Workbook

Sheet HIEU
A1: ='[1]A VIEN'!A1:Q1 -> 2025年09销路运费
A2: CHI PHÍ VẬN CHUYỂN HÀNG NỘI ĐỊA
A3: ='[1]A VIEN'!A3:Q3 -> THÁNG 09 NĂM 2025
A4: NCC: TRỊNH MINH HIẾU
A5: STT 次序 | B5: Ngày xuất hàng 日期 | C5: Đơn xuất hàng 销货单 | D5: Khách hàng 客户 | E5: Địa chỉ KH 送货地址 | G5: SỐ LƯỢNG 重量 NET WEIGHT | K5: SỐ LƯỢNG 重量 (kg) GROSS WEIGHT | L5: PHÍ VẬN CHUYỂN 路运费 | N5: CHI PHÍ KHÁC (LẤY HÀNG VỀ/GIAO MẪU…) | P5: CHỞ PHẾ | Q5: THÀNH TIỀN 合计 | R5: GHI CHÚ
E6: NỘI THÀNH | F6: NGOẠI THÀNH | G6: MÀNG NHỰA | H6: ĐỊNH HÌNH
G7: KG | H7: PCS | I7: KG | L7: MÀNG NHỰA | M7: ĐỊNH HÌNH | N7: MÀNG NHỰA | O7: ĐỊNH HÌNH
A8: 1 | B8: 26/8/2025 | C8: 26 | D8: CHAU | E8: THU DUC | H8: 142600 | I8: 663.173 | M8: 1200000 | Q8: =SUM(L8:P9) -> 1200000 | R8: 2X
C9: 6+7+8+24 | D9: PHU HOI | E9: Q9 | H9: =46600+6000 -> 52600 | I9: =537.01+118.2532 -> 655.2632
A10: 2 | B10: 27/8/2025 | C10: 20 | D10: BIOPLAS | E10: GO VAP | H10: 246000 | I10: 1205.707 | M10: 1050000 | Q10: =SUM(L10:P11) -> 1050000
C11: 44 | D11: QUANG NINH | E11: GO VAP | H11: 7047 | I11: 191.3179
A12: 3 | B12: 27/8/2025 | C12: 2+3 | D12: KMS | E12: BEN CAT | H12: 40000 | I12: 392.8865 | M12: 600000 | Q12: =SUM(L12:P12) -> 600000 | R12: 50B, PHI 1.5T, 2X
A13: 4 | B13: 28/8/2025 | C13: 2 | D13: VIFON | E13: TAN PHU | H13: 308000 | I13: 1632.4 | M13: 1100000 | Q13: =SUM(L13:P13) -> 1100000
A14: 5 | B14: 29/8/2025 | C14: 32 | D14: BIOVEGI | E14: Q1 | H14: 15500 | I14: 336.43 | M14: 1100000 | Q14: =SUM(L14:P17) -> 1300000 | R14: 2X
C15: 13 | D15: TAN DAI LONG | E15: BINH TAN | H15: 23460 | I15: 590.7228
C16: 28 | D16: ANH NGAN | E16: TDM | H16: 19000 | I16: 325.839
C17: 26 | D17: THIEN MOC | E17: TAN PHU | G17: 420 | L17: 200000
A18: 6 | B18: 30/8/2025 | C18: 15 | D18: RVC | E18: THU DUC | H18: 100830 | I18: 996.3505 | M18: 1050000 | Q18: =SUM(L18:P19) -> 1050000
C19: 30 | D19: LAM GIA | E19: THUAN AN | H19: 10950 | I19: 282.9075
A20: 7 | B20: 31/8/2025 | C20: 33+34 | D20: GIA MINH | E20: Q8 | H20: 120350 | I20: 1440.7286 | M20: 1150000 | Q20: =SUM(L20:P20) -> 1150000
A21: 8 | B21: 03/9/2025 | C21: 11 | D21: ANH CONG | E21: Q8 | H21: 49800 | I21: 1170.798 | M21: 1150000 | O21: 60000 | Q21: =SUM(L21:P21) -> 1210000 | R21: VE CHANH
A22: 9 | B22: 04/9/2025 | C22: 17+19+18+21 | D22: PHU HOI | E22: Q9 | H22: =129250+20000 -> 149250 | I22: =1299.476+219 -> 1518.476 | M22: 1150000 | Q22: =SUM(L22:P22) -> 1150000 | R22: 2X
A23: 10 | B23: 05/9/2025 | C23: 36 | D23: HANA | E23: TAN PHU | H23: 9000 | I23: 326.25 | M23: 1100000 | Q23: =SUM(L23:P25) -> 1250000 | R23: 2X
C24: 37 | D24: HANA | E24: TAN BINH | H24: 66000 | I24: 998.8399
C25: 13 | D25: HAO PHAT | E25: BINH TAN | G25: 300 | L25: 150000
A26: 11 | B26: 06/9/2025 | C26: 29+30+25+27+32 | D26: PLASACO | E26: TAN BINH | H26: =43000+16800+27650+40000 -> 127450 | I26: =367.692+253.9749+434+100.548 -> 1156.2149 | M26: 1150000 | Q26: =SUM(L26:P26) -> 1150000 | R26: 2X
A27: 12 | B27: 08/9/2025 | C27: 5 | D27: HANA | E27: TAN BINH+Q11 | H27: 56800 | I27: 1005.36 | M27: 1200000 | Q27: =SUM(L27:P27) -> 1200000
A28: 13 | B28: 09/9/2025 | C28: 26+12+15 | D28: RVC | E28: THU DUC | G28: 420 | H28: =13800+4600 -> 18400 | I28: =347.484+119.46 -> 466.944 | L28: 150000 | M28: 1050000 | Q28: =SUM(L28:P29) -> 1200000 | R28: 2X
C29: 6 | D29: HANA | E29: TAN BINH | H29: 24000 | I29: 337.68
A30: 14 | B30: 10/9/2025 | C30: 8+9 | D30: RVC | E30: THU DUC | H30: =15600+39340 -> 54940 | I30: =432.6+962.664 -> 1395.264 | M30: 1050000 | Q30: =SUM(L30:P30) -> 1050000 | R30: 2X
A31: 15 | B31: 11/9/2025 | C31: 7+8 | D31: KMS | E31: BEN CAT | H31: 60000 | I31: 598.3969 | M31: 600000 | Q31: =SUM(L31:P31) -> 600000 | R31: 90B. PHI 1.5T, 2X
A32: 16 | B32: 11/9/2025 | C32: 26+40+15 | D32: PHU HOI | E32: Q9 | H32: =19850+22000+28700 -> 70550 | I32: =368.7516+346.7086+584.914 -> 1300.3742 | M32: 1100000 | Q32: =SUM(L32:P32) -> 1100000
A33: 17 | B33: 12/9/2025 | C33: 2 | D33: QUEEN PACK | E33: THU DUC | H33: 73400 | I33: 597.8216 | M33: 1000000 | Q33: =SUM(L33:P33) -> 1000000
A34: 18 | B34: 12/9/2025 | C34: 2+3 | D34: TUYEN HUNG PHU | E34: DUC HOA | H34: 45800 | I34: 999.68 | M34: 1250000 | Q34: =SUM(L34:P34) -> 1250000
A35: 19 | B35: 13/9/2025 | C35: 31+23 | D35: HANA | E35: Q6 + BINH TAN | H35: =105000+15000 -> 120000 | I35: =1139.25+390 -> 1529.25 | M35: 1200000 | O35: 24000 | Q35: =SUM(L35:P35) -> 1224000 | R35: VE CHANH
A36: 20 | B36: 15/9/2025 | C36: 26+27 | D36: VINATRAY | E36: HOC MON | H36: 67200 | I36: 1318.1138 | M36: 1050000 | Q36: =SUM(L36:P36) -> 1050000 | R36: 2X
A37: 21 | B37: 16/9/2025 | C37: 8 | D37: PHU HOI | E37: THU DUC | H37: 20000 | I37: 434 | M37: 1150000 | Q37: =SUM(L37:P38) -> 1150000
C38: 33+53 | D38: PHU HOI | E38: Q9 | H38: =24600+12000 -> 36600 | I38: =418.2682+260.4 -> 678.6682
A39: 22 | B39: 16/9/2025 | C39: 18+12+13 | D39: ANH CONG | E39: Q8 | H39: =2400+72000 -> 74400 | I39: =48.48+1044 -> 1092.48 | M39: 1150000 | O39: 60000 | Q39: =SUM(L39:P39) -> 1210000 | R39: C2, 2X, VE CHANH
A40: 23 | B40: 17/9/2025 | C40: 48+15 | D40: CHI YEN | E40: Q9 | H40: =30600+40000 -> 70600 | I40: =624.393+110 -> 734.393 | M40: 1200000 | Q40: =SUM(L40:P41) -> 1200000 | R40: 2X
...

Sheet NAM
A1: ='[1]A VIEN'!A1:Q1 -> 2025年09销路运费
A2: CHI PHÍ VẬN CHUYỂN HÀNG NỘI ĐỊA
A3: ='[1]A VIEN'!A3:Q3 -> THÁNG 09 NĂM 2025
A4: NCC: A NAM - 2.5T
A5: STT 次序 | B5: Ngày xuất hàng 日期 | C5: Đơn xuất hàng 销货单 | D5: Khách hàng 客户 | E5: Địa chỉ KH 送货地址 | G5: SỐ LƯỢNG 重量 NET WEIGHT | K5: SỐ LƯỢNG 重量 (kg) GROSS WEIGHT | L5: PHÍ VẬN CHUYỂN 路运费 | N5: CHI PHÍ KHÁC (LẤY HÀNG VỀ/GIAO MẪU…) | P5: CHỞ PHẾ | Q5: THÀNH TIỀN 合计 | R5: GHI CHÚ
E6: NỘI THÀNH | F6: NGOẠI THÀNH | G6: MÀNG NHỰA | H6: ĐỊNH HÌNH
G7: KG | H7: PCS | I7: KG | L7: MÀNG NHỰA | M7: ĐỊNH HÌNH | N7: MÀNG NHỰA | O7: ĐỊNH HÌNH
A8: 1 | B8: 26/8/2025 | C8: 16+17 | D8: PHU HOI | E8: THU DUC | H8: 27250 | I8: 626.9741 | M8: 1050000 | O8: 15000 | Q8: =SUM(L8:P9) -> 1065000 | R8: VE CHANH
C9: 13 | D9: PHU HOI | E9: THU DUC | H9: 20400 | I9: 442.68
A10: 2 | B10: 26/8/2025 | C10: 13 | D10: THANH CONG | E10: Q8 | G10: 2040 | L10: 1150000 | N10: 60000 | Q10: =SUM(L10:P10) -> 1210000 | R10: C2, 2X,VE CHANH
A11: 3 | B11: 27/8/2025 | C11: 29 | D11: ANH NGAN | E11: BINH THANH | H11: 31800 | I11: 393.3779 | M11: 650000 | Q11: =SUM(L11:P13) -> 1450000 | R11: 2X
C12: 15 | D12: HAI NAM | E12: GO VAP | H12: 18400 | I12: 298.08 | O12: 300000 | R12: LAY HANG NG VE 23T (CHÂU).
C13: 7 | D13: THINH PHAT | E13: BINH THANH | G13: 1020 | L13: 500000
A14: 4 | B14: 28/8/2025 | C14: 26+25 | D14: THE KY XANH | E14: TAN PHU | H14: 49500 | I14: 1051.7948 | M14: 1000000 | Q14: =SUM(L14:P15) -> 1200000 | R14: 2X
C15: 37 | D15: THIEN MOC | E15: TAN PHU | G15: 420 | L15: 200000
A16: 5 | B16: 29/8/2025 | C16: 17 | D16: TU PHUONG | E16: BINH CHANH | H16: 20000 | I16: 520 | M16: 1300000 | Q16: =SUM(L16:P17) -> 1300000
C17: 33 | D17: ANH NGAN | E17: BINH TAN | H17: 58050 | I17: 715.7804
A18: 6 | B18: 30/8/2025 | C18: 5+4 | D18: PLASACO | E18: TAN BINH | H18: 107000 | I18: 1302.015 | M18: 1150000 | Q18: =SUM(L18:P18) -> 1150000 | R18: 2X
A19: 7 | B19: 03/9/2025 | C19: 6 | D19: WAHL | E19: CAN GIUOC | H19: 29710 | I19: 751.4326 | M19: 1850000 | O19: =100*500 -> 50000 | Q19: =SUM(L19:P19) -> 1900000 | R19: LẤY 102 PCS VỎ THÙNG VỀ
A20: 8 | B20: 04/9/2025 | C20: 43 | D20: HANA | E20: BINH TAN | H20: 54400 | I20: 962.88 | M20: 1100000 | Q20: =SUM(L20:P20) -> 1100000
A21: 9 | B21: 05/9/2025 | C21: 2 | D21: NPP THANH PHAT | E21: BINH TAN | H21: 66000 | I21: 396 | M21: 1100000 | Q21: =SUM(L21:P21) -> 1100000
A22: 10 | B22: 05/9/2025 | C22: 19 | D22: NIDEC VN | E22: Q9 | G22: 2000 | L22: 1050000 | Q22: =SUM(L22:P22) -> 1050000 | R22: C2
A23: 11 | B23: 06/9/2025 | C23: 18 | D23: ANH NGAN | E23: Q12 | H23: 28000 | I23: 469.98 | M23: 1050000 | Q23: =SUM(L23:P24) -> 1050000
C24: 16+17 | D24: VINH LIEN | E24: Q12 | H24: 73000 | I24: 736.945
A25: 12 | B25: 08/9/2025 | C25: 6+8 | D25: CHAU | E25: TAN PHU | H25: =3300+30500 -> 33800 | I25: =101.805+489.3566 -> 591.1616 | M25: 1300000 | O25: 60000 | Q25: =SUM(L25:P27) -> 1420000 | R25: VE CHANH
C26: 26+11 | D26: TH FARM | E26: Q6 | H26: =2500+67950 -> 70450 | I26: =105+227.6486 -> 332.6486 | O26: 60000 | R26: VE CHANH
C27: 30+31 | D27: ANH NGAN | E27: BINH TAN | H27: 20000 | I27: 345.6332 | R27: 2X
A28: 13 | B28: 09/9/2025 | C28: 13+22 | D28: ANH CONG | E28: Q8 | H28: =24000+23700 -> 47700 | I28: =348+557.187 -> 905.187 | M28: 1200000 | O28: 60000 | Q28: =SUM(L28:P28) -> 1260000 | R28: VE CHANH, 2X
A29: 14 | B29: 10/9/2025 | C29: 30 | D29: NAM PHAM | E29: THU DUC | I29: 360 | M29: 1250000 | O29: 25000 | Q29: =SUM(L29:P31) -> 1275000 | R29: 2X, VE CHANH
C30: 1 | D30: THANH-QN | E30: TAN PHU | H30: 20000 | I30: 217
C31: 33 | D31: BB TN | E31: BINH TAN | H31: 28920 | I31: 415.7048
A32: 15 | B32: 10/9/2025 | C32: 24+23 | D32: HANA | E32: Q11 + TAN BINH | H32: 42000 | I32: 971.1138 | M32: 1150000 | O32: 200000 | Q32: =SUM(L32:P32) -> 1350000 | R32: GIAO TOI, C2
A33: 16 | B33: 11/9/2025 | C33: 4+5+6+10 | D33: HANA | E33: TAN BINH+Q12 | H33: =68500+19730 -> 88230 | I33: =803.3491+309.9605 -> 1113.3096 | M33: 1200000 | Q33: =SUM(L33:P33) -> 1200000 | R33: 2X
A34: 17 | B34: 12/9/2025 | C34: 15+13+14 | D34: QUANG DUNG | E34: BIEN HOA | H34: 112900 | I34: 1272.4648 | M34: 1150000 | Q34: =SUM(L34:P34) -> 1150000 | R34: 2X
A35: 18 | B35: 13/9/2025 | C35: 27 | D35: BB NGOC THANH | E35: Q6 | H35: 68000 | I35: 408 | M35: 1150000 | Q35: =SUM(L35:P35) -> 1150000
A36: 19 | B36: 15/9/2025 | C36: 39 | D36: ANH DINH | E36: BINH CHANH | H36: 49600 | I36: 877.92 | M36: 1150000 | Q36: =SUM(L36:P36) -> 1150000
A37: 20 | B37: 15/9/2025 | C37: 35+50 | D37: HANA | E37: BINH CHANH | H37: =118300+400 -> 118700 | I37: =1689.2075+9.0299 -> 1698.2374 | M37: 1150000 | O37: 200000 | Q37: =SUM(L37:P37) -> 1350000 | R37: GIAO TOI, C2, 2X
A38: 21 | B38: 16/9/2025 | C38: 11 | D38: PHU HOI | E38: Q6 | H38: 48000 | I38: 979.44 | M38: 1250000 | Q38: =SUM(L38:P39) -> 1250000 | R38: 2X
C39: 14 | D39: BIOVEGI | E39: Q1 | H39: 15500 | I39: 481.976
A40: 22 | B40: 16/9/2025 | C40: 49 | D40: ANH NGAN | E40: BINH TAN | H40: 100780 | I40: 1234.0264 | M40: 1100000 | O40: 200000 | Q40: =SUM(L40:P40) -> 1300000 | R40: GIAO TOI, C2, 2X
...

Sheet TU 2T
A1: ='[1]A VIEN'!A1:Q1 -> 2025年09销路运费
A2: CHI PHÍ VẬN CHUYỂN HÀNG NỘI ĐỊA
A3: ='[1]A VIEN'!A3:Q3 -> THÁNG 09 NĂM 2025
A4: NCC: ANH TÚ - 2.5T
A5: STT 次序 | B5: Ngày xuất hàng 日期 | C5: Đơn xuất hàng 销货单 | D5: Khách hàng 客户 | E5: Địa chỉ KH 送货地址 | G5: SỐ LƯỢNG 重量 NET WEIGHT | K5: SỐ LƯỢNG 重量 (kg) GROSS WEIGHT | L5: PHÍ VẬN CHUYỂN 路运费 | N5: CHI PHÍ KHÁC (LẤY HÀNG VỀ/GIAO MẪU…) | P5: CHỞ PHẾ | Q5: THÀNH TIỀN 合计 | R5: GHI CHÚ
E6: NỘI THÀNH | F6: NGOẠI THÀNH | G6: MÀNG NHỰA | H6: ĐỊNH HÌNH
G7: KG | H7: PCS | I7: KG | L7: MÀNG NHỰA | M7: ĐỊNH HÌNH | N7: MÀNG NHỰA | O7: ĐỊNH HÌNH
A8: 1 | B8: 26/8/2025 | C8: 16+17 | D8: GIA MINH | E8: Q8 | H8: 136600 | I8: 1545.4462 | M8: 1150000 | Q8: =SUM(L8:P8) -> 1150000
A9: 2 | B9: 27/8/2025 | C9: 1 | D9: VIFON | E9: TAN PHU | H9: 320000 | I9: 1696 | M9: 1100000 | Q9: =SUM(L9:P9) -> 1100000
A10: 3 | B10: 27/8/2025 | C10: 26 | D10: ANH NGAN | E10: Q6 | H10: 27050 | I10: 549.6314 | M10: 1150000 | O10: 260000 | Q10: =SUM(L10:P11) -> 1410000 | R10: GIAO TOI, VE CHANH
C11: 7 | D11: ANH NGAN | E11: BINH TAN | H11: 38000 | I11: 456.4966 | R11: C2
A12: 4 | B12: 28/8/2025 | C12: 18 | D12: MASAN | E12: DI AN | H12: 106920 | I12: 1154.736 | M12: 950000 | Q12: =SUM(L12:P12) -> 950000
A13: 5 | B13: 29/8/2025 | C13: 22 | D13: RVC | E13: THU DUC | H13: 26400 | I13: 568.7281 | M13: 1150000 | Q13: =SUM(L13:P14) -> 1150000
C14: 44+45 | D14: PHU HOI | E14: Q9 | H14: 29250 | I14: 620.9799
A15: 6 | B15: 29/8/2025 | C15: 37 | D15: TAN PHAT | E15: DI AN | H15: 37230 | I15: 961.8855 | M15: 900000 | Q15: =SUM(L15:P15) -> 900000 | R15: C2
A16: 7 | B16: 30/8/2025 | C16: 8 | D16: MASAN | E16: DI AN | H16: 106920 | I16: 1154.736 | M16: 950000 | Q16: =SUM(L16:P16) -> 950000
A17: 8 | B17: 03/9/2025 | C17: 35 | D17: HANA | E17: BINH TAN | H17: 15000 | I17: 390 | M17: 1150000 | O17: 24000 | Q17: =SUM(L17:P18) -> 1174000 | R17: VE CHANH
C18: 36 | D18: HANA | E18: TAN BINH | H18: 47600 | I18: 1032.92
A19: 9 | B19: 04/9/2025 | C19: 9 | D19: VIFON | E19: TAN PHU | H19: 320000 | I19: 1696 | M19: 1100000 | Q19: =SUM(L19:P19) -> 1100000
A20: 10 | B20: 05/9/2025 | C20: 27 | D20: ANH NGAN | E20: Q12 | H20: 67830 | I20: 1072.6555 | M20: 1100000 | Q20: =SUM(L20:P22) -> 1100000
C21: 23 | D21: NAM PHAM | E21: THU DUC | H21: 15800 | I21: 253.716
C22: 33 | D22: RVC | E22: THU DUC | H22: 6000 | I22: 108
A23: 11 | B23: 06/9/2025 | C23: 17 | D23: PHU HOI | E23: Q6 | H23: 33600 | I23: 764.4 | M23: 1200000 | Q23: =SUM(L23:P24) -> 1200000
C24: 9 | D24: NAM PHAM | E24: TAN PHU | H24: 30000 | I24: 365.3503
A25: 12 | B25: 08/9/2025 | C25: 7 | D25: BIOVEGI | E25: Q1 | H25: 19000 | I25: 472.54 | M25: 1200000 | Q25: =SUM(L25:P26) -> 1218000 | R25: 2X
C26: 14 | D26: PHU HOI | E26: THU DUC | H26: 24000 | I26: 520.8 | O26: 18000 | R26: VE CHANH
A27: 13 | B27: 09/9/2025 | C27: 30+31 | D27: KMS | E27: BEN CAT | H27: 40000 | I27: 392.8865 | M27: 600000 | Q27: =SUM(L27:P27) -> 600000 | R27: 50B. PHI 1.5T, 2X
A28: 14 | B28: 09/9/2025 | C28: 5 | D28: FOSTER | E28: VSIP 2 | H28: 5100 | I28: 606.9 | M28: 300000 | Q28: =SUM(L28:P28) -> 300000
A29: 15 | B29: 10/9/2025 | C29: 48 | D29: QUEEN PACK | E29: THU DUC | H29: 89000 | I29: 677.82 | M29: 1000000 | Q29: =SUM(L29:P29) -> 1000000
A30: 16 | B30: 10/9/2025 | C30: 39+29 | D30: CHI YEN | E30: Q9 | H30: =10230+30600 -> 40830 | I30: =315.5955+703.8 -> 1019.3955 | M30: 1050000 | Q30: =SUM(L30:P30) -> 1050000 | R30: C2
A31: 17 | B31: 11/9/2025 | C31: 7+6 | D31: THE KY XANH | E31: TAN PHU | H31: 67500 | I31: 1064.25 | M31: 1150000 | Q31: =SUM(L31:P31) -> 1150000 | R31: 2X
A32: 18 | B32: 11/9/2025 | C32: 16 | D32: PHU HOI | E32: BINH CHANH | H32: 90600 | I32: 764.4768 | M32: 1100000 | O32: 65000 | Q32: =SUM(L32:P32) -> 1165000 | R32: C2, VE CHANH
A33: 19 | B33: 12/9/2025 | C33: 16+17 | D33: HANA | E33: TAN BINH | H33: 72100 | I33: 1213.8138 | M33: 1100000 | Q33: =SUM(L33:P33) -> 1100000
A34: 20 | B34: 12/9/2025 | C34: 24+25 | D34: TRUONG AN | E34: THU DUC | H34: 11800 | I34: 198.78 | M34: 1000000 | O34: 200000 | Q34: =SUM(L34:P35) -> 1200000 | R34: GIAO TOI
C35: 50 | D35: XUAN THAI THINH | E35: DI AN | H35: 45400 | I35: 912.26 | R35: C2
A36: 21 | B36: 13/9/2025 | C36: 53 | D36: KMS | E36: BEN CAT | H36: 40000 | I36: 317.982 | M36: 550000 | Q36: =SUM(L36:P36) -> 550000 | R36: 40B. PHI 1.5T
A37: 22 | B37: 15/9/2025 | C37: 4 | D37: PHAM NGUYEN | E37: DUC HOA | H37: 64000 | I37: 329 | M37: 1400000 | Q37: =SUM(L37:P39) -> 1465000 | R37: 2X
C38: 2 | D38: PHU HOI | E38: BINH CHANH | H38: 30600 | I38: 624.393 | O38: 65000 | R38: VE CHANH
C39: 22+21 | D39: TAN DAI LONG | E39: BINH TAN | H39: 62000 | I39: 785.698
A40: 23 | B40: 16/9/2025 | C40: 24+25 | D40: PHUC HANG | E40: DUC HOA | H40: 126000 | I40: 1390.35 | M40: 1250000 | Q40: =SUM(L40:P40) -> 1250000
...

Sheet HOANG
A1: ='[1]A VIEN'!A1:Q1 -> 2025年09销路运费
A2: CHI PHÍ VẬN CHUYỂN HÀNG NỘI ĐỊA
A3: ='[1]A VIEN'!A3:Q3 -> THÁNG 09 NĂM 2025
A4: NCC: TRỊNH VĂN HOÀNG - 4T
A5: STT 次序 | B5: Ngày xuất hàng 日期 | C5: Đơn xuất hàng 销货单 | D5: Khách hàng 客户 | E5: Địa chỉ KH 送货地址 | G5: SỐ LƯỢNG 重量 NET WEIGHT | K5: SỐ LƯỢNG 重量 (kg) GROSS WEIGHT | L5: PHÍ VẬN CHUYỂN 路运费 | N5: CHI PHÍ KHÁC (LẤY HÀNG VỀ/GIAO MẪU…) | P5: CHỞ PHẾ | Q5: THÀNH TIỀN 合计 | R5: GHI CHÚ
E6: NỘI THÀNH | F6: NGOẠI THÀNH | G6: MÀNG NHỰA | H6: ĐỊNH HÌNH | J6: PHẾ LIỆU
G7: KG | H7: PCS | I7: KG | J7: KG | L7: MÀNG NHỰA | M7: ĐỊNH HÌNH | N7: MÀNG NHỰA | O7: ĐỊNH HÌNH
A8: 1 | B8: 26/8/2025 | C8: 3 | D8: DONG BAC VINA | F8: HOC MON | G8: 4175 | L8: 1300000 | Q8: =SUM(L8:P8) -> 1300000
A9: 2 | B9: 26/8/2025 | C9: 39+40+41 | D9: NIDEC VN | F9: Q9 | G9: 2500 | J9: 696 | L9: 1100000 | P9: =J9*400 -> 278400 | Q9: =SUM(L9:P9) -> 1378400 | R9: 2X, C2, LẤY PHẾ NIDEC VN
A10: 3 | B10: 27/8/2025 | C10: 4 | D10: KIEN XUONG | F10: DUC HOA | G10: 1000 | L10: 350000 | Q10: =SUM(L10:P12) -> 1660000 | R10: 2X
C11: 3 | D11: PHAM NGUYEN | F11: DUC HOA | H11: 50000 | I11: 260 | M11: 1310000
C12: 22 | D12: THUAN THANH | F12: BINH TAN | H12: 68000 | I12: 681.1498
A13: 4 | B13: 28/8/2025 | C13: 13 | D13: DONG BAC VINA | F13: HOC MON | G13: 3719 | J13: 1060 | L13: 1200000 | P13: =J13*500 -> 530000 | Q13: =SUM(L13:P13) -> 1730000 | R13: LAY PHEYSD
A14: 5 | B14: 28/8/2025 | C14: 10 | D14: TAN PHAT 2 | F14: DI AN | H14: 200000 | I14: 712.5 | M14: 1100000 | Q14: =SUM(L14:P14) -> 1100000
A15: 6 | B15: 29/8/2025 | C15: 11+15 | D15: TRUONG AN | F15: THU DUC | H15: =38000+4000 -> 42000 | I15: =267.7047+40 -> 307.7047 | M15: 1490000 | Q15: =SUM(L15:P18) -> 1490000 | R15: 2X
C16: 12 | D16: TH FARM | F16: THU DUC | H16: 29230 | I16: 887.9535
C17: 20 | D17: PHU HOI | F17: THU DUC | H17: 26000 | I17: 676
C18: 18 | D18: BIOVEGI | F18: DI AN | H18: 11000 | I18: 374.7
A19: 7 | B19: 30/8/2025 | C19: 2 | D19: P&G | F19: VSIP 2 | H19: 153840 | I19: 697.4154 | M19: 600000 | Q19: =SUM(L19:P19) -> 600000
A20: 8 | B20: 03/9/2025 | C20: 8 | D20: MINH PHUONG | F20: BINH CHANH | G20: 900 | L20: 1100000 | Q20: =SUM(L20:P22) -> 1560000 | R20: 2X
C21: 9 | D21: TAN BAC HAI | F21: BINH CHANH | G21: 1560
C22: 38 | D22: TRUONG AN | F22: BINH TAN | H22: 18000 | I22: 462.6 | M22: 460000
A23: 9 | B23: 04/9/2025 | C23: 3 | D23: TAN DAI LONG | F23: BINH TAN | H23: 20000 | I23: 192 | M23: 1310000 | Q23: =SUM(L23:P25) -> 1560000 | R23: 2X
C24: 32+2 | D24: THUAN THANH | F24: BINH CHANH | H24: =15000+60000 -> 75000 | I24: =12+663.6117 -> 675.6117
C25: 11 | D25: MINH PHUONG | F25: BINH CHANH | G25: 1097.5 | L25: 250000
A26: 10 | B26: 05/9/2025 | C26: 20 | D26: TAXIN | F26: LONG THANH | H26: 144000 | I26: 1310.4 | M26: 1750000 | O26: 100000 | Q26: =SUM(L26:P26) -> 1850000 | R26: LẤY VÈ 6T HÀNG NG (DƠ) TỪ LÔ TRƯỚC- HẠ
A27: 11 | B27: 06/9/2025 | C27: 9 | D27: HANH MINH KHOI | F27: CAN GIUOC | H27: 36000 | I27: 727.2 | M27: 1950000 | Q27: =SUM(L27:P27) -> 1950000
A28: 12 | B28: 08/9/2025 | C28: 1 | D28: PHAM NGUYEN | F28: BINH TAN | H28: 100000 | I28: 764 | M28: 1380000 | Q28: =SUM(L28:P29) -> 1380000
C29: 33 | D29: ANH NGAN | F29: HOC MON | H29: 48200 | I29: 1105.7915
A30: 13 | B30: 09/9/2025 | C30: 10 | D30: TAN BAC HAI | F30: BINH CHANH | G30: 2040 | L30: 1000000 | Q30: =SUM(L30:P31) -> 1580000 | R30: 2X
C31: 2 | D31: PHAM NGUYEN | F31: DUC HOA | H31: 80400 | I31: 597.44 | M31: 580000
A32: 14 | B32: 10/9/2025 | C32: 47+21+57 | D32: LONG PHAT | F32: BINH CHANH | H32: =40000+19200+75000 -> 134200 | I32: =552+255.168+1221.0831 -> 2028.2511 | M32: 1400000 | Q32: =SUM(L32:P32) -> 1400000 | R32: 2X
A33: 15 | B33: 16/9/2025 | C33: 28 | D33: C VAN-HA NOI | F33: Q12 | H33: 56300 | I33: 1657.865 | M33: 1280000 | Q33: =SUM(L33:P34) -> 1280000
C34: 3 | D34: PHU HOI | F34: BEN CAT' | H34: 30600 | I34: 624.393
A35: 16 | B35: 17/9/2025 | C35: 56 | D35: HARADA | F35: BIEN HOA | G35: 2089 | J35: 120 | L35: 1200000 | P35: =120*1000+80000 -> 200000 | Q35: =SUM(L35:P37) -> 1660000 | R35: LẤY PHẾ HARADA-LONG BINH
C36: 28 | D36: QUANG HAY | F36: BIEN HOA | G36: 1000
C37: 7 | D37: HONG PHAT | F37: THU DUC | H37: 28600 | I37: 262.5365 | M37: 260000
A38: 17 | B38: 18/9/2025 | C38: 8 | D38: VINATRAY | F38: HOC MON | H38: 68800 | I38: 1912.6128 | M38: 1280000 | Q38: =SUM(L38:P39) -> 1280000
C39: 36 | D39: ANH NGAN | F39: Q12 | H39: 25200 | I39: 560.916
A40: 18 | B40: 19/9/2025 | C40: 40 | D40: ANH HUNG | F40: BINH CHANH | H40: 30000 | I40: 325.5 | M40: 1340000 | Q40: =SUM(L40:P43) -> 1640000 | R40: 2X
...

Sheet TUAN
A1: ='[1]A VIEN'!A1:Q1 -> 2025年09销路运费
A2: CHI PHÍ VẬN CHUYỂN HÀNG NỘI ĐỊA
A3: ='[1]A VIEN'!A3:Q3 -> THÁNG 09 NĂM 2025
A4: NCC: ANH TUẤN - 7T
A5: STT 次序 | B5: Ngày xuất hàng 日期 | C5: Đơn xuất hàng 销货单 | D5: Khách hàng 客户 | E5: Địa chỉ KH 送货地址 | G5: SỐ LƯỢNG 重量 NET WEIGHT | K5: SỐ LƯỢNG 重量 (kg) GROSS WEIGHT | L5: PHÍ VẬN CHUYỂN 路运费 | N5: CHI PHÍ KHÁC (LẤY HÀNG VỀ/GIAO MẪU…) | P5: CHỞ PHẾ | Q5: THÀNH TIỀN 合计 | R5: GHI CHÚ
E6: NỘI THÀNH | F6: NGOẠI THÀNH | G6: MÀNG NHỰA | H6: ĐỊNH HÌNH | J6: PHẾ LIỆU
G7: KG | H7: PCS | I7: KG | J7: KG | L7: MÀNG NHỰA | M7: ĐỊNH HÌNH | N7: MÀNG NHỰA | O7: ĐỊNH HÌNH
A8: 1 | B8: 26/8/2025 | C8: 23 | D8: HANH MINH KHOI | F8: CAN GIUOC | H8: 29400 | I8: 1021.941 | M8: 2300000 | Q8: =SUM(L8:P9) -> 2300000
C9: 18 | D9: HANA | F9: NHA BE | H9: 24600 | I9: 772.059
A10: 2 | B10: 26/8/2025 | C10: 25+28 | D10: LONG PHAT | F10: BINH CHANH | H10: =16500+124000 -> 140500 | I10: =509.025+2285.68 -> 2794.705 | M10: 1500000 | Q10: =SUM(L10:P11) -> 1700000
C11: 16 | D11: TAN BAC HAI | F11: BINH CHANH | G11: 1020 | L11: 200000
A12: 3 | B12: 28/8/2025 | C12: 31 | D12: MINH KHANG | F12: Q12 | H12: 97000 | I12: 2110.801 | M12: 1500000 | Q12: =SUM(L12:P13) -> 1500000
C13: 10 | D13: A PHUC-HN | F13: GA ST | H13: 6000 | I13: 426
A14: 4 | B14: 28/8/2025 | C14: 1 | D14: P&G | F14: VSIP 2 | H14: 27680 | I14: 977.16 | M14: 650000 | O14: 1000000 | Q14: =SUM(L14:P14) -> 1650000 | R14: C2, GIAO TỪ 6PM => 4AM MOI XONG
A15: 5 | B15: 29/8/2025 | C15: 32+35 | D15: KOYO | F15: MP3 | H15: =120000+60000 -> 180000 | I15: =1578+923.94 -> 2501.94 | M15: 1000000 | Q15: =SUM(L15:P15) -> 1000000 | R15: 2X
A16: 6 | B16: 30/8/2025 | C16: 11 | D16: VINATRAY | F16: HOC MON | H16: 93600 | I16: 2723.7 | M16: 1400000 | Q16: =SUM(L16:P16) -> 1400000
A17: 7 | B17: 03/9/2025 | C17: 3 | D17: TAXIN | F17: LONG THANH | H17: 192000 | I17: 1747.2 | M17: 2050000 | O17: 1025000 | Q17: =SUM(L17:P17) -> 3075000 | R17: TRẢ VỀ NGUYÊN XE HÀNG 192T DO HÀNG NG (DÍNH TẠP CHẤTTRONG NHUA)-HẠ
A18: 8 | B18: 04/9/2025 | C18: 39 | D18: LONG PHAT | F18: BINH CHANH | H18: 139860 | I18: 3058.7109 | M18: 1600000 | Q18: =SUM(L18:P18) -> 1600000
A19: 9 | B19: 05/9/2025 | C19: 3 | D19: WAHL | F19: CAN GIUOC | H19: 20680 | I19: 429.7412 | M19: 2300000 | O19: =129*500 -> 64500 | Q19: =SUM(L19:P20) -> 2364500 | R19: LẤY 129 VỎ THÙNG WAHL VỀ
C20: 5 | D20: HANH MINH KHOI | F20: CAN GIUOC | H20: 34560 | I20: 815.04
A21: 10 | B21: 06/9/2025 | C21: 4 | D21: NIDEC INS | F21: Q9 | G21: 4855 | L21: 1200000 | Q21: =SUM(L21:P22) -> 1600000
C22: 21 | D22: NHUA VN | F22: TDM | H22: 28320 | I22: 439.754 | M22: 400000
A23: 11 | B23: 07/9/2025 | C23: 3 | D23: UKP | F23: TAN UYEN | G23: 5200 | J23: 3184 | L23: 1000000 | N23: 600000 | Q23: =SUM(L23:P23) -> 1600000 | R23: LAY PHE UKP 3184KG
A24: 12 | B24: 08/9/2025 | C24: 22 | D24: VINATRAY | F24: HOC MON | H24: 64200 | I24: 2413.5408 | M24: 1500000 | Q24: =SUM(L24:P25) -> 1500000
C25: 17 | D25: ANH NGAN | F25: BEN CAT | H25: 110980 | I25: 445.4996
A26: 13 | B26: 09/9/2025 | C26: 16 | D26: JUMBO | F26: LONG KHANH | G26: 4692 | L26: 2200000 | Q26: =SUM(L26:P27) -> 2200000
C27: 24 | D27: TAN VIET PHAT | F27: BIEN HOA | G27: 1000
A28: 14 | B28: 10/9/2025 | C28: 4 | D28: DONG BAC VINA | F28: HOC MON | G28: 4560 | L28: 1700000 | Q28: =SUM(L28:P29) -> 1700000
C29: 25 | D29: MINH PHUONG | F29: BINH CHANH | G29: 1003
A30: 15 | B30: 10/9/2025 | C30: 41+42 | D30: NIDEC VN | F30: Q9 | G30: 2500 | L30: 1050000 | N30: 200000 | Q30: =SUM(L30:P30) -> 1250000 | R30: C2, GIAO TOI
A31: 16 | B31: 11/9/2025 | C31: 20 | D31: TAXIN | F31: LONG THANH | H31: 192000 | I31: 1670.4 | M31: 2050000 | O31: 300000 | Q31: =SUM(L31:P31) -> 2350000 | R31: TRẢ 50T DO HÀNG NG (HẠ)
A32: 17 | B32: 12/9/2025 | C32: 19 | D32: RAW | F32: BAU BANG | G32: 5997.9 | L32: 1400000 | Q32: =SUM(L32:P33) -> 1400000
C33: 43 | D33: ZHENG HUI | F33: BEN CAT | G33: 720
A34: 18 | B34: 12/9/2025 | C34: 45+46 | D34: NIDEC VN | F34: Q9 | G34: 3000 | L34: 700000 | Q34: =SUM(L34:P35) -> 1550000 | R34: C2
C35: 41+42 | D35: TAN PHAT 2 | F35: DI AN | H35: 222400 | I35: 872.564 | M35: 850000
A36: 19 | B36: 13/9/2025 | C36: 26+28+29+30 | D36: HOANG ANH | F36: BEN LUC | H36: =101000+45000 -> 146000 | I36: =606+270 -> 876 | M36: 2200000 | Q36: =SUM(L36:P36) -> 2200000
A37: 20 | B37: 15/9/2025 | C37: 16 | D37: TAXIN | F37: LONG THANH | H37: 187200 | I37: 1703.52 | J37: 545 | M37: 2050000 | P37: =J37*400 -> 218000 | Q37: =SUM(L37:P37) -> 2268000 | R37: LẤY PHẾ NIDEC INS
A38: 21 | B38: 16/9/2025 | C38: 45 | D38: CHI YEN | F38: TDM | H38: 15000 | I38: 398.4238 | M38: 1200000 | Q38: =SUM(L38:P40) -> 1200000 | R38: 2X
C39: 8+3 | D39: ANH NGAN | F39: BEN CAT | H39: =20000+30600 -> 50600 | I39: =434+624.393 -> 1058.393
C40: 17+38 | D40: KOYO | F40: BEN CAT | H40: =41000+60000 -> 101000 | I40: =41000+923.94 -> 41923.94
...

Sheet DANH
A1: ='[1]A VIEN'!A1:Q1 -> 2025年09销路运费
A2: CHI PHÍ VẬN CHUYỂN HÀNG NỘI ĐỊA
A3: ='[1]A VIEN'!A3:Q3 -> THÁNG 09 NĂM 2025
A4: NCC: ANH DANH - 10T
A5: STT 次序 | B5: Ngày xuất hàng 日期 | C5: Đơn xuất hàng 销货单 | D5: Khách hàng 客户 | E5: Địa chỉ KH 送货地址 | G5: SỐ LƯỢNG 重量 NET WEIGHT | K5: SỐ LƯỢNG 重量 (kg) GROSS WEIGHT | L5: PHÍ VẬN CHUYỂN 路运费 | N5: CHI PHÍ KHÁC (LẤY HÀNG VỀ/GIAO MẪU…) | P5: CHỞ PHẾ | Q5: THÀNH TIỀN 合计 | R5: GHI CHÚ
E6: NỘI THÀNH | F6: NGOẠI THÀNH | G6: MÀNG NHỰA | H6: ĐỊNH HÌNH | J6: PHẾ LIỆU
G7: KG | H7: PCS | I7: KG | J7: KG | L7: MÀNG NHỰA | M7: ĐỊNH HÌNH | N7: MÀNG NHỰA | O7: ĐỊNH HÌNH
A8: 1 | B8: 26/8/2025 | C8: 32+18 | D8: VINATRAY | F8: HOC MON | G8: 95 | H8: =19955+51000 -> 70955 | I8: =770.2028+1326 -> 2096.2028 | M8: 1850000 | Q8: =SUM(L8:P9) -> 1850000
C9: 28 | D9: UNITED | F9: CU CHI | H9: 95000 | I9: 864.5
A10: 2 | B10: 27/8/2025 | C10: 9 | D10: WAHL | F10: CAN GIUOC | H10: 46900 | I10: 1127.8544 | M10: 2600000 | O10: =63*500 -> 31500 | Q10: =SUM(L10:P11) -> 2631500 | R10: LẤY VỀ 63PCS VỎ THÙNG
C11: 12 | D11: HANH MINH KHOI | F11: CAN GIUOC | H11: 36000 | I11: 1305.24
A12: 3 | B12: 28/8/2025 | C12: 21+25 | D12: LONG PHAT | F12: BINH CHANH | H12: =111105+102330 -> 213435 | I12: =1056.72+1531.5953 -> 2588.3153 | M12: 2000000 | Q12: =SUM(L12:P12) -> 2000000 | R12: 2X
A13: 4 | B13: 29/8/2025 | C13: 6 | D13: LE LAN | F13: BINH TAN | H13: 140410 | I13: 2918.916 | M13: 1850000 | Q13: =SUM(L13:P13) -> 1850000 | R13: 2X
A14: 5 | B14: 30/8/2025 | C14: 23 | D14: ACUMEN | F14: THUAN AN | G14: 5027 | L14: 1400000 | Q14: =SUM(L14:P14) -> 1400000
A15: 6 | B15: 30/8/2025 | C15: 19+13+16 | D15: LONG PHAT | F15: BINH CHANH | H15: =9600+61830+75600 -> 147030 | I15: =195.888+1167.8955+1203.96 -> 2567.7435 | M15: 1950000 | Q15: =SUM(L15:P15) -> 1950000 | R15: C2, 2X
A16: 7 | B16: 03/9/2025 | C16: 10 | D16: ANH HUNG | F16: BINH CHANH | H16: 733300 | I16: 3277.4074 | M16: 1950000 | Q16: =SUM(L16:P16) -> 1950000
A17: 8 | B17: 04/9/2025 | C17: 22 | D17: HANH MINH KHOI | F17: CAN GIUOC | H17: 57120 | I17: 1485.12 | M17: 2500000 | Q17: =SUM(L17:P17) -> 2500000
A18: 9 | B18: 05/9/2025 | C18: 4 | D18: STARPRINT | F18: BIEN HOA | H18: 33600 | I18: 2157.12 | J18: 2179 | M18: 1800000 | P18: =J18*400 -> 871600 | Q18: =SUM(L18:P18) -> 2671600 | R18: LAY PHE NIDEC VN 2179KG
A19: 10 | B19: 06/9/2025 | C19: 27+28 | D19: UKP | F19: TAN UYEN | G19: 8500 | L19: 1100000 | Q19: =SUM(L19:P19) -> 1100000
A20: 11 | B20: 08/9/2025 | C20: 42 | D20: AN THAI | F20: DUC HOA | G20: 8111.8 | L20: 2150000 | Q20: =SUM(L20:P20) -> 2150000
A21: 12 | B21: 08/9/2025 | C21: 10+11 | D21: UKP | F21: TAN UYEN | G21: 8900 | J21: 5081 | L21: 1100000 | P21: 800000 | Q21: =SUM(L21:P21) -> 1900000 | R21: C2, LAY PHE UKP 5081KG
A22: 13 | B22: 09/9/2025 | C22: 33+38 | D22: UKP | F22: TAN UYEN | G22: 8900 | L22: 1150000 | Q22: =SUM(L22:P22) -> 1150000
A23: 14 | B23: 10/9/2025 | C23: 17+48 | D23: TAIXIN | F23: LONG THANH | H23: =212000+7000 -> 219000 | I23: =1844.4+60.9 -> 1905.3 | M23: 2150000 | Q23: =SUM(L23:P24) -> 2350000
C24: 10 | D24: THIEN LONG | F24: LONG THANH | G24: 997.5 | L24: 200000
A25: 15 | B25: 10/9/2025 | C25: 11 | D25: LE LAN | F25: BINH TAN | H25: 140400 | I25: 2737.8 | M25: 1750000 | Q25: =SUM(L25:P25) -> 1750000 | R25: C2
A26: 16 | B26: 11/9/2025 | C26: 14 | D26: HANH MINH KHOI | F26: CAN GIUOC | H26: 62200 | I26: 1516.28 | M26: 2600000 | Q26: =SUM(L26:P26) -> 2600000
A27: 17 | B27: 12/9/2025 | C27: 6 | D27: STARPRINT | F27: BIEN HOA | H27: 40320 | I27: 1274.3136 | J27: 2297 | M27: 1800000 | P27: =J27*400 -> 918800 | Q27: =SUM(L27:P27) -> 2718800 | R27: LAY PHE NIDEC VN
A28: 18 | B28: 13/9/2025 | C28: 6 | D28: VINATRAY | F28: HOC MON | H28: 86940 | I28: 2398.2984 | M28: 1750000 | Q28: =SUM(L28:P28) -> 1750000
A29: 19 | B29: 15/9/2025 | C29: 4 | D29: ACUMEN | F29: THUAN AN | G29: 4980 | L29: 1000000 | Q29: =SUM(L29:P30) -> 1500000
C30: 20+19 | D30: TAO LUC | F30: TDM | H30: =9000+94000 -> 103000 | I30: 1117.55 | M30: 500000
A31: 20 | B31: 15/9/2025 | C31: 28+29 | D31: LONG PHAT | F31: BINH CHANH | H31: 219220 | I31: 4052.9254 | M31: 1950000 | Q31: =SUM(L31:P31) -> 1950000 | R31: C2, 2X
A32: 21 | B32: 16/9/2025 | C32: 16 | D32: STARPRINT | F32: BIEN HOA | H32: 23920 | I32: 1252.92 | M32: 1450000 | Q32: =SUM(L32:P34) -> 2670000 | R32: 2X
C33: 15 | D33: BIOVEGI | F33: DI AN | H33: 15200 | I33: 312.706 | R33: LẤY PHẾ NIDEC VN
C34: 52+54 | D34: NIDEC VN | F34: Q9 | G34: 2500 | J34: 1550 | L34: 600000 | P34: =J34*400 -> 620000
A35: 22 | B35: 17/9/2025 | C35: 58 | D35: HUNUFA | F35: DUC HOA | H35: 222100 | I35: 3689.6212 | M35: 2000000 | Q35: =SUM(L35:P35) -> 2000000
A36: 23 | B36: 18/9/2025 | C36: 14+13 | D36: STARPRINT | F36: BIEN HOA | H36: 38080 | I36: 2084.88 | J36: 608 | M36: 1800000 | P36: =J36*400 -> 243200 | Q36: =SUM(L36:P36) -> 2043200 | R36: LẤY PHẾ NIDEC VN
A37: 24 | B37: 19/9/2025 | C37: 41+42 | D37: LONG PHAT | F37: BINH CHANH | H37: 338000 | I37: 3224.7 | M37: 1950000 | Q37: =SUM(L37:P37) -> 1950000
A38: 25 | B38: 20/9/2025 | C38: 57 | D38: AN THAI | F38: DUC HOA | G38: 7350 | L38: 2000000 | Q38: =SUM(L38:P38) -> 2000000
A39: 26 | B39: 20/9/2025 | C39: 1 | D39: LE LAN | F39: BINH TAN | H39: 140400 | I39: 2737.8 | M39: 1750000 | Q39: =SUM(L39:P39) -> 1750000 | R39: C2
A40: 27 | B40: 22/9/2025 | C40: 4 | D40: TAN TIEN PHAT TAI | F40: BINH CHANH | G40: 8928 | L40: 2300000 | Q40: =SUM(L40:P40) -> 2300000
...

Sheet TU 4T
A1: ='[1]A VIEN'!A1:Q1 -> 2025年09销路运费
A2: CHI PHÍ VẬN CHUYỂN HÀNG NỘI ĐỊA
A3: ='[1]A VIEN'!A3:Q3 -> THÁNG 09 NĂM 2025
A4: NCC: ĐINH TÚ 4T
A5: STT 次序 | B5: Ngày xuất hàng 日期 | C5: Đơn xuất hàng 销货单 | D5: Khách hàng 客户 | E5: Địa chỉ KH 送货地址 | G5: SỐ LƯỢNG 重量 NET WEIGHT | K5: SỐ LƯỢNG 重量 (kg) GROSS WEIGHT | L5: PHÍ VẬN CHUYỂN 路运费 | N5: CHI PHÍ KHÁC (LẤY HÀNG VỀ/GIAO MẪU…) | P5: CHỞ PHẾ | Q5: THÀNH TIỀN 合计 | R5: GHI CHÚ
E6: NỘI THÀNH | F6: NGOẠI THÀNH | G6: MÀNG NHỰA | H6: ĐỊNH HÌNH | J6: PHẾ LIỆU
G7: KG | H7: PCS | I7: KG | J7: KG | L7: MÀNG NHỰA | M7: ĐỊNH HÌNH | N7: MÀNG NHỰA | O7: ĐỊNH HÌNH
A8: 1 | B8: 26/8/2025 | C8: 12 | D8: DAI TIEN | F8: TAN UYEN | H8: 143000 | I8: 393.25 | M8: 1380000 | Q8: =SUM(L8:P9) -> 1415000
C9: 27 | D9: HANA | F9: CHO THU DUC | H9: 56500 | I9: 1377.025 | O9: 35000 | R9: VE CHANH
A10: 2 | B10: 27/8/2025 | C10: 25+26 | D10: ANH NGAN | F10: HOC MON | H10: 76000 | I10: 1367.1462 | M10: 1430000 | Q10: =SUM(L10:P11) -> 1480000 | R10: 2X
C11: 5+4 | D11: ANH NGAN | F11: Q12 | H11: 61650 | I11: 588.0185 | O11: 50000 | R11: VE CHANH
A12: 3 | B12: 27/8/2025 | C12: 41+42 | D12: NIDEC VN | F12: Q9 | G12: 2500 | J12: 901 | L12: 1050000 | P12: =J12*400 -> 360400 | Q12: =SUM(L12:P12) -> 1410400 | R12: C2, LAY PHE NIDEC VN
A13: 4 | B13: 28/8/2025 | C13: 15 | D13: AN THAI | F13: DUC HOA | G13: 2990 | L13: 1180000 | Q13: =SUM(L13:P14) -> 1795000
C14: 29+28+27 | D14: PHU HOI | F14: BINH CHANH | H14: 55650 | I14: 540.0825 | M14: 550000 | O14: 65000 | R14: 2X, VE CHANH
A15: 5 | B15: 29/8/2025 | C15: 3 | D15: HARADA | F15: BIEN HOA | G15: 2086 | L15: 850000 | Q15: =SUM(L15:P16) -> 2080000 | R15: 2X
C16: 8 | D16: ANH NGAN | F16: NHON TRACH | H16: 109600 | I16: 1331.46 | M16: 1230000
A17: 6 | B17: 03/9/2025 | C17: 37 | D17: HANA | F17: CHO THU DUC | H17: 37110 | I17: 958.1835 | M17: 1510000 | O17: 35000 | Q17: =SUM(L17:P19) -> 1545000 | R17: 2X, VE CHANH
C18: 13 | D18: BIOVEGI | F18: DI AN | H18: 13800 | I18: 351.8464
C19: 21 | D19: TRUONG AN | F19: THU DUC | H19: 18000 | I19: 462.6
A20: 7 | B20: 04/9/2025 | C20: 23 | D20: MINH KHANG | F20: Q12 | H20: 139230 | I20: 2078.7855 | M20: 1300000 | Q20: =SUM(L20:P20) -> 1300000
A21: 8 | B21: 04/9/2025 | C21: 34 | D21: NIDEC VN | F21: Q9 | G21: 3000 | L21: 1150000 | Q21: =SUM(L21:P21) -> 1150000 | R21: C2
A22: 9 | B22: 05/9/2025 | C22: 1 | D22: DONG BAC VINA | F22: HOC MON | G22: 3530 | L22: 800000 | Q22: =SUM(L22:P23) -> 1430000 | R22: 2X
C23: 39 | D23: ANH NGAN | F23: HOC MON | H23: 61000 | I23: 662.334 | M23: 630000
A24: 10 | B24: 06/9/2025 | C24: 14+15+23 | D24: TH FARM | F24: THU DUC | H24: =12950+93000 -> 105950 | I24: =278.45+2038.2162 -> 2316.6662 | M24: 1350000 | Q24: =SUM(L24:P24) -> 1350000 | R24: 2X
A25: 11 | B25: 06/9/2025 | C25: 11 | D25: TAXIN | F25: LONG THANH | H25: 147000 | I25: 1278.9 | M25: 1900000 | Q25: =SUM(L25:P25) -> 1900000 | R25: C2
A26: 12 | B26: 08/9/2025 | C26: 8 | D26: HANH MINH KHOI | F26: CAN GIUOC | H26: 45000 | I26: 909 | M26: 2050000 | Q26: =SUM(L26:P26) -> 2050000
A27: 13 | B27: 09/9/2025 | C27: 11 | D27: HANH MINH KHOI | F27: CAN GIUOC | H27: 45000 | I27: 909 | M27: 2050000 | Q27: =SUM(L27:P27) -> 2050000
A28: 14 | B28: 10/9/2025 | C28: 2 | D28: HARADA | F28: LONG BINH | G28: 200 | L28: 20000 | Q28: =SUM(L28:P30) -> 1980000 | R28: 2X
C29: 3 | D29: HARADA | F29: BIEN HOA | G29: 627
C30: 43 | D30: HUNG THAO | F30: NHON TRACH | H30: 144800 | I30: 2161.579 | M30: 1960000
A31: 15 | B31: 11/9/2025 | C31: 27+28 | D31: MINH KHANG | F31: Q12 | H31: 227000 | I31: 2290.908 | M31: 1300000 | Q31: =SUM(L31:P31) -> 1300000
A32: 16 | B32: 11/9/2025 | C32: 36+37 | D32: NIDEC VN | F32: Q9 | G32: 3000 | L32: 1200000 | Q32: =SUM(L32:P32) -> 1200000 | R32: C2, 2X
A33: 17 | B33: 12/9/2025 | C33: 7 | D33: WAHL | F33: CAN GIUOC | H33: 61060 | I33: 1408.009 | M33: 2050000 | O33: =100*500 -> 50000 | Q33: =SUM(L33:P33) -> 2100000 | R33: LẤY 100 PCS VỎ THÙNG VỀ
A34: 18 | B34: 13/9/2025 | C34: 14+15+18 | D34: TAIXIN | F34: LONG THANH | H34: =168000+13000 -> 181000 | I34: =1461.6+113.1 -> 1574.7 | M34: 1950000 | Q34: =SUM(L34:P34) -> 1950000
A35: 19 | B35: 15/9/2025 | C35: 17+18 | D35: MINH KHANG | F35: Q12 | H35: =32400+3600 -> 36000 | I35: 709.5195 | M35: 1380000 | O35: 100000 | Q35: =SUM(L35:P36) -> 1480000 | R35: LẤY VỀ 12T JB25A
C36: 49 | D36: ANH NGAN | F36: Q12 | H36: 155780 | I36: 1830.7764
A37: 20 | B37: 15/9/2025 | C37: 46+56 | D37: NIDEC VN | F37: Q9 | G37: =3000+119 -> 3119 | J37: 1198 | L37: 1150000 | P37: =J37*400 -> 479200 | Q37: =SUM(L37:P37) -> 1629200 | R37: C2, LAY PHẾ NIDEC VN
A38: 21 | B38: 16/9/2025 | C38: 21 | D38: DONG BAC VINA | F38: HOC MON | G38: 3780 | L38: 800000 | Q38: =SUM(L38:P39) -> 1430000 | R38: 2X
C39: 26 | D39: ANH NGAN | F39: HOC MON | H39: 30600 | I39: 624.393 | M39: 630000
A40: 22 | B40: 17/9/2025 | C40: 2 | D40: P&G | F40: VSIP 2 | H40: 15040 | I40: 281.0311 | M40: 130000 | Q40: =SUM(L40:P41) -> 780000 | R40: 2X
...

Sheet HUU
A1: ='[1]A VIEN'!A1:Q1 -> 2025年09销路运费
A2: CHI PHÍ VẬN CHUYỂN HÀNG NỘI ĐỊA
A3: ='[1]A VIEN'!A3:Q3 -> THÁNG 09 NĂM 2025
A4: NCC: NGUYỄN TRỌNG HỮU - 8T-61C42819
A5: STT 次序 | B5: Ngày xuất hàng 日期 | C5: Đơn xuất hàng 销货单 | D5: Khách hàng 客户 | E5: Địa chỉ KH 送货地址 | G5: SỐ LƯỢNG 重量 NET WEIGHT | K5: SỐ LƯỢNG 重量 (kg) GROSS WEIGHT | L5: PHÍ VẬN CHUYỂN 路运费 | N5: CHI PHÍ KHÁC (LẤY HÀNG VỀ/GIAO MẪU…) | P5: CHỞ PHẾ | Q5: THÀNH TIỀN 合计 | R5: GHI CHÚ
E6: NỘI THÀNH | F6: NGOẠI THÀNH | G6: MÀNG NHỰA | H6: ĐỊNH HÌNH | J6: PHẾ LIỆU
G7: KG | H7: PCS | I7: KG | J7: KG | L7: MÀNG NHỰA | M7: ĐỊNH HÌNH | N7: MÀNG NHỰA | O7: ĐỊNH HÌNH
A8: 1 | B8: 26/8/2025 | C8: 19 | D8: VINATRAY | F8: HOC MON | H8: 154720 | I8: 3446.8933 | M8: 1900000 | Q8: =SUM(L8:P8) -> 1900000
A9: 2 | B9: 27/8/2025 | C9: 19 | D9: DAI TIEN | F9: TAN UYEN | H9: 204600 | I9: 1664.7026 | M9: 1200000 | Q9: =SUM(L9:P10) -> 1200000
C10: 23 | D10: TAO LUC | F10: TDM | H10: 149830 | I10: 2572.5555
A11: 3 | B11: 27/8/2025 | C11: 1+2 | D11: LE LAN | F11: BINH TAN | H11: 187920 | I11: 3906.8568 | M11: 1900000 | Q11: =SUM(L11:P11) -> 1900000 | R11: C2
A12: 4 | B12: 28/8/2025 | C12: 40+38 | D12: VINATRAY | F12: HOC MON | H12: =184000+21000 -> 205000 | I12: =2849.8231+686.7 -> 3536.5231 | M12: 1950000 | Q12: =SUM(L12:P12) -> 1950000 | R12: 2X
A13: 5 | B13: 29/8/2025 | C13: 2 | D13: COLOMATE | F13: TAN UYEN | H13: 110275 | I13: 2738.2829 | M13: 1600000 | Q13: =SUM(L13:P14) -> 1600000 | R13: 2X
C14: 9 | D14: DAI TIEN | F14: TAN UYEN | H14: 700000 | I14: 1365
A15: 6 | B15: 29/8/2025 | C15: 7 | D15: HOANG ANH | F15: BEN LUC | H15: 346000 | I15: 5235.315 | M15: 2600000 | O15: 200000 | Q15: =SUM(L15:P15) -> 2800000 | R15: C3, GIAO TOI
A16: 7 | B16: 29/8/2025 | C16: 19 | D16: VINATRAY | F16: HOC MON | H16: 209400 | I16: 4023.5999 | M16: 1850000 | Q16: =SUM(L16:P16) -> 1850000 | R16: C2
A17: 8 | B17: 30/8/2025 | C17: 1 | D17: LE LAN | F17: BINH TAN | H17: 146880 | I17: 3053.6352 | M17: 1950000 | Q17: =SUM(L17:P17) -> 1950000
A18: 9 | B18: 31/8/2025 | C18: 1+2 | D18: VAN-BINH THUAN | F18: PHAN THIET | H18: =228400+60000 -> 288400 | I18: =3835.8865+445.7 -> 4281.5865 | M18: 2700000 | Q18: =SUM(L18:P18) -> 2700000
A19: 10 | B19: 03/9/2025 | C19: 15+2 | D19: LE LAN | F19: BINH TAN | H19: =105840+41040 -> 146880 | I19: =2200.4136+853 -> 3053.4136 | M19: 1950000 | Q19: =SUM(L19:P19) -> 1950000
A20: 11 | B20: 04/9/2025 | C20: 22+19 | D20: VINATRAY | F20: HOC MON | H20: =32400+490000 -> 522400 | I20: =631.8+5759 -> 6390.8 | M20: 1900000 | Q20: =SUM(L20:P20) -> 1900000
A21: 12 | B21: 04/9/2025 | C21: 1 | D21: HOANG ANH | F21: BEN LUC | H21: 548810 | I21: 1524.36 | M21: 2650000 | Q21: =SUM(L21:P21) -> 2650000
A22: 13 | B22: 05/9/2025 | C22: 40 | D22: LONG PHAT | F22: BINH CHANH | H22: 163800 | I22: 3878.9901 | M22: 2100000 | Q22: =SUM(L22:P22) -> 2100000
A23: 14 | B23: 05/9/2025 | C23: 12 | D23: HOANG ANH | F23: BEN LUC | H23: 247000 | I23: 4120.4931 | M23: 2600000 | O23: 200000 | Q23: =SUM(L23:P23) -> 2800000 | R23: GIAO TOI, C2
A24: 15 | B24: 06/9/2025 | C24: 41 | D24: LONG PHAT | F24: BINH CHANH | H24: 216000 | I24: 4069.5 | M24: 2100000 | Q24: =SUM(L24:P24) -> 2100000
A25: 16 | B25: 08/9/2025 | C25: 12+13+GC | D25: UKP | F25: TAN UYEN | G25: =2997.6+4000+2000 -> 8997.6 | M25: 1150000 | Q25: =SUM(L25:P25) -> 1150000
A26: 17 | B26: 08/9/2025 | C26: 18+19+35+ 36+15 | D26: HOANG ANH | F26: BEN LUC | H26: =19000+19000+331600 -> 369600 | I26: =243.2+243.2+4618.763 -> 5105.163 | M26: 2650000 | Q26: =SUM(L26:P26) -> 2650000
A27: 18 | B27: 09/9/2025 | C27: 9+8 | D27: VINATRAY | F27: HOC MON | H27: 163300 | I27: 3347.79 | M27: 1950000 | Q27: =SUM(L27:P27) -> 1950000 | R27: 2X
A28: 19 | B28: 10/9/2025 | C28: 16+17 | D28: VINATRAY | F28: HOC MON | H28: 83400 | I28: 1878.4889 | M28: 1200000 | Q28: =SUM(L28:P29) -> 2050000 | R28: 2X
C29: 41 | D29: HIEP HUNG | F29: CU CHI | G29: 4074.5 | L29: 850000
A30: 20 | B30: 10/9/2025 | C30: 36+37+GC | D30: UKP | F30: TAN UYEN | G30: 8900 | L30: 1150000 | Q30: =SUM(L30:P30) -> 1150000
A31: 21 | B31: 11/9/2025 | C31: 1 | D31: LE LAN | F31: BINH TAN | H31: 146880 | I31: 2864.16 | M31: 1900000 | Q31: =SUM(L31:P31) -> 1900000 | R31: C2
A32: 22 | B32: 11/9/2025 | C32: 32+GC | D32: UKP | F32: TAN UYEN | G32: 8900 | L32: 1150000 | Q32: =SUM(L32:P32) -> 1150000
A33: 23 | B33: 11/9/2025 | C33: 47 | D33: LONG PHAT | F33: BINH CHANH | H33: 165000 | I33: 5090.25 | M33: 2050000 | O33: 200000 | Q33: =SUM(L33:P33) -> 2250000 | R33: C3, GIAO TOI
A34: 24 | B34: 12/9/2025 | C34: 2 | D34: LE LAN | F34: BINH TAN | H34: 159840 | I34: 3116.88 | M34: 1950000 | Q34: =SUM(L34:P34) -> 1950000
A35: 25 | B35: 12/9/2025 | C35: 23+24+25+ 26+27+29 | D35: HOANG ANH | F35: BEN LUC | H35: =223460+510000 -> 733460 | I35: =3540.421+714 -> 4254.421 | M35: 2600000 | O35: 200000 | Q35: =SUM(L35:P35) -> 2800000 | R35: C2, GIAO TOI
A36: 26 | B36: 13/9/2025 | C36: 18 | D36: HANH MINH KHOI | F36: CAN GIUOC | H36: 74200 | I36: 1929.2 | M36: 2650000 | Q36: =SUM(L36:P36) -> 2650000
A37: 27 | B37: 15/9/2025 | C37: 1 | D37: LE LAN | F37: BINH TAN | H37: 159840 | I37: 3116.88 | M37: 1950000 | Q37: =SUM(L37:P37) -> 1950000
A38: 28 | B38: 15/9/2025 | C38: 6+10+11+ 12+13+14 | D38: HOANG ANH | F38: BEN LUC | H38: =1057200+143000 -> 1200200 | I38: =2060.503+1699.2164 -> 3759.7194 | M38: 2600000 | O38: 200000 | Q38: =SUM(L38:P38) -> 2800000 | R38: C2, GIAO TOI
A39: 29 | B39: 16/9/2025 | C39: 6+7+8+9 +10+57 | D39: HOANG ANH | F39: BEN LUC | H39: =272800+21600+94000 -> 388400 | I39: =3923.024+440.748+258.5 -> 4622.272 | M39: 2650000 | Q39: =SUM(L39:P39) -> 2650000
A40: 30 | B40: 17/9/2025 | C40: 17+19 | D40: VINATRAY | F40: HOC MON | H40: =154000+60500 -> 214500 | I40: =2460+1492.0661 -> 3952.0661 | M40: 1900000 | Q40: =SUM(L40:P40) -> 1900000
...

Sheet TH
A1: STT | B1: XE | C1: PHÍ VC CHƯA VAT | D1: VAT 8% | E1: THÀNH TIỀN
A2: 1 | B2: HIẾU | C2: =HIEU!Q57 -> 37144000 | D2: =C2*8% -> 2971520 | E2: =C2+D2 -> 40115520
A3: 2 | B3: NAM | C3: =NAM!Q59 -> 41330000 | D3: =C3*8% -> 3306400 | E3: =C3+D3 -> 44636400
A4: 3 | B4: TÚ | C4: ='TU 2T'!Q54 -> 36902000 | D4: =C4*8% -> 2952160 | E4: =C4+D4 -> 39854160
A5: 4 | B5: HOÀNG | C5: =HOANG!Q51 -> 32908400 | D5: =C5*8% -> 2632672 | E5: =C5+D5 -> 35541072
A6: 5 | B6: TUẤN | C6: =TUAN!Q55 -> 56148000 | D6: =C6*8% -> 4491840 | E6: =C6+D6 -> 60639840
A7: 6 | B7: TÚ 4T | C7: ='TU 4T'!Q56 -> 51779300 | D7: =C7*8% -> 4142344 | E7: =C7+D7 -> 55921644
A8: 7 | B8: HỮU | C8: =HUU!Q55 -> 93000000 | D8: =C8*8% -> 7440000 | E8: =C8+D8 -> 100440000
A9: 8 | B9: DANH | C9: =DANH!Q46 -> 65135100 | D9: =C9*8% -> 5210808 | E9: =C9+D9 -> 70345908
A10: TỔNG | C10: =SUM(C2:C9) -> 414346800 | D10: =SUM(D2:D9) -> 33147744 | E10: =SUM(E2:E9) -> 447494544
