Workbook

Sheet HIEU
A1: ='[1]A VIEN'!A1:Q1 -> 2025年12销路运费
A2: CHI PHÍ VẬN CHUYỂN HÀNG NỘI ĐỊA
A3: ='[1]A VIEN'!A3:Q3 -> THÁNG 12 NĂM 2025
A4: NCC: TRỊNH MINH HIẾU
A5: STT 次序 | B5: Ngày xuất hàng 日期 | C5: Đơn xuất hàng 销货单 | D5: Khách hàng 客户 | E5: Địa chỉ KH 送货地址 | G5: SỐ LƯỢNG 重量 NET WEIGHT | K5: SỐ LƯỢNG 重量 (kg) GROSS WEIGHT | L5: PHÍ VẬN CHUYỂN 路运费 | N5: CHI PHÍ KHÁC (LẤY HÀNG VỀ/GIAO MẪU…) | P5: CHỞ PHẾ | Q5: THÀNH TIỀN 合计 | R5: GHI CHÚ
E6: NỘI THÀNH | F6: NGOẠI THÀNH | G6: MÀNG NHỰA | H6: ĐỊNH HÌNH
G7: KG | H7: PCS | I7: KG | L7: MÀNG NHỰA | M7: ĐỊNH HÌNH | N7: MÀNG NHỰA | O7: ĐỊNH HÌNH
A8: 1 | B8: 26/11/2025 | C8: 4 | D8: KMS | E8: BEN CAT | H8: 30000 | I8: 307.53 | M8: 550000 | Q8: =SUM(L8:P8) -> 550000 | R8: 60B. TINH 1.5T
A9: 2 | B9: 26/11/2025 | C9: 6 | D9: HOA THAI | E9: BINH TAN | G9: 2100 | L9: 1100000 | Q9: =SUM(L9:P9) -> 1100000
A10: 3 | B10: 27/11/2025 | C10: 13 | D10: CHI YEN | E10: BINH TAN | H10: 39900 | I10: 1291.7351 | M10: 1100000 | O10: 60000 | Q10: =SUM(L10:P10) -> 1160000 | R10: VE CHANH
A11: 4 | B11: 28/11/2025 | C11: 44 | D11: P&G | E11: VSIP 2 | H11: 10560 | I11: 601.92 | M11: 550000 | O11: =300000+300000 -> 600000 | Q11: =SUM(L11:P11) -> 1150000 | R11: CHỞ HANG DI KIEM HOA-KCN SONG THAN + PHÍ LƠ XE
A12: 5 | B12: 28/11/2025 | C12: 49 | D12: ANH NGAN | E12: Q12 | H12: 46050 | I12: 1109.8725 | M12: 1000000 | Q12: =SUM(L12:P12) -> 1000000
A13: 6 | B13: 29/11/2025 | C13: 8 | D13: HANA | E13: NHA BE | H13: 24000 | I13: 753.2283 | M13: 1650000 | Q13: =SUM(L13:P15) -> 1650000 | R13: GAN CAN GIUOC +300K
C14: 9 | D14: HANA | E14: Q10 | H14: 5100 | I14: 160.061
C15: 10 | D15: HANA | E15: BINH CHANH | H15: 8800 | I15: 572
A16: 7 | B16: 01/12/2025 | C16: 2 | D16: BB NGOC THANH | E16: Q8 | H16: 700000 | I16: 980 | M16: 1150000 | Q16: =SUM(L16:P16) -> 1150000
A17: 8 | B17: 01/12/2025 | C17: 3 | D17: BB NGOC THANH | E17: Q8 | H17: 365000 | I17: 1372 | M17: 1100000 | O17: 200000 | Q17: =SUM(L17:P17) -> 1300000 | R17: GIAO TOI, C2
A18: 9 | B18: 02/12/2025 | C18: 12 | D18: BIOPLAS | E18: GO VAP | H18: 282000 | I18: 1382.1519 | M18: 1000000 | O18: =109*500 -> 54500 | Q18: =SUM(L18:P18) -> 1054500 | R18: LẤY 109PCS VỎ THÙNG VỀ
A19: 10 | B19: 03/12/2025 | C19: 22 | D19: KMS | E19: BEN CAT | H19: 40000 | I19: 617.6 | M19: 550000 | Q19: =SUM(L19:P19) -> 550000 | R19: 80B. TINH PHI 1.5T
A20: 11 | B20: 03/12/2025 | C20: 21 | D20: GALLANT | E20: Q12 | H20: 60000 | I20: 1500 | M20: 1000000 | O20: 40000 | Q20: =SUM(L20:P20) -> 1040000 | R20: VE CHANH
A21: 12 | B21: 04/12/2025 | C21: 9 | D21: TAN DAI LONG | E21: BINH TAN | H21: 30000 | I21: 288 | M21: 1150000 | Q21: =SUM(L21:P22) -> 1150000
C22: 19 | D22: ANH NGAN | E22: Q12 | H22: 510000 | I22: 714
A23: 13 | B23: 05/12/2025 | C23: 59 | D23: ECOPAK | E23: BINH TAN | H23: 96000 | I23: 835.2 | M23: 1100000 | O23: =237*500 -> 118500 | Q23: =SUM(L23:P23) -> 1218500 | R23: LẤY VỀ 237PCS VỎ THÙNG NHỰA
A24: 14 | B24: 05/12/2025 | C24: 39 | D24: P&G | E24: VSIP 2 | G24: 349 | L24: 350000 | O24: 200000 | Q24: =SUM(L24:P24) -> 550000 | R24: GIAO TOI .PHI 1.5T
A25: 15 | B25: 06/12/2025 | C25: 5+12 | D25: RVC | E25: THU DUC | H25: =20000+55000 -> 75000 | I25: =399.85+120 -> 519.85 | M25: 1250000 | Q25: =SUM(L25:P27) -> 1250000 | R25: 2X
C26: 18+19 | D26: PHU HOI | E26: Q9 | H26: 140000 | I26: 527.572
C27: 21 | D27: RUECO | E27: GA ST | H27: 20000 | I27: 172
A28: 16 | B28: 07/12/2025 | C28: 2+3+4 | D28: PLASACO | E28: TAN BINH | H28: 126000 | I28: 1170.4497 | M28: 1100000 | Q28: =SUM(L28:P28) -> 1100000
A29: 17 | B29: 08/12/2025 | C29: 20 | D29: VINA HT | E29: BINH TAN | H29: 160000 | I29: 624 | M29: 1100000 | Q29: =SUM(L29:P29) -> 1100000
A30: 18 | B30: 09/12/2025 | C30: 14 | D30: VIFON | E30: TAN PHU | H30: 320000 | I30: 1842.976 | M30: 1100000 | Q30: =SUM(L30:P30) -> 1100000
A31: 19 | B31: 10/12/2025 | C31: 1 | D31: LC FOODS | E31: BEN CAT | H31: 40000 | I31: 317.982 | M31: 850000 | Q31: =SUM(L31:P32) -> 850000 | R31: 2X
C32: 11 | D32: ANH NGAN | E32: BEN CAT | H32: 36600 | I32: 726.4096
A33: 20 | B33: 10/12/2025 | C33: 12 | D33: ANH NGAN | E33: Q6 | H33: 47050 | I33: 1094.19 | M33: 1100000 | O33: 60000 | Q33: =SUM(L33:P33) -> 1160000 | R33: C2, VE CHANH
A34: 21 | B34: 12/12/2025 | C34: 5 | D34: ECOPAK | E34: BINH TAN | H34: 96000 | I34: 835.2 | M34: 1100000 | O34: =42*500+100000 -> 121000 | Q34: =SUM(L34:P34) -> 1221000 | R34: LẤY 42PCS VỎ THÙNG, LẤY 17T TAO LUC VỀ (KIM HOA)
A35: 22 | B35: 12/12/2025 | C35: 24 | D35: ECOPAK | E35: BINH TAN | H35: 96000 | I35: 851.9808 | M35: 1050000 | O35: 200000 | Q35: =SUM(L35:P35) -> 1250000 | R35: GIAO TOI, C2
A36: 23 | B36: 13/12/2025 | C36: 20 | D36: BB NGOC THANH | E36: Q6 | H36: 122000 | I36: 1352.2202 | M36: 1150000 | N36: 50000 | Q36: =SUM(L36:P36) -> 1200000 | R36: GIAO MAU MY LAN Q6-X1 (HẠNH)
A37: 24 | B37: 14/12/2025 | C37: 43 | D37: GIA MINH | E37: BINH CHANH | H37: 124200 | I37: 1661.3469 | M37: 1150000 | Q37: =SUM(L37:P37) -> 1150000
A38: 25 | B38: 15/12/2025 | C38: 7 | D38: QUANG DUNG | E38: BIEN HOA | H38: 94002 | I38: 1147.8768 | M38: 1150000 | Q38: =SUM(L38:P38) -> 1150000 | R38: 2X
A39: 26 | B39: 16/12/2025 | C39: 3 | D39: VIFON | E39: TAN PHU | H39: 320000 | I39: 1842.976 | M39: 1100000 | Q39: =SUM(L39:P39) -> 1100000
A40: 27 | B40: 16/12/2025 | C40: 41 | D40: AN THAI | E40: DUC HOA | G40: 1283 | M40: 1200000 | Q40: =SUM(L40:P40) -> 1200000 | R40: ĐI THIẾU TẢI DO HÀNG GẤP (THI, HẠNH), C2
...

Sheet NAM
A1: ='[1]A VIEN'!A1:Q1 -> 2025年12销路运费
A2: CHI PHÍ VẬN CHUYỂN HÀNG NỘI ĐỊA
A3: ='[1]A VIEN'!A3:Q3 -> THÁNG 12 NĂM 2025
A4: NCC: A NAM - 2.5T-61H10411
A5: STT 次序 | B5: Ngày xuất hàng 日期 | C5: Đơn xuất hàng 销货单 | D5: Khách hàng 客户 | E5: Địa chỉ KH 送货地址 | G5: SỐ LƯỢNG 重量 NET WEIGHT | K5: SỐ LƯỢNG 重量 (kg) GROSS WEIGHT | L5: PHÍ VẬN CHUYỂN 路运费 | N5: CHI PHÍ KHÁC (LẤY HÀNG VỀ/GIAO MẪU…) | P5: CHỞ PHẾ | Q5: THÀNH TIỀN 合计 | R5: GHI CHÚ
E6: NỘI THÀNH | F6: NGOẠI THÀNH | G6: MÀNG NHỰA | H6: ĐỊNH HÌNH
G7: KG | H7: PCS | I7: KG | L7: MÀNG NHỰA | M7: ĐỊNH HÌNH | N7: MÀNG NHỰA | O7: ĐỊNH HÌNH
A8: 1 | B8: 26/11/2025 | C8: 6+7+26+ 27+28+21 | D8: RVC | E8: THU DUC | H8: =37600+29100+5000+1400 -> 73100 | I8: =565.6706+342.7378+130+61.46 -> 1099.8684 | M8: 1050000 | Q8: =SUM(L8:P8) -> 1050000 | R8: 2X
A9: 2 | B9: 27/11/2025 | C9: 34+33 | D9: PHU HOI | E9: Q9 | H9: 40000 | I9: 424.8276 | M9: 1150000 | Q9: =SUM(L9:P10) -> 1150000
C10: 25 | D10: CHI YEN | E10: Q9 | H10: 316000 | I10: 963.8
A11: 3 | B11: 28/11/2025 | C11: 9+4+2+3 | D11: RVC | E11: THU DUC | G11: 120 | H11: 118400 | I11: 1460.6483 | M11: 1050000 | Q11: =SUM(L11:P11) -> 1050000 | R11: 2X
A12: 4 | B12: 28/11/2025 | C12: 12 | D12: QUEEN PACK | E12: THU DUC | H12: 57000 | I12: 546 | M12: 950000 | Q12: =SUM(L12:P12) -> 950000 | R12: C2
A13: 5 | B13: 29/11/2025 | C13: 39 | D13: THINH PHAT | E13: BINH THANH | G13: 1020 | L13: 1050000 | Q13: =SUM(L13:P16) -> 1250000
C14: 29 | D14: LIEN TAM KHOA | E14: Q12 | G14: 360
C15: 32 | D15: LE LAN | E15: BINH TAN | G15: 240
C16: 43 | D16: HONG PHAT | E16: Q12 | H16: 56000 | I16: 443.8 | M16: 200000
A17: 6 | B17: 01/12/2025 | C17: 12 | D17: NPP HUNG THAO | E17: NHON TRACH | H17: 90000 | I17: 1105.3164 | M17: 1550000 | Q17: =SUM(L17:P17) -> 1550000
A18: 7 | B18: 02/12/2025 | C18: 34 | D18: RVC | E18: THU DUC | H18: 51600 | I18: 1687.32 | M18: 1000000 | Q18: =SUM(L18:P18) -> 1000000
A19: 8 | B19: 03/12/2025 | C19: 41 | D19: ECOPAK | E19: BINH TAN | H19: 96000 | I19: 851.9808 | M19: 1100000 | Q19: =SUM(L19:P19) -> 1100000
A20: 9 | B20: 04/12/2025 | C20: 20+54 | D20: PHU HOI | E20: Q9 | H20: =18000+30000 -> 48000 | I20: =367.29+339.6 -> 706.89 | M20: 1150000 | Q20: =SUM(L20:P21) -> 1150000
C21: 29 | D21: CHI YEN | E21: Q9 | H21: 380000 | I21: 532
A22: 10 | B22: 04/12/2025 | C22: 1+2 | D22: ANH CONG | E22: Q8 | H22: 56400 | I22: 1570.44 | M22: 1100000 | O22: 260000 | Q22: =SUM(L22:P22) -> 1360000 | R22: GIAO TỐI, C2, VE CHANH
A23: 11 | B23: 05/12/2025 | C23: 18+19+20 | D23: GIA MINH | E23: Q8 | H23: 112650 | I23: 1387.1238 | M23: 1150000 | O23: 575000 | Q23: =SUM(L23:P23) -> 1725000 | R23: GHÉ HƯƠNG MY LẤY HÀNG GC VỀ - 1.8 TẤN (TUYẾN)
A24: 12 | B24: 06/12/2025 | C24: 17 | D24: THUAN THANH | E24: BINH CHANH | H24: 16830 | I24: 519.2055 | M24: 1200000 | O24: 300000 | Q24: =SUM(L24:P25) -> 1500000 | R24: GHÉ HƯƠNG MY LẤY HÀNG GC VE-600KG (TUYẾN)
C25: 16 | D25: THUAN THANH | E25: BINH TAN | H25: 16500 | I25: 509.025
A26: 13 | B26: 08/12/2025 | C26: 4 | D26: THE KY XANH | E26: TAN PHU | H26: 64200 | I26: 1278.6665 | M26: 1100000 | Q26: =SUM(L26:P26) -> 1100000
A27: 14 | B27: 09/12/2025 | C27: 19 | D27: ANH NGAN | E27: Q12 | H27: 115000 | I27: 307.9745 | M27: 1200000 | Q27: =SUM(L27:P29) -> 1200000
C28: 29 | D28: ANH NGAN | E28: BINH TAN | H28: 47000 | I28: 269.7325
C29: 20 | D29: PHU HOI | E29: HOC MON | H29: 83000 | I29: 748.3242
A30: 15 | B30: 10/12/2025 | C30: 5 | D30: WAHL | E30: CAN GIUOC | H30: 44610 | I30: 1068.3534 | M30: 1850000 | O30: 50000 | Q30: =SUM(L30:P30) -> 1900000 | R30: LẤY 210 PCS VỎ THÙNG VỀ
A31: 16 | B31: 11/12/2025 | C31: 46 | D31: ECOPAK | E31: BINH TAN | H31: 96000 | I31: 835.2 | M31: 1100000 | Q31: =SUM(L31:P31) -> 1100000 | R31: LẤY 129PCS VỎ THÙNG VỀ
A32: 17 | B32: 12/12/2025 | C32: 3 | D32: WAHL | E32: CAN GIUOC | H32: 21160 | I32: 484.0688 | M32: 1950000 | Q32: =SUM(L32:P33) -> 1950000 | R32: 2X
C33: 29 | D33: PHU HOI | E33: Q9 | H33: 19200 | I33: 391.776
A34: 18 | B34: 13/12/2025 | C34: 36 | D34: NAM PHAM | E34: TAN PHU | H34: 20000 | I34: 225.825 | M34: 1200000 | Q34: =SUM(L34:P35) -> 1200000
C35: 27 | D35: HOANG ANH | E35: Q8 | H35: 122400 | I35: 732.564
A36: 19 | B36: 15/12/2025 | C36: 1 | D36: STARPRINT | E36: BIEN HOA | H36: 15760 | I36: 795.11 | M36: 1100000 | Q36: =SUM(L36:P36) -> 1100000
A37: 20 | B37: 16/12/2025 | C37: 34+44 | D37: GIA MINH | E37: BINH CHANH | H37: =70600+623000 -> 693600 | I37: =979.5261+901.8738 -> 1881.3999 | M37: 1150000 | Q37: =SUM(L37:P37) -> 1150000
A38: 21 | B38: 17/12/2025 | C38: 11+13 | D38: PLASACO | E38: TAN BINH | H38: 91800 | I38: 1141.6418 | M38: 1100000 | O38: 300000 | Q38: =SUM(L38:P38) -> 1400000 | R38: GHÉ CTY PHAM HA-Q12 LẤY 300KG TÚI PE (NGÂN)
A39: 22 | B39: 17/12/2025 | C39: 42 | D39: ECOPACK | E39: BINH TAN | H39: 96000 | I39: 835.2 | M39: 1050000 | O39: 200000 | Q39: =SUM(L39:P39) -> 1250000 | R39: GIAO TOI, C2
A40: 23 | B40: 18/12/2025 | C40: 4 | D40: HOA THAI | E40: BINH TAN | G40: 2027 | L40: 1100000 | Q40: =SUM(L40:P40) -> 1100000
...

Sheet HUNG
A1: ='[1]A VIEN'!A1:Q1 -> 2025年12销路运费
A2: CHI PHÍ VẬN CHUYỂN HÀNG NỘI ĐỊA
A3: ='[1]A VIEN'!A3:Q3 -> THÁNG 12 NĂM 2025
A4: NCC: ANH HƯNG - 2.5T
A5: STT 次序 | B5: Ngày xuất hàng 日期 | C5: Đơn xuất hàng 销货单 | D5: Khách hàng 客户 | E5: Địa chỉ KH 送货地址 | G5: SỐ LƯỢNG 重量 NET WEIGHT | K5: SỐ LƯỢNG 重量 (kg) GROSS WEIGHT | L5: PHÍ VẬN CHUYỂN 路运费 | N5: CHI PHÍ KHÁC (LẤY HÀNG VỀ/GIAO MẪU…) | P5: CHỞ PHẾ | Q5: THÀNH TIỀN 合计 | R5: GHI CHÚ
E6: NỘI THÀNH | F6: NGOẠI THÀNH | G6: MÀNG NHỰA | H6: ĐỊNH HÌNH
G7: KG | H7: PCS | I7: KG | L7: MÀNG NHỰA | M7: ĐỊNH HÌNH | N7: MÀNG NHỰA | O7: ĐỊNH HÌNH
A8: 1 | B8: 26/11/2025 | C8: 9 | D8: NPP THANH PHAT | E8: BINH TAN | H8: 77000 | I8: 462 | M8: 1100000 | Q8: =SUM(L8:P8) -> 1100000
A9: 2 | B9: 27/11/2025 | C9: 41 | D9: HAO PHAT | E9: BINH TAN | G9: 1020 | L9: 500000 | Q9: =SUM(L9:P10) -> 1200000 | R9: 2X
C10: 17+15 | D10: THE KY XANH | E10: TAN PHU | H10: 34300 | I10: 771.3999 | M10: 700000
A11: 3 | B11: 28/11/2025 | C11: 28 | D11: CHI YEN | E11: Q9 | H11: 105903 | I11: 1217.7015 | M11: 1100000 | Q11: =SUM(L11:P11) -> 1100000
A12: 4 | B12: 29/11/2025 | C12: 20+19 | D12: HANA | E12: TAN BINH | H12: 84400 | I12: 1197.2623 | M12: 1100000 | Q12: =SUM(L12:P12) -> 1100000
A13: 5 | B13: 01/12/2025 | C13: 9+55~57 | D13: PHU HOI | E13: Q9 | H13: 72800 | I13: 1053.4941 | M13: 1150000 | Q13: =SUM(L13:P13) -> 1150000 | R13: 2X
A14: 6 | B14: 02/12/2025 | C14: 32+54 | D14: PHU HOI | E14: Q9 | H14: =6000+88000 -> 94000 | I14: =98.5542+1411.2019 -> 1509.7561 | M14: 1100000 | Q14: =SUM(L14:P14) -> 1100000
A15: 7 | B15: 03/12/2025 | C15: 1 | D15: VIFON | E15: TAN PHU | H15: 320000 | I15: 1842.976 | M15: 1100000 | Q15: =SUM(L15:P15) -> 1100000
A16: 8 | B16: 04/12/2025 | C16: 17 | D16: ANH NGAN | E16: BINH TAN | H16: 227650 | I16: 615.8025 | M16: 1100000 | Q16: =SUM(L16:P16) -> 1100000
A17: 9 | B17: 04/12/2025 | C17: 14 | D17: ANH NGAN | E17: HOC MON | H17: 69530 | I17: 1324.9835 | M17: 950000 | Q17: =SUM(L17:P17) -> 950000 | R17: C2
A18: 10 | B18: 05/12/2025 | C18: 28 | D18: NPP THANH PHAT | E18: BINH TAN | H18: 160000 | I18: 500 | M18: 1100000 | O18: 300000 | Q18: =SUM(L18:P18) -> 1400000 | R18: GHÉ BÌNH TÂN LẤY 500KG PHỤ GIA VỀ (NGÂN)
A19: 11 | B19: 06/12/2025 | C19: 2 | D19: QUEEN PACK | E19: THU DUC | H19: 80000 | I19: 480 | M19: 1000000 | Q19: =SUM(L19:P19) -> 1000000
A20: 12 | B20: 06/12/2025 | C20: 30+32 | D20: ANH DINH | E20: TDM | H20: =54000+37660 -> 91660 | I20: =393.39+749.9692 -> 1143.3592 | M20: 550000 | Q20: =SUM(L20:P20) -> 550000
A21: 13 | B21: 07/12/2025 | C21: 2+3+9 | D21: ANH CONG | E21: Q8 | H21: =33000+41000 -> 74000 | I21: =666.6+672.9 -> 1339.5 | M21: 1150000 | O21: 60000 | Q21: =SUM(L21:P21) -> 1210000 | R21: VE CHANH
A22: 14 | B22: 08/12/2025 | C22: 7 | D22: ANH NGAN | E22: BINH TAN | H22: 122800 | I22: 1529.6871 | M22: 1100000 | Q22: =SUM(L22:P22) -> 1100000
A23: 15 | B23: 09/12/2025 | C23: 13 | D23: VIFON | E23: TAN PHU | H23: 320000 | I23: 1842.976 | M23: 1100000 | Q23: =SUM(L23:P23) -> 1100000
A24: 16 | B24: 10/12/2025 | C24: 6 | D24: BIOPLAS | E24: GO VAP | H24: 212960 | I24: 1269.8547 | M24: 1000000 | Q24: =SUM(L24:P24) -> 1000000
A25: 17 | B25: 10/12/2025 | C25: 26 | D25: QUEEN PACK | E25: THU DUC | H25: 59600 | I25: 796.2848 | M25: 950000 | Q25: =SUM(L25:P25) -> 950000 | R25: C2
A26: 18 | B26: 11/12/2025 | C26: 5 | D26: PLASACO | E26: TAN BINH | H26: 76000 | I26: 866.0206 | M26: 1150000 | Q26: =SUM(L26:P27) -> 1150000
C27: 33+28 | D27: NAM PHAM | E27: TAN PHU | H27: =4000+210000 -> 214000 | I27: =86.8+385.442 -> 472.242
A28: 19 | B28: 12/12/2025 | C28: 36+37 | D28: ANH NGAN | E28: BINH TAN | H28: 241800 | I28: 1019.2562 | M28: 1100000 | Q28: =SUM(L28:P28) -> 1100000
A29: 20 | B29: 13/12/2025 | C29: 12 | D29: ECOPAK | E29: BINH TAN | H29: 96000 | I29: 835.2 | M29: 1100000 | Q29: =SUM(L29:P29) -> 1100000
A30: 21 | B30: 14/12/2025 | C30: 29~33 | D30: GIA MINH | E30: BINH CHANH | H30: 85180 | I30: 1374.4191 | M30: 1150000 | Q30: =SUM(L30:P30) -> 1150000
A31: 22 | B31: 15/12/2025 | C31: 5 | D31: ECOPACK | E31: BINH TAN | H31: 96000 | I31: 851.9808 | M31: 1100000 | Q31: =SUM(L31:P31) -> 1100000
A32: 23 | B32: 15/12/2025 | C32: 14 | D32: ANH NGAN | E32: HOC MON | H32: 75300 | I32: 1425.462 | M32: 950000 | Q32: =SUM(L32:P32) -> 950000 | R32: C2
A33: 24 | B33: 16/12/2025 | C33: 2 | D33: VIFON | E33: TAN PHU | H33: 320000 | I33: 1842.976 | M33: 1100000 | Q33: =SUM(L33:P33) -> 1100000
A34: 25 | B34: 17/12/2025 | C34: 3 | D34: ECOPACK | E34: BINH TAN | H34: 96000 | I34: 851.9808 | M34: 1100000 | Q34: =SUM(L34:P34) -> 1100000
A35: 26 | B35: 17/12/2025 | C35: 4+50 | D35: TAN PHAT 2 | E35: DI AN | H35: =122400+51000 -> 173400 | I35: =732.564+561.9113 -> 1294.4753 | M35: 900000 | Q35: =SUM(L35:P35) -> 900000 | R35: C2
A36: 27 | B36: 18/12/2025 | C36: 27 | D36: ANH NGAN | E36: BINH TAN | H36: 126000 | I36: 1201.9236 | M36: 1100000 | Q36: =SUM(L36:P36) -> 1100000
A37: 28 | B37: 19/12/2025 | C37: 12 | D37: MASAN | E37: DI AN | H37: 106920 | I37: 1154.736 | M37: 950000 | Q37: =SUM(L37:P37) -> 950000
A38: 29 | B38: 19/12/2025 | C38: 42 | D38: AN VINH | E38: Q12 | H38: 43200 | I38: 680.4 | M38: 950000 | Q38: =SUM(L38:P38) -> 950000 | R38: C2
A39: 30 | B39: 20/12/2025 | C39: 52+41 | D39: CHI YEN | E39: Q9 | H39: =21600+510000 -> 531600 | I39: =129.276+714 -> 843.276 | M39: 1100000 | Q39: =SUM(L39:P39) -> 1100000
A40: 31 | B40: 20/12/2025 | C40: 42+43+46 | D40: PHU HOI | E40: BINH TAN | H40: =29200+1250 -> 30450 | I40: =787.3735+52.5 -> 839.8735 | M40: 1200000 | O40: 260000 | Q40: =SUM(L40:P41) -> 1520000 | R40: GIAO TOI, VE CHANH
...

Sheet HOANG
A1: ='[1]A VIEN'!A1:Q1 -> 2025年12销路运费
A2: CHI PHÍ VẬN CHUYỂN HÀNG NỘI ĐỊA
A3: ='[1]A VIEN'!A3:Q3 -> THÁNG 12 NĂM 2025
A4: NCC: TRỊNH VĂN HOÀNG - 4T-61K52908
A5: STT 次序 | B5: Ngày xuất hàng 日期 | C5: Đơn xuất hàng 销货单 | D5: Khách hàng 客户 | E5: Địa chỉ KH 送货地址 | G5: SỐ LƯỢNG 重量 NET WEIGHT | K5: SỐ LƯỢNG 重量 (kg) GROSS WEIGHT | L5: PHÍ VẬN CHUYỂN 路运费 | N5: CHI PHÍ KHÁC (LẤY HÀNG VỀ/GIAO MẪU…) | P5: CHỞ PHẾ | Q5: THÀNH TIỀN 合计 | R5: GHI CHÚ
E6: NỘI THÀNH | F6: NGOẠI THÀNH | G6: MÀNG NHỰA | H6: ĐỊNH HÌNH | J6: PHẾ LIỆU
G7: KG | H7: PCS | I7: KG | J7: KG | L7: MÀNG NHỰA | M7: ĐỊNH HÌNH | N7: MÀNG NHỰA | O7: ĐỊNH HÌNH
A8: 1 | B8: 26/11/2025 | C8: 43 | D8: ANH NGAN | F8: TDM | H8: 36400 | I8: 311.1606 | M8: 1260000 | Q8: =SUM(L8:P10) -> 1260000
C9: 8+7 | D9: C VAN-HN | F9: DI AN | H9: 42900 | I9: 1083.804
C10: 32 | D10: KOYO | F10: BEN CAT | H10: 32000 | I10: 518.4
A11: 2 | B11: 27/11/2025 | C11: 7 | D11: HIEP HUNG | F11: CU CHI | G11: 2040 | L11: 480000 | Q11: =SUM(L11:P12) -> 1280000
C12: 4 | D12: JOYFOOD | F12: HOC MON | H12: 100000 | I12: 850 | M12: 800000
A13: 3 | B13: 27/11/2025 | C13: 36 | D13: UGEN | F13: BINH TAN | H13: 142000 | I13: 1534.86 | M13: 1250000 | O13: 260000 | Q13: =SUM(L13:P13) -> 1510000 | R13: C2, GIAO TOI, VE CHANH
A14: 4 | B14: 28/11/2025 | C14: 36 | D14: KIEN XUONG | F14: DUC HOA | G14: 3000 | L14: 1630000 | Q14: =SUM(L14:P15) -> 1630000 | R14: 2X
C15: 20 | D15: TAN TIEN PT | F15: BINH CHANH | G15: 704
A16: 5 | B16: 29/11/2025 | C16: 44 | D16: BB KIEN NANG | F16: DUC HOA | H16: 100000 | I16: 920 | M16: 1450000 | Q16: =SUM(L16:P16) -> 1450000
A17: 6 | B17: 02/12/2025 | C17: 36 | D17: ANH NGAN | F17: NHON TRACH | H17: 160900 | I17: 2266.06 | M17: 1750000 | N17: 400000 | Q17: =SUM(L17:P17) -> 2150000 | R17: CHUYỂN PHẾ NIDEC VN TỪ X1=> AN PHÁT 1.3TAN
A18: 7 | B18: 03/12/2025 | C18: 8 | D18: KIEN XUONG | F18: DUC HOA | G18: 2000 | M18: 900000 | Q18: =SUM(L18:P19) -> 1530000
C19: 2 | D19: PHAM NGUYEN | F19: DUC HOA | H19: 60000 | I19: 422 | N19: 630000
A20: 8 | B20: 04/12/2025 | C20: 15+18 | D20: THIEN LONG | F20: LONG THANH | G20: =2740+1000 -> 3740 | M20: 1700000 | Q20: =SUM(L20:P21) -> 2030000
C21: 17 | D21: DAI TIEN | F21: TAN UYEN | H21: 122405 | I21: 732.564 | N21: 330000
A22: 9 | B22: 05/12/2025 | C22: 23 | D22: TH-FARM | F22: BINH CHANH | H22: 25532 | I22: 310.6316 | M22: 1260000 | Q22: =SUM(L22:P24) -> 1660000 | R22: 2X
C23: 21 | D23: TU PHUONG | F23: BINH CHANH | H23: 29500 | I23: 870.25
C24: 16 | D24: MINH PHUONG | F24: BINH CHANH | G24: 1000 | L24: 400000
A25: 10 | B25: 06/12/2025 | C25: 9 | D25: VINATRAY | F25: HOC MON | H25: 83200 | I25: 1551.86 | M25: 1200000 | Q25: =SUM(L25:P25) -> 1200000
A26: 11 | B26: 08/12/2025 | C26: 8 | D26: KOYO | F26: MP3 | H26: 50000 | I26: 375 | M26: 480000 | Q26: =SUM(L26:P27) -> 980000
C27: 12 | D27: COLGATE | F27: MP3 | G27: 1870 | L27: 500000
A28: 12 | B28: 08/12/2025 | C28: 3 | D28: DAI TIEN | F28: TAN UYEN | H28: 123600 | I28: 2311.8002 | M28: 850000 | Q28: =SUM(L28:P28) -> 850000 | R28: C2
A29: 13 | B29: 09/12/2025 | C29: 40 | D29: A PHUC | F29: DI AN | H29: 56000 | I29: 1597.19 | M29: 1180000 | Q29: =SUM(L29:P30) -> 1180000
C30: 30 | D30: C VAN-HN | F30: DI AN | H30: 14949 | I30: 554.7441
A31: 14 | B31: 10/12/2025 | C31: 27 | D31: P&G | F31: VSIP 2A | H31: 15000 | I31: 1489.11 | M31: 600000 | O31: 200000 | Q31: =SUM(L31:P31) -> 800000 | R31: + LƠ XE
A32: 15 | B32: 10/12/2025 | C32: 16 | D32: XUAN THAI THINH | F32: THU DUC | H32: 55300 | I32: 1447.93 | M32: 1230000 | Q32: =SUM(L32:P33) -> 1230000 | R32: C2
C33: 31 | D33: ANH NGAN | F33: HOC MON | H33: 61600 | I33: 965.7774
A34: 16 | B34: 12/12/2025 | C34: 20 | D34: DONG BAC VINA | F34: HOC MON | G34: 2216 | L34: 500000 | Q34: =SUM(L34:P35) -> 1280000
C35: 27 | D35: ANH NGAN | F35: HOC MON | H35: 40800 | I35: 885.36 | M35: 780000
A36: 17 | B36: 13/12/2025 | C36: 9 | D36: MINH PHUONG | F36: BINH CHANH | G36: 2390 | L36: 1340000 | Q36: =SUM(L36:P38) -> 1740000 | R36: GIAO 2 DIEM
C37: 28 | D37: HIEP HUNG | F37: CU CHI | G37: 1320
C38: 14+26 | D38: TAN DAI LONG | F38: BINH TAN | H38: =35000+5000 -> 40000 | I38: =369.3+112.5 -> 481.8 | M38: 400000
A39: 18 | B39: 14/12/2025 | C39: 42 | D39: ANH NGAN | F39: TAN UYEN | H39: 151960 | I39: 1427.1949 | M39: 900000 | Q39: =SUM(L39:P39) -> 900000
A40: 19 | B40: 15/12/2025 | C40: 10 | D40: HUNG THAO | F40: NHON TRACH | H40: 164800 | I40: 2395.3062 | J40: 1043 | M40: 1750000 | P40: =J40*400+80000 -> 497200 | Q40: =SUM(L40:P40) -> 2247200 | R40: LẤY PHẾ NIDEC VN
...

Sheet TUAN
A1: ='[1]A VIEN'!A1:Q1 -> 2025年12销路运费
A2: CHI PHÍ VẬN CHUYỂN HÀNG NỘI ĐỊA
A3: ='[1]A VIEN'!A3:Q3 -> THÁNG 12 NĂM 2025
A4: NCC: ANH TUẤN - 7T-61H09504
A5: STT 次序 | B5: Ngày xuất hàng 日期 | C5: Đơn xuất hàng 销货单 | D5: Khách hàng 客户 | E5: Địa chỉ KH 送货地址 | G5: SỐ LƯỢNG 重量 NET WEIGHT | K5: SỐ LƯỢNG 重量 (kg) GROSS WEIGHT | L5: PHÍ VẬN CHUYỂN 路运费 | N5: CHI PHÍ KHÁC (LẤY HÀNG VỀ/GIAO MẪU…) | P5: CHỞ PHẾ | Q5: THÀNH TIỀN 合计 | R5: GHI CHÚ
E6: NỘI THÀNH | F6: NGOẠI THÀNH | G6: MÀNG NHỰA | H6: ĐỊNH HÌNH | J6: PHẾ LIỆU
G7: KG | H7: PCS | I7: KG | J7: KG | L7: MÀNG NHỰA | M7: ĐỊNH HÌNH | N7: MÀNG NHỰA | O7: ĐỊNH HÌNH
A8: 1 | B8: 26/11/2025 | C8: 11 | D8: COLGATE | F8: MP3 | G8: 7020 | L8: 1250000 | Q8: =SUM(L8:P9) -> 1250000
C9: 12 | D9: ZHENG HUI | F9: MP1 | G9: 217
A10: 2 | B10: 27/11/2025 | C10: 5 | D10: KOYO | F10: MP3 | H10: 124200 | I10: 1776.06 | M10: 950000 | Q10: =SUM(L10:P10) -> 950000
A11: 3 | B11: 27/11/2025 | C11: 14 | D11: NAM TAY PHUONG | F11: Q12 | H11: 192000 | M11: 1350000 | O11: 675000 | Q11: =SUM(L11:P11) -> 2025000 | R11: TRẢ VỀ NGUYÊN XE HÀNG NG (THẢO), C2
A12: 4 | B12: 28/11/2025 | C12: 37 | D12: BB KIEN NANG | F12: DUC HOA | H12: 80000 | I12: 760 | M12: 1800000 | Q12: =SUM(L12:P13) -> 1800000
C13: 1+34 | D13: TUYEN HUNG PHU | F13: DUC HOA | H13: =110000+2000 -> 112000 | I13: =1245.2+22.1009 -> 1267.3009
A14: 5 | B14: 29/11/2025 | C14: 4 | D14: AN THAI | F14: DUC HOA | G14: 4320 | L14: 1850000 | Q14: =SUM(L14:P16) -> 1950000 | R14: 2X
C15: 3 | D15: DONG BAC VINA | F15: HOC MON | G15: 1020
C16: 29 | D16: UGEN | F16: BINH TAN | H16: 10000 | I16: 86.4 | M16: 100000
A17: 6 | B17: 01/12/2025 | C17: 1 | D17: KIEN XUONG | F17: DUC HOA | G17: 5860 | L17: 2000000 | Q17: =SUM(L17:P18) -> 2000000
C18: 14 | D18: MINH PHUONG | F18: BINH CHANH | G18: 920
A19: 7 | B19: 01/12/2025 | C19: 16 | D19: ZHENG HUI | F19: BEN CAT | G19: 3000 | L19: 850000 | Q19: =SUM(L19:P19) -> 850000
A20: 8 | B20: 02/12/2025 | C20: 53 | D20: NHU PHUC | F20: NHON TRACH | H20: 25000 | I20: 278.9687 | M20: 500000 | Q20: =SUM(L20:P22) -> 2400000 | R20: 2X
C21: 30 | D21: TSUKASA | F21: BINH AN, DN | H21: 72000 | I21: 284.72
C22: 5+11 | D22: THIEN LONG | F22: LONG THANH | G22: 5200 | L22: 1900000
A23: 9 | B23: 03/12/2025 | C23: 7 | D23: KIWORK | F23: THUAN AN | G23: 1315 | L23: 300000 | Q23: =SUM(L23:P24) -> 2000000
C24: 11+15 | D24: TAN PHAT | F24: DI AN | H24: =520010+50000 -> 570010 | I24: =728+300 -> 1028 | M24: 1200000 | N24: 500000 | R24: GHÉ LP LẤY 2TAN HÀNG NIDEC VỀ X2 (NGÂN)
A25: 10 | B25: 04/12/2025 | C25: 5 | D25: MASAN | F25: DI AN | H25: 66810 | I25: 592.9254 | N25: 1400000 | Q25: =SUM(L25:P25) -> 1400000
A26: 11 | B26: 05/12/2025 | C26: 34+13 | D26: COLGATE | F26: MP3 | G26: 7340 | L26: 950000 | Q26: =SUM(L26:P26) -> 950000
A27: 12 | B27: 05/12/2025 | C27: 38+37 | D27: TAN PHAT 2 | F27: DI AN | H27: 62600 | I27: 997.4448 | M27: 550000 | Q27: =SUM(L27:P28) -> 2106400
C28: 38+40 | D28: NIDEC VN | F28: Q9 | G28: 4000 | J28: 1391 | L28: 1000000 | P28: =J28*400 -> 556400 | R28: C2, LẤY PHẾ NIDEC VN
A29: 13 | B29: 06/12/2025 | C29: 8 | D29: C VAN-HN | F29: DI AN | H29: 58260 | I29: 1738.735 | M29: 1550000 | Q29: =SUM(L29:P30) -> 1550000 | R29: 2X
D30: COLORMATE | F30: TAN UYEN | H30: 83334 | I30: 2017
A31: 14 | B31: 08/12/2025 | C31: 25 | D31: AN THAI | F31: DUC HOA | G31: 6300 | L31: 1850000 | Q31: =SUM(L31:P31) -> 1850000
A32: 15 | B32: 09/12/2025 | C32: THI | D32: AMIBA | F32: VSIP 2A | G32: 6000 | L32: 800000 | Q32: =SUM(L32:P32) -> 800000 | R32: HANG GC
A33: 16 | B33: 09/12/2025 | C33: 32 | D33: NIDEC INS | F33: Q9 | G33: 5880 | J33: 650 | L33: 1600000 | P33: =J33*500 -> 325000 | Q33: =SUM(L33:P33) -> 1925000 | R33: LẤY PHẾ NIDEC INS, C2
A34: 17 | B34: 10/12/2025 | C34: 24 | D34: UKP | F34: TAN UYEN | G34: 5200 | L34: 1000000 | Q34: =SUM(L34:P34) -> 1000000
A35: 18 | B35: 10/12/2025 | C35: 30+31 | D35: NIDEC VN | F35: Q9 | G35: 4500 | L35: 1400000 | Q35: =SUM(L35:P35) -> 1400000
A36: 19 | B36: 11/12/2025 | C36: 13+15 | D36: MINH KHANG | F36: Q12 | H36: 591400 | I36: 2441.32 | M36: 1400000 | Q36: =SUM(L36:P36) -> 1400000
A37: 20 | B37: 12/12/2025 | C37: 1 | D37: TAN TIEN PT | F37: BINH CHANH | G37: 5632 | L37: 1600000 | Q37: =SUM(L37:P37) -> 1600000
A38: 21 | B38: 13/12/2025 | C38: 40 | D38: TAN PHAT 2 | F38: DI AN | H38: 151000 | I38: 1161.6324 | M38: 1400000 | Q38: =SUM(L38:P38) -> 1400000 | R38: LẤY 6T HÀNG GA ST VỀ -PHƯỚC
A39: 22 | B39: 14/12/2025 | C39: 1+2 | D39: LONG PHAT | F39: BINH CHANH | H39: 140500 | I39: 2406.325 | M39: 1600000 | Q39: =SUM(L39:P39) -> 1600000
A40: 23 | B40: 15/12/2025 | C40: 9 | D40: MEIZAN | F40: NHA BE | H40: 138240 | I40: 1336.7808 | M40: 1700000 | Q40: =SUM(L40:P40) -> 1700000
...

Sheet DANH
A1: ='[1]A VIEN'!A1:Q1 -> 2025年12销路运费
A2: CHI PHÍ VẬN CHUYỂN HÀNG NỘI ĐỊA
A3: ='[1]A VIEN'!A3:Q3 -> THÁNG 12 NĂM 2025
A4: NCC: ANH DANH - 10T
A5: STT 次序 | B5: Ngày xuất hàng 日期 | C5: Đơn xuất hàng 销货单 | D5: Khách hàng 客户 | E5: Địa chỉ KH 送货地址 | G5: SỐ LƯỢNG 重量 NET WEIGHT | K5: SỐ LƯỢNG 重量 (kg) GROSS WEIGHT | L5: PHÍ VẬN CHUYỂN 路运费 | N5: CHI PHÍ KHÁC (LẤY HÀNG VỀ/GIAO MẪU…) | P5: CHỞ PHẾ | Q5: THÀNH TIỀN 合计 | R5: GHI CHÚ
E6: NỘI THÀNH | F6: NGOẠI THÀNH | G6: MÀNG NHỰA | H6: ĐỊNH HÌNH | J6: PHẾ LIỆU
G7: KG | H7: PCS | I7: KG | J7: KG | L7: MÀNG NHỰA | M7: ĐỊNH HÌNH | N7: MÀNG NHỰA | O7: ĐỊNH HÌNH
A8: 1 | B8: 26/11/2025 | C8: 17+18 | D8: MINH KHANG | F8: Q12 | H8: 84000 | I8: 1701.4897 | M8: 2050000 | Q8: =SUM(L8:P9) -> 2050000
C9: 19+20 | D9: ANH HUNG | F9: BINH CHANH | H9: 193400 | I9: 1745.9166
A10: 2 | B10: 27/11/2025 | C10: 20 | D10: MASAN | F10: DI AN | H10: 109650 | I10: 973.1218 | M10: 1700000 | Q10: =SUM(L10:P10) -> 1700000
A11: 3 | B11: 27/11/2025 | C11: 12 | D11: VINATRAY | F11: HOC MON | H11: 100020 | I11: 2006.4201 | M11: 1700000 | Q11: =SUM(L11:P11) -> 1700000 | R11: C2
A12: 4 | B12: 28/11/2025 | C12: 16 | D12: MASAN | F12: DI AN | H12: 113730 | I12: 989.451 | M12: 1700000 | Q12: =SUM(L12:P12) -> 1700000
A13: 5 | B13: 29/11/2025 | D13: KIWORK | F13: THUAN AN | G13: 2066 | L13: 2250000 | Q13: =SUM(L13:P14) -> 2651600
D14: NIDEC VN | F14: Q9 | G14: 7500 | J14: 1004 | P14: =J14*400 -> 401600 | R14: LẤY PHẾ NIDEC VN
A15: 6 | B15: 02/12/2025 | C15: 6 | D15: MASAN | F15: DI AN | H15: 114240 | I15: 1013.8571 | M15: 1700000 | Q15: =SUM(L15:P15) -> 1700000
A16: 7 | B16: 02/12/2025 | C16: 39 | D16: NIDEC VN | F16: Q9 | G16: 3948 | J16: 1458 | L16: 1000000 | P16: =J16*400 -> 583200 | Q16: =SUM(L16:P17) -> 2433200 | R16: C2, LAY PHE NIDEC VN
C17: 21 | D17: TAO LUC | F17: TDM | H17: 620000 | I17: 1003 | M17: 850000
A18: 8 | B18: 03/12/2025 | C18: 25+24 | D18: THUAN THANH | F18: BINH TAN | H18: 204000 | I18: 2309.28 | M18: 1900000 | Q18: =SUM(L18:P19) -> 1900000
C19: 13 | D19: TAN DAI LONG | F19: BINH TAN | H19: 85200 | I19: 1092.656
A20: 9 | B20: 04/12/2025 | C20: 45+58 | D20: LONG PHAT | F20: BINH CHANH | H20: =182600+40000 -> 222600 | I20: =3629.981+442.0184 -> 4071.9994 | M20: 2000000 | Q20: =SUM(L20:P20) -> 2000000 | R20: 2X
A21: 10 | B21: 05/12/2025 | C21: 6 | D21: TAIXIN | F21: LONG THANH | H21: 270000 | I21: 2396.196 | M21: 2250000 | O21: =384*500 -> 192000 | Q21: =SUM(L21:P21) -> 2442000 | R21: LẤY 384PCS VỎ THÙNG VỀ
A22: 11 | B22: 06/12/2025 | C22: 6 | D22: TAIXIN | F22: LONG THANH | H22: 272000 | I22: 2366.4 | J22: 1002 | M22: 2250000 | P22: =J22*400 -> 400800 | Q22: =SUM(L22:P22) -> 2650800 | R22: LẤY PHẾ NIDEC VN
A23: 12 | B23: 08/12/2025 | C23: 5 | D23: TAN TIEN PT | F23: BINH CHANH | G23: 8800 | L23: 2200000 | N23: 1100000 | Q23: =SUM(L23:P23) -> 3300000 | R23: LẤY HÀNG TRẢ VỀ 8.5 TÂN
A24: 13 | B24: 09/12/2025 | C24: 2 | D24: LONG PHAT | F24: BINH CHANH | H24: 245800 | I24: 4282.8196 | M24: 1950000 | Q24: =SUM(L24:P24) -> 1950000
A25: 14 | B25: 10/12/2025 | C25: 4 | D25: JUM BO | F25: LONG KHANH | G25: 7467 | L25: 2300000 | Q25: =SUM(L25:P25) -> 2300000
A26: 15 | B26: 11/12/2025 | C26: 2 | D26: KIWORK | F26: THUAN AN | G26: 3000 | L26: 1950000 | Q26: =SUM(L26:P27) -> 2384400 | R26: 2X
C27: 14 | D27: NIDEC VN | F27: Q9 | G27: 4500 | J27: 1086 | P27: =J27*400 -> 434400 | R27: LẤY PHẾ NIDEC VN
A28: 16 | B28: 12/12/2025 | C28: 38+39 | D28: ANH PHUC | F28: DI AN | H28: 119480 | I28: 3502.9942 | M28: 1700000 | Q28: =SUM(L28:P28) -> 1700000
A29: 17 | B29: 13/12/2025 | C29: 18+15 | D29: LONG PHAT | F29: BINH CHANH | H29: =40000+665000 -> 705000 | I29: =328+3259.8 -> 3587.8 | M29: 2000000 | Q29: =SUM(L29:P29) -> 2000000 | R29: 2X
A30: 18 | B30: 15/12/2025 | C30: 25+ | D30: TAN TIEN PT | F30: BINH CHANH | G30: =2816+352 -> 3168 | L30: 2300000 | Q30: =SUM(L30:P31) -> 2300000 | R30: 2X
C31: 28 | D31: AN THAI | F31: DUC HOA | G31: 5323
A32: 19 | B32: 16/12/2025 | C32: 16+19 | D32: LONG PHAT | F32: BINH CHANH | H32: =86400+73000 -> 159400 | I32: 1634.0012 | M32: 1950000 | Q32: =SUM(L32:P32) -> 1950000
A33: 20 | B33: 17/12/2025 | C33: 6 | D33: TAIXIN | F33: LONG THANH | H33: 270000 | I33: 2396.196 | M33: 2250000 | Q33: =SUM(L33:P33) -> 2250000
A34: 21 | B34: 20/12/2025 | C34: 44 | D34: TAN VIET PHAT | F34: BIEN HOA | G34: 800 | L34: 1900000 | Q34: =SUM(L34:P35) -> 2305600
C35: 30+31 | D35: NIDEC VN | F35: Q9 | G35: 6500 | J35: 1014 | P35: =J35*400 -> 405600 | R35: LẤY PHẾ NIDEC VN
A36: 22 | B36: 23/12/2025 | C36: 14 | D36: VINATRAY | F36: HOC MON | H36: 130960 | I36: 2850.192 | M36: 1750000 | Q36: =SUM(L36:P36) -> 1750000
A37: 23 | B37: 23/12/2025 | C37: 34 | D37: FINTECHX | F37: BEN CAT | H37: 124200 | I37: 2484 | M37: 1100000 | Q37: =SUM(L37:P37) -> 1100000 | R37: C2
A38: 24 | B38: 24/12/2025 | C38: 10+11+12 | D38: LONG PHAT | F38: BINH CHANH | H38: 148100 | I38: 2874.8281 | M38: 2000000 | Q38: =SUM(L38:P38) -> 2000000 | R38: 2X
A39: 25 | B39: 25/12/2025 | C39: 7 | D39: TAIXIN | F39: LONG THANH | H39: 272000 | I39: 2413.9456 | M39: 2250000 | Q39: =SUM(L39:P39) -> 2250000
A40: TỔNG CỘNG | G40: =SUM(G8:G39) -> 53072 | H40: =SUM(H8:H39) -> 4563780 | I40: =SUM(I8:I39) -> 47696.564 | J40: =SUM(J8:J39) -> 5564 | K40: =SUM(K8:K39) -> 0 | L40: =SUM(L8:L39) -> 13900000 | M40: =SUM(M8:M39) -> 35050000 | N40: =SUM(N8:N39) -> 1100000 | ... Q40: =SUM(Q8:Q39) -> 52467600
...

Sheet TU 4T
A1: ='[1]A VIEN'!A1:Q1 -> 2025年12销路运费
A2: CHI PHÍ VẬN CHUYỂN HÀNG NỘI ĐỊA
A3: ='[1]A VIEN'!A3:Q3 -> THÁNG 12 NĂM 2025
A4: NCC: ĐINH TÚ 4T
A5: STT 次序 | B5: Ngày xuất hàng 日期 | C5: Đơn xuất hàng 销货单 | D5: Khách hàng 客户 | E5: Địa chỉ KH 送货地址 | G5: SỐ LƯỢNG 重量 NET WEIGHT | K5: SỐ LƯỢNG 重量 (kg) GROSS WEIGHT | L5: PHÍ VẬN CHUYỂN 路运费 | N5: CHI PHÍ KHÁC (LẤY HÀNG VỀ/GIAO MẪU…) | P5: CHỞ PHẾ | Q5: THÀNH TIỀN 合计 | R5: GHI CHÚ
E6: NỘI THÀNH | F6: NGOẠI THÀNH | G6: MÀNG NHỰA | H6: ĐỊNH HÌNH | J6: PHẾ LIỆU
G7: KG | H7: PCS | I7: KG | J7: KG | L7: MÀNG NHỰA | M7: ĐỊNH HÌNH | N7: MÀNG NHỰA | O7: ĐỊNH HÌNH
A8: 1 | B8: 26/11/2025 | C8: 5 | D8: DAI TIEN | F8: TAN UYEN | H8: 719000 | I8: 2958.57 | M8: 950000 | Q8: =SUM(L8:P8) -> 950000
A9: 2 | B9: 26/11/2025 | C9: 30 | D9: NIDEC VN | F9: Q9 | G9: 4500 | J9: 1138 | L9: 1350000 | P9: =J9*400 -> 455200 | Q9: =SUM(L9:P9) -> 1805200 | R9: C2, LẤY PHẾ NIDEC VN
A10: 3 | B10: 27/11/2025 | C10: 6 | D10: KOYO | F10: MP3 | H10: 28000 | I10: 453.6 | M10: 1030000 | Q10: =SUM(L10:P11) -> 1030000
C11: 42 | D11: ANH NGAN | F11: BEN CAT | H11: 530000 | I11: 940.4
A12: 4 | B12: 27/11/2025 | C12: 42 | D12: LONG PHAT | F12: BINH CHANH | H12: 138000 | I12: 2650.4222 | M12: 1450000 | Q12: =SUM(L12:P12) -> 1450000 | R12: C2
A13: 5 | B13: 28/11/2025 | C13: 12 | D13: VINATRAY | F13: HOC MON | H13: 136600 | I13: 1903.3328 | M13: 1300000 | Q13: =SUM(L13:P13) -> 1300000
A14: 6 | B14: 28/11/2025 | C14: 17 | D14: HIEP HUNG | F14: CU CHI | G14: 3780 | L14: 1200000 | Q14: =SUM(L14:P14) -> 1200000 | R14: C2
A15: 7 | B15: 29/11/2025 | C15: 39 | D15: BB KIEN NANG | F15: DUC HOA | H15: 114500 | I15: 1547.75 | M15: 1600000 | Q15: =SUM(L15:P15) -> 1600000
A16: 8 | B16: 30/11/2025 | C16: 51 | D16: ANH NGAN | F16: BINH CHANH | H16: 1030000 | I16: 1442 | M16: 1500000 | Q16: =SUM(L16:P16) -> 1500000
A17: 9 | B17: 01/12/2025 | C17: 20 | D17: NIDEC VN | F17: Q9 | G17: 4000 | J17: 1186 | L17: 1400000 | P17: =J17*400 -> 474400 | Q17: =SUM(L17:P17) -> 1874400 | R17: LẤY PHẾ NIDEC VN
A18: 10 | B18: 02/12/2025 | C18: 10 | D18: MAI THU | F18: VSIP 2A | H18: 138000 | I18: 828 | M18: 650000 | Q18: =SUM(L18:P18) -> 650000
A19: 11 | B19: 02/12/2025 | C19: 18 | D19: KWOOK VN | F19: DI AN | H19: 424400 | I19: 1570.28 | M19: 1200000 | Q19: =SUM(L19:P19) -> 1200000 | R19: C2
A20: 12 | B20: 03/12/2025 | C20: 13+14 | D20: MINH KHANG | F20: Q12 | H20: 168000 | I20: 2474.115 | M20: 1300000 | Q20: =SUM(L20:P20) -> 1300000
A21: 13 | B21: 04/12/2025 | C21: 1 | D21: STARPRINT | F21: BIEN HOA | H21: 20000 | I21: 1261.9 | M21: 1450000 | Q21: =SUM(L21:P21) -> 1450000
A22: 14 | B22: 04/12/2025 | C22: 33 | D22: NIDEC VN | F22: Q9 | G22: 4500 | J22: 1038 | L22: 1350000 | P22: =J22*400 -> 415200 | Q22: =SUM(L22:P22) -> 1765200 | R22: C2, LAY PHE NIDEC VN
A23: 15 | B23: 05/12/2025 | C23: 5 | D23: KIEN XUONG | F23: DUC HOA | G23: 2400 | L23: 850000 | Q23: =SUM(L23:P24) -> 1730000 | R23: 2X
C24: 37 | D24: SONG HUONG | F24: BINH CHANH | H24: 36000 | I24: 368.4 | M24: 880000
A25: 16 | B25: 06/12/2025 | C25: 3 | D25: ZHENG HUI | F25: BEN CAT | G25: 3000 | L25: 850000 | Q25: =SUM(L25:P25) -> 850000
A26: 17 | B26: 06/12/2025 | C26: 20 | D26: HUNG THAO | F26: NHON TRACH | H26: 282400 | I26: 2305.7175 | M26: 1900000 | O26: 200000 | Q26: =SUM(L26:P26) -> 2100000 | R26: C2, GIAO TOI
A27: 18 | B27: 08/12/2025 | C27: 10 | D27: C VAN-HN | F27: DI AN | H27: 6440 | I27: 282.716 | M27: 480000 | O27: 20000 | Q27: =SUM(L27:P28) -> 1932400 | R27: VE CHANH
C28: 17 | D28: NIDEC VN | F28: Q9 | G28: 3500 | J28: 1081 | L28: 1000000 | P28: =J28*400 -> 432400 | R28: LAY PHE NIDEC VN
A29: 19 | B29: 09/12/2025 | C29: 25 | D29: NIDEC VN | F29: Q9 | G29: 4100 | J29: 1178 | L29: 1450000 | P29: =J29*400 -> 471200 | Q29: =SUM(L29:P29) -> 1921200 | R29: 2X, LAY PHE NIDEC VN
A30: 20 | B30: 10/12/2025 | C30: 19 | D30: ANH NGAN | F30: NHON TRACH | H30: 214200 | I30: 2238.6172 | M30: 1950000 | Q30: =SUM(L30:P30) -> 1950000
A31: 21 | B31: 11/12/2025 | C31: 11 | D31: MINH PHUONG | F31: BINH CHANH | G31: 3189 | L31: 1000000 | N31: 80000 | Q31: =SUM(L31:P32) -> 1660000 | R31: GIAO MAU QUOC THANG- BINH CHANH (HANH)
C32: 7 | D32: PHAM NGUYEN | F32: BINH TAN | H32: 80400 | I32: 589.3122 | M32: 580000
A33: 22 | B33: 12/12/2025 | C33: 19 | D33: AN THAI | F33: DUC HOA | G33: 4162 | L33: 1600000 | N33: 300000 | Q33: =SUM(L33:P33) -> 1900000 | R33: GHẾ NGOC ANH LẤY 300PCS ỐNG GIẤY VỀ
A34: 23 | B34: 13/12/2025 | C34: 13 | D34: MASAN | F34: DI AN | H34: 52050 | I34: 616.95 | M34: 1250000 | N34: 300000 | O34: 200000 | Q34: =SUM(L34:P34) -> 1750000 | R34: GHÉ HƯNG THINH-TAN UYÊN LẤY MÚT XỐP + GHÉ NGOC ANH LẤY 200PCS ỐNG GIẤY VỀ
A35: 24 | B35: 15/12/2025 | C35: 17 | D35: HIEP HUNG | F35: CU CHI | G35: 2040 | L35: 600000 | Q35: =SUM(L35:P36) -> 1380000
C36: 4 | D36: JOYFOOD | F36: HOC MON | H36: 100000 | I36: 850 | M36: 780000
A37: 25 | B37: 16/12/2025 | C37: 26+27 | D37: TH-FARM | F37: THU DUC | H37: 24982 | I37: 588.9838 | M37: 1510000 | Q37: =SUM(L37:P39) -> 1510000 | R37: 2X
C38: 11+12 | D38: THU PHUONG | F38: Q12 | H38: 50000 | I38: 300
C39: 42 | D39: PHONG THUY | F39: THUAN AN | H39: 36800 | I39: 496.8
A40: 26 | B40: 16/12/2025 | C40: 56+55+59 | D40: NIDEC VN | F40: Q9 | G40: 3080 | L40: 1150000 | Q40: =SUM(L40:P40) -> 1150000 | R40: C2
...

Sheet HUU
A1: ='[1]A VIEN'!A1:Q1 -> 2025年12销路运费
A2: CHI PHÍ VẬN CHUYỂN HÀNG NỘI ĐỊA
A3: ='[1]A VIEN'!A3:Q3 -> THÁNG 12 NĂM 2025
A4: NCC: NGUYỄN TRỌNG HỮU - 8T-61C42819
A5: STT 次序 | B5: Ngày xuất hàng 日期 | C5: Đơn xuất hàng 销货单 | D5: Khách hàng 客户 | E5: Địa chỉ KH 送货地址 | G5: SỐ LƯỢNG 重量 NET WEIGHT | K5: SỐ LƯỢNG 重量 (kg) GROSS WEIGHT | L5: PHÍ VẬN CHUYỂN 路运费 | N5: CHI PHÍ KHÁC (LẤY HÀNG VỀ/GIAO MẪU…) | P5: CHỞ PHẾ | Q5: THÀNH TIỀN 合计 | R5: GHI CHÚ
E6: NỘI THÀNH | F6: NGOẠI THÀNH | G6: MÀNG NHỰA | H6: ĐỊNH HÌNH | J6: PHẾ LIỆU
G7: KG | H7: PCS | I7: KG | J7: KG | L7: MÀNG NHỰA | M7: ĐỊNH HÌNH | N7: MÀNG NHỰA | O7: ĐỊNH HÌNH
A8: 1 | B8: 26/11/2025 | C8: 28+29 | D8: LONG PHAT | F8: BINH CHANH | H8: 369500 | I8: 5219.0781 | M8: 2150000 | Q8: =SUM(L8:P8) -> 2150000 | R8: 2X
A9: 2 | B9: 27/11/2025 | C9: 8 | D9: TAIXIN | F9: LONG THANH | H9: 256000 | M9: 2450000 | O9: 1225000 | Q9: =SUM(L9:P9) -> 3675000 | R9: TRẢ VỀ NGUYÊN XE HÀNG NG (THẢO)
A10: 2 | B10: 27/11/2025 | C10: 38+39+40 | D10: HOANG ANH | F10: BEN LUC | H10: 406800 | I10: 4770.738 | M10: 2600000 | O10: 200000 | Q10: =SUM(L10:P10) -> 2800000 | R10: C2, GIAO TOI
A11: 3 | B11: 28/11/2025 | C11: 11 | D11: VINATRAY | F11: HOC MON | H11: 134400 | I11: 2782.08 | M11: 1900000 | Q11: =SUM(L11:P11) -> 1900000
A12: 4 | B12: 29/11/2025 | C12: 11+13+14 | D12: LONG PHAT | F12: BINH CHANH | H12: 107520 | I12: 2737.0349 | M12: 2150000 | Q12: =SUM(L12:P12) -> 2150000 | R12: 2X
A13: 5 | B13: 30/11/2025 | C13: 41+5+2+1 | D13: VAN-BT | F13: BINH THUAN | H13: 600300 | I13: 4042.5803 | M13: 2700000 | Q13: =SUM(L13:P13) -> 2700000
A14: 6 | B14: 01/12/2025 | C14: 4+5 | D14: VINATRAY | F14: HOC MON | H14: 229100 | I14: 3683.4351 | M14: 1950000 | Q14: =SUM(L14:P14) -> 1950000 | R14: 2X
A15: 7 | B15: 02/12/2025 | C15: 3 | D15: TAIXIN | F15: LONG THANH | H15: 256000 | M15: 2450000 | O15: 700000 | Q15: =SUM(L15:P15) -> 3150000 | R15: TRẢ 56T HÀNG NG. 1/11
A16: 8 | B16: 03/12/2025 | C16: 42+43 | D16: LONG PHAT | F16: BINH CHANH | H16: 240700 | I16: 4707.8681 | M16: 2100000 | Q16: =SUM(L16:P16) -> 2100000
A17: 9 | B17: 04/12/2025 | C17: 27~33 | D17: HOANG ANH | F17: BEN LUC | H17: 350000 | I17: 5235.0522 | M17: 2650000 | Q17: =SUM(L17:P17) -> 2650000
A18: 10 | B18: 05/12/2025 | C18: 24+25 | D18: VINATRAY | F18: HOC MON | H18: 140480 | I18: 2143.136 | M18: 1900000 | Q18: =SUM(L18:P18) -> 1900000
A19: 11 | B19: 06/12/2025 | C19: 52 | D19: COLORMATE | F19: TAN UYEN | H19: 116666 | I19: 2823 | M19: 1450000 | Q19: =SUM(L19:P19) -> 1450000
A20: 12 | B20: 06/12/2025 | C20: 13+14+15 | D20: NIDEC VN | F20: Q9 | G20: 9000 | L20: 2100000 | Q20: =SUM(L20:P20) -> 2100000 | R20: C2
A21: 13 | B21: 06/12/2025 | C21: 7~13 | D21: HOANG ANH | F21: BEN LUC | H21: 1323000 | I21: 3938.5172 | M21: 2600000 | O21: 200000 | Q21: =SUM(L21:P21) -> 2800000 | R21: C3, GIAO TOI
A22: 14 | B22: 08/12/2025 | C22: 13 | D22: TAIXIN | F22: LONG THANH | H22: 227000 | I22: 2014.5796 | M22: 2450000 | Q22: =SUM(L22:P22) -> 2450000
A23: 15 | B23: 09/12/2025 | C23: 18 | D23: HOANG ANH | F23: BEN LUC | H23: 1315800 | I23: 2256.61 | M23: 2650000 | Q23: =SUM(L23:P23) -> 2650000
A24: 16 | B24: 10/12/2025 | C24: 17 | D24: COLGATE | F24: MP3 | G24: 7930 | L24: 950000 | Q24: =SUM(L24:P24) -> 950000
A25: 17 | B25: 10/12/2025 | C25: 23 | D25: HOANG ANH | F25: BEN LUC | H25: 237000 | I25: 1422 | M25: 2600000 | Q25: =SUM(L25:P25) -> 2600000 | R25: C2
A26: 18 | B26: 11/12/2025 | C26: 24+23 | D26: VINATRAY | F26: HOC MON | H26: 173200 | I26: 3406.7419 | M26: 1950000 | Q26: =SUM(L26:P26) -> 1950000 | R26: 2X
A27: 19 | B27: 12/12/2025 | C27: 4 | D27: VINATRAY | F27: HOC MON | H27: 134400 | I27: 2782.08 | M27: 1900000 | Q27: =SUM(L27:P27) -> 1900000
A28: 20 | B28: 12/12/2025 | C28: 28~35 | D28: HOANG ANH | F28: BEN LUC | H28: 297200 | I28: 3243.4695 | M28: 2650000 | Q28: =SUM(L28:P28) -> 2650000 | R28: C2, 2X
A29: 21 | B29: 13/12/2025 | C29: 37+38 | D29: NIDEC VN | F29: Q9 | G29: 6500 | J29: 2207 | L29: 1650000 | P29: =J29*400 -> 882800 | Q29: =SUM(L29:P29) -> 2532800 | R29: LẤY PHẾ NIDEC VN
A30: 22 | B30: 15/12/2025 | C30: 26+27 | D30: PHONG THUY | F30: THUAN AN | H30: 56200 | I30: 886.8 | M30: 2000000 | Q30: =SUM(L30:P31) -> 2000000
C31: 11+12 | D31: MINH KHANG | F31: Q12 | H31: 265200 | I31: 3460.3092
A32: 23 | B32: 15/12/2025 | C32: 35~41 | D32: HOANG ANH | F32: BEN LUC | H32: 300600 | I32: 4826.5923 | M32: 2600000 | O32: 200000 | Q32: =SUM(L32:P32) -> 2800000 | R32: C2, GIAO TOI
A33: 24 | B33: 16/12/2025 | C33: 30 | D33: HUNUFA | F33: DUC HOA | H33: 240000 | I33: 4080.6648 | M33: 2150000 | Q33: =SUM(L33:P33) -> 2150000
A34: 25 | B34: 17/12/2025 | C34: 22+23 | D34: VINATRAY | F34: HOC MON | H34: 207060 | I34: 4266.6782 | M34: 1950000 | Q34: =SUM(L34:P34) -> 1950000 | R34: 2X
A35: 26 | B35: 18/12/2025 | C35: 10 | D35: TAIXIN | F35: LONG THANH | H35: 320000 | I35: 2839.936 | M35: 2450000 | O35: =259*500 -> 129500 | Q35: =SUM(L35:P35) -> 2579500 | R35: LẤY 259PCS VỎ THÙNG VỀ
A36: 27 | B36: 19/12/2025 | C36: 14 | D36: TAIXIN | F36: LONG THANH | H36: 320000 | I36: 2839.936 | M36: 2450000 | Q36: =SUM(L36:P36) -> 2450000
A37: 28 | B37: 20/12/2025 | C37: 11+12 | D37: VINATRAY | F37: HOC MON | H37: 137440 | I37: 3325.008 | M37: 1950000 | Q37: =SUM(L37:P37) -> 1950000 | R37: 2X
A38: 29 | B38: 22/12/2025 | C38: 31~38 | D38: HOANG ANH | F38: BEN LUC | H38: 324250 | I38: 4709.415 | M38: 2600000 | Q38: =SUM(L38:P38) -> 2600000 | R38: C2
A39: 30 | B39: 23/12/2025 | C39: 7~13 | D39: HOANG ANH | F39: BEN LUC | H39: 428800 | I39: 4834.116 | M39: 2650000 | Q39: =SUM(L39:P39) -> 2650000
A40: 31 | B40: 24/12/2025 | C40: 6+8 | D40: HANH MINH KHOI | F40: CAN GIUOC | G40: 5000 | H40: 24600 | I40: 516.6 | L40: 1000000 | M40: 1750000 | Q40: =SUM(L40:P41) -> 2750000
...

Sheet TH
A1: STT | B1: XE | C1: PHÍ VC CHƯA VAT | D1: VAT 8% | E1: THÀNH TIỀN
A2: 1 | B2: HIẾU | C2: =HIEU!Q57 -> 41424000 | D2: =C2*8% -> 3313920 | E2: =C2+D2 -> 44737920
A3: 2 | B3: NAM | C3: =NAM!Q52 -> 39185000 | D3: =C3*8% -> 3134800 | E3: =C3+D3 -> 42319800
A4: 3 | B4: HƯNG | C4: =HUNG!Q50 -> 40430000 | D4: =C4*8% -> 3234400 | E4: =C4+D4 -> 43664400
A5: 4 | B5: HOÀNG | C5: =HOANG!Q59 -> 41366200 | D5: =C5*8% -> 3309296 | E5: =C5+D5 -> 44675496
A6: 5 | B6: TUẤN | C6: =TUAN!Q64 -> 55726400 | D6: =C6*8% -> 4458112 | E6: =C6+D6 -> 60184512
A7: 6 | B7: TÚ 4T | C7: ='TU 4T'!Q55 -> 56061200 | D7: =C7*8% -> 4484896 | E7: =C7+D7 -> 60546096
A8: 7 | B8: HỮU | C8: =HUU!Q44 -> 76587300 | D8: =C8*8% -> 6126984 | E8: =C8+D8 -> 82714284
A9: 8 | B9: DANH | C9: =DANH!Q40 -> 52467600 | D9: =C9*8% -> 4197408 | E9: =C9+D9 -> 56665008
A10: TỔNG | C10: =SUM(C2:C9) -> 403247700 | D10: =SUM(D2:D9) -> 32259816 | E10: =SUM(E2:E9) -> 435507516
