Workbook

Sheet A CHAU
B2: BÁO CÁO TỜ KHAI XUẤT NHẬP KHẨU
J3: Chi phí làm hàng
A4: STT | B4: Số TK | C4: Ngày ĐK | D4: Tạo Job | E4: Note | F4: Ngày tạm ứmg | G4: 20' | H4: 40' | I4: LCL / CONT NO. | J4: Nâng/hạ/ CSHT | K4: Chi phí làm hàng | L4: LCC/ CO | M4: Chi hộ TM | N4: Estimate tạm ứng | O4: Vận đơn/ BOOKING | Q4: Ngày vận đơn | R4: Số lượng kiện | S4: Tổng trọng lượng hàng (Gross) | T4: Địa điểm lưu kho | U4: Tên địa điểm lưu kho | V4: Mã phương tiện vận chuyển | W4: Tên phương tiện vận chuyển | X4: Ngày đến | Y4: Mã địa điểm dỡ hàng | Z4: Tên địa điểm dỡ hàng | AA4: Mã địa điểm xếp hàng | AB4: Tên địa điểm xếp hàng | AC4: Số lượng cont | AD4: Số giấy phép | AE4: Số hóa đơn TM | AF4: Ngày HĐTM | AG4: Tổng trị giá hóa đơn | AH4: Phương thức thanh toán | AI4: Điều kiện giá hóa đơn | AJ4: Ng.Tệ hóa đơn | AK4: Tỷ giá VNĐ | AL4: Phí BH | AM4: Phí VC | AN4: Người nộp thuế | AO4: Trị giá KB | AP4: Tổng trị giá TT | AQ4: Tổng tiền thuế | AR4: Khoản điều chỉnh 1 | AS4: Khoản điều chỉnh 2 | AT4: Khoản điều chỉnh 3 | AU4: Khoản điều chỉnh 4 | AV4: Khoản điều chỉnh 5 | AW4: Lý do đề nghị BP | AX4: Mã ngân hàng trả thuế | AY4: Tên ngân hàng trả thuế | AZ4: Năm phát hành hạn mức | BA4: Ký hiệu CT hạn mức | BB4: Số CT hạn mức | BC4: Mã xđ thời hạn nộp thuế | BD4: Mã ngân hàng bảo lãnh | BE4: Tên ngân hàng bảo lãnh | BF4: Năm phát hành bảo lãnh | BG4: Ký hiệu CT bảo lãnh | BH4: Số hiệu CT bảo lãnh | BI4: Số hợp đồng | BJ4: Ngày hợp đồng | BK4: Ngày HHHĐ | BL4: Trạng thái | BM4: Phân luồng | BN4: Ngày thông quan | BO4: Tổng thuế XNK | BP4: Tổng Thuế TV | BQ4: Số tiền miễn thuế XNK | BR4: Tổng thuế PBĐX | BS4: Tổng thuế TTĐB | BT4: Tổng thuế MT | BU4: Tổng thuế VAT | BV4: Tổng lượng hàng | BW4: Số hồ sơ TK | BX4: Ghi chú | BY4: Số điện thoại | BZ4: Mã doanh nghiệp | CA4: Tên doanh nghiệp | CB4: Mã phân loại khai trị giá | CC4: Số hợp đồng xuất khẩu | CD4: Số Record | CE4: Nhà cung cấp | CF4: Số chứng từ thanh toán | CG4: Ngày chứng từ thanh toán | CH4: Mã tiền tệ phí bảo hiểm | CI4: Mã tiền tệ phí vận chuyển | CJ4: Địa chỉ đối tác 1 | CK4: Địa chỉ đối tác 2 | CL4: Địa chỉ đối tác 3 | CM4: Địa chỉ đối tác 4 | CN4: Ký hiệu và số bao bì | CO4: Chi tiết khai trị giá
A5: 1 | B5: 305258522500 | C5: 44930 | D5: KGN-23010881 | F5: 44963 | G5: 1 | I5: TEMU0499180 | J5: =(G5*$C$255)+(G5*$C$256)+(H5*$D$255+H5*$D$256)+(G5*$C$258+H5*$D$258) -> 1300000 | K5: =SUM(G5:I5)*250000 -> 250000 | L5: 300000 | N5: =+SUM(J5:M5) -> 1850000 | O5: 7242946470 | R5: 790 | W5: OREA 033N | BM5: XANH
A6: 2 | B6: 305263342920 | C6: 44931 | D6: KGN-23010890 | F6: 44963 | H6: 1 | I6: HMMU6455630 | J6: =(G6*$C$255)+(G6*$C$256)+(H6*$D$255+H6*$D$256)+(G6*$C$258+H6*$D$258) -> 2000000 | K6: =SUM(G6:I6)*250000 -> 250000 | L6: 300000 | N6: =+SUM(J6:M6) -> 2550000 | O6: SGNE95488800 | R6: 1600 | W6: ONE CYGNUS 013W | BM6: XANH
A7: 3 | B7: 305262991520 | C7: 44931 | D7: KGN-23010900 | F7: 44963 | G7: 1 | I7: CULU1924155 | J7: =(G7*$C$255)+(G7*$C$256)+(H7*$D$255+H7*$D$256)+(G7*$C$258+H7*$D$258) -> 1300000 | K7: =SUM(G7:I7)*250000 -> 250000 | L7: 300000 | N7: =+SUM(J7:M7) -> 1850000 | O7: CULVSGN2300006 | R7: 200 | W7: ZHONG LIAN SHAN TOU 2249N | BM7: XANH
A8: 4 | B8: 105204164550 | C8: 44931 | D8: KGN-23010127 | F8: 44963 | G8: 5 | I8: EGHU3209614 EITU0601582 EITU0611847 EITU3020621 EITU3088088 | J8: =(G8*$C$255)+(G8*$C$256)+(H8*$D$255+H8*$D$256)+(G8*$C$258+H8*$D$258) -> 6500000 | K8: =SUM(G8:I8)*250000 -> 1250000 | N8: =+SUM(J8:M8) -> 7750000 | O8: EGLV091230734256 | R8: 5 | BM8: VÀNG
A9: 5 | B9: 105204217530 | C9: 44932 | D9: KGN-23010147 | F9: 44963 | H9: 3 | I9: CMAU4185078 CMAU6460646 CMAU6971780 | J9: =(G9*$C$255)+(G9*$C$256)+(H9*$D$255+H9*$D$256)+(G9*$C$258+H9*$D$258) -> 6000000 | K9: =SUM(G9:I9)*250000 -> 750000 | N9: =+SUM(J9:M9) -> 6750000 | O9: XDQD906107 | R9: 3300 | BM9: VÀNG
A10: 6 | B10: 105210601050 | C10: 44935 | D10: KGN-23010636 | F10: 13/01/2023 | I10: AIR | J10: =(G10*$C$255)+(G10*$C$256)+(H10*$D$255+H10*$D$256)+(G10*$C$258+H10*$D$258) -> 0 | K10: =SUM(G10:I10)*250000 -> 0 | N10: =+SUM(J10:M10) -> 0 | O10: 625044315044 | R10: 1 | BM10: VÀNG
A11: 7 | B11: 105216259630 | C11: 44936 | D11: KGN-23010438 | F11: 13/01/2023 | H11: 4 | I11: WHSU4010385 WHSU4014122 WHSU4021060 WHSU4061989 | J11: =(G11*$C$255)+(G11*$C$256)+(H11*$D$255+H11*$D$256)+(G11*$C$258+H11*$D$258) -> 8000000 | K11: =SUM(G11:I11)*250000 -> 1000000 | N11: =+SUM(J11:M11) -> 9000000 | O11: 046CX04159 | R11: 160 | BM11: VÀNG
A12: 8 | B12: 105214353860 | C12: 44936 | D12: KGN-23010634 | F12: 13/01/2023 | H12: 3 | I12: TRHU4201790 BMOU5842873 CSNU8035111 | J12: =(G12*$C$255)+(G12*$C$256)+(H12*$D$255+H12*$D$256)+(G12*$C$258+H12*$D$258) -> 6000000 | K12: =SUM(G12:I12)*250000 -> 750000 | N12: =+SUM(J12:M12) -> 6750000 | O12: TAOHCM2479JHL12 | R12: 3300 | BM12: ĐỎ
A13: 9 | B13: 305274320100 | C13: 44936 | D13: KGN-23010547 | F13: 13/01/2023 | H13: 1 | I13: OBLU8811520 | J13: =(G13*$C$255)+(G13*$C$256)+(H13*$D$255+H13*$D$256)+(G13*$C$258+H13*$D$258) -> 2000000 | K13: =SUM(G13:I13)*250000 -> 250000 | L13: 300000 | N13: =+SUM(J13:M13) -> 2550000 | O13: O22120116 | R13: 1120 | BM13: XANH
A14: 10 | B14: 305280758550 | C14: 44938 | D14: KGN-23010635 | F14: 13/01/2023 | H14: 2 | I14: OOCU8561204 FFAU3543128 | J14: =(G14*$C$255)+(G14*$C$256)+(H14*$D$255+H14*$D$256)+(G14*$C$258+H14*$D$258) -> 4000000 | K14: =SUM(G14:I14)*250000 -> 500000 | L14: 300000 | N14: =+SUM(J14:M14) -> 4800000 | O14: 2712750210 | R14: 40 | BM14: XANH
A15: 11 | B15: 105216212840 | C15: 44942 | D15: KGN-23010421 | F15: 13/01/2023 | I15: LCL | J15: =(G15*$C$255)+(G15*$C$256)+(H15*$D$255+H15*$D$256)+(G15*$C$258+H15*$D$258) -> 0 | K15: =SUM(G15:I15)*250000 -> 0 | N15: =+SUM(J15:M15) -> 0 | O15: VEJA18879 | R15: 6 | BM15: VÀNG
A16: 12 | B16: 105216070740 | C16: 44942 | D16: KGN-23010419 | F16: 13/01/2023 | I16: LCL | J16: =(G16*$C$255)+(G16*$C$256)+(H16*$D$255+H16*$D$256)+(G16*$C$258+H16*$D$258) -> 0 | K16: =SUM(G16:I16)*250000 -> 0 | N16: =+SUM(J16:M16) -> 0 | O16: VEJA18885 | R16: 6 | BM16: VÀNG
A17: 13 | B17: 105216603700 | C17: 44942 | D17: KGN-23010475 | F17: 13/01/2023 | H17: 3 | I17: CMAU7849817 CXDU1822749 SEKU5794524 | J17: =(G17*$C$255)+(G17*$C$256)+(H17*$D$255+H17*$D$256)+(G17*$C$258+H17*$D$258) -> 6000000 | K17: =SUM(G17:I17)*250000 -> 750000 | N17: =+SUM(J17:M17) -> 6750000 | O17: XDQD906109 | R17: 3300 | BM17: VÀNG
A18: 14 | B18: 305298946760 | C18: 28/01/2023 | D18: KGN-23011084 | F18: 44963 | G18: 1 | I18: TWCU2149130 | J18: =(G18*$C$255)+(G18*$C$256)+(H18*$D$255+H18*$D$256)+(G18*$C$258+H18*$D$258) -> 1300000 | K18: =SUM(G18:I18)*250000 -> 250000 | L18: 300000 | N18: =+SUM(J18:M18) -> 1850000 | O18: JJS230010000253 | R18: 280 | BM18: XANH
A19: 15 | B19: 305299496300 | C19: 30/01/2023 | D19: KGN-23011083 | F19: 44963 | H19: 2 | I19: BSIU9382431 SEGU6915605 | J19: =(G19*$C$255)+(G19*$C$256)+(H19*$D$255+H19*$D$256)+(G19*$C$258+H19*$D$258) -> 4000000 | K19: =SUM(G19:I19)*250000 -> 500000 | L19: 300000 | N19: =+SUM(J19:M19) -> 4800000 | O19: 2712927350 | R19: 72 | BM19: XANH
A20: 16 | B20: 105237755010 | C20: 30/01/2023 | D20: KGN-23010991 | F20: 44963 | G20: 3 | I20: BHCU3233988 IAAU2827590 IAAU2872943 | J20: =(G20*$C$255)+(G20*$C$256)+(H20*$D$255+H20*$D$256)+(G20*$C$258+H20*$D$258) -> 3900000 | K20: =SUM(G20:I20)*250000 -> 750000 | N20: =+SUM(J20:M20) -> 4650000 | O20: A17CX12100 | R20: 3 | BM20: ĐỎ
A21: 17 | B21: 305303984920 | C21: 44928 | D21: KGN-23020023 | E21: KHAI TK + THANH LÝ | F21: 44963 | H21: 1 | I21: TRIU8095638 | J21: =(G21*$C$255)+(G21*$C$256)+(H21*$D$255+H21*$D$256)+(G21*$C$258+H21*$D$258) -> 2000000 | K21: =SUM(G21:I21)*250000 -> 250000 | L21: 300000 | N21: =+SUM(J21:M21) -> 2550000 | O21: HASLS21221201107 | R21: 28 | BM21: XANH
A22: 18 | B22: VẬN CHUYỂN NỘI ĐỊA | C22: 44932 | D22: KGN-23020104 | N22: =+SUM(J22:M22) -> 0
B23: THÁNG 02/2023
A24: 1 | B24: 105255211500 | C24: 44964 | D24: KGN-23020271 | F24: 16/02/23 | G24: AIR | N24: =+SUM(J24:M24) -> 0 | O24: 1Z6W7881D958280958 | R24: 1 | BM24: VÀNG | CP24: N
A25: =+A24+1 -> 2 | B25: 105255551550 | C25: 44964 | D25: KGN-23020272 | F25: 16/02/23 | G25: AIR | N25: =+SUM(J25:M25) -> 0 | O25: 1Z6W7881D958048147 | R25: 1 | BM25: VÀNG | CP25: N
A26: =+A25+1 -> 3 | B26: 305314148330 | C26: 44964 | D26: KGN-23020273 | F26: 16/02/23 | G26: LCL | J26: =(G26*$C$255)+(G26*$C$256)+(H26*$D$255+H26*$D$256)+(G26*$C$258+H26*$D$258) -> #VALUE! | K26: =SUM(G26:I26)*250000 -> 0 | L26: 300000 | N26: =+SUM(J26:M26) -> #VALUE! | O26: TMC23020574SIN | R26: 2 | BM26: VÀNG | CP26: X
A27: =+A26+1 -> 4 | B27: 305314199210 | C27: 44964 | D27: KGN-23020274 | F27: 16/02/23 | H27: 2 | I27: WHSU5558820 WHSU6517213 | J27: =(G27*$C$255)+(G27*$C$256)+(H27*$D$255+H27*$D$256)+(G27*$C$258+H27*$D$258) -> 4000000 | K27: =SUM(G27:I27)*250000 -> 500000 | L27: 300000 | N27: =+SUM(J27:M27) -> 4800000 | O27: 039DX02312 | R27: 72 | BM27: XANH | CP27: X
A28: =+A27+1 -> 5 | B28: 305314463660 | C28: 44964 | D28: KGN-23020278 | F28: 16/02/23 | H28: 1 | I28: HLBU2871720 | J28: =(G28*$C$255)+(G28*$C$256)+(H28*$D$255+H28*$D$256)+(G28*$C$258+H28*$D$258) -> 2000000 | K28: =SUM(G28:I28)*250000 -> 250000 | L28: 300000 | N28: =+SUM(J28:M28) -> 2550000 | O28: HLCUSGN230216610 | R28: 600 | BM28: XANH | CP28: X
A29: =+A28+1 -> 6 | B29: 305314372810 | C29: 44964 | D29: KGN-23020275 | F29: 16/02/23 | H29: 1 | I29: TEMU7812969 | J29: =(G29*$C$255)+(G29*$C$256)+(H29*$D$255+H29*$D$256)+(G29*$C$258+H29*$D$258) -> 2000000 | K29: =SUM(G29:I29)*250000 -> 250000 | L29: 300000 | N29: =+SUM(J29:M29) -> 2550000 | O29: PB2301310131 | R29: 1000 | BM29: XANH | CP29: X
A30: =+A29+1 -> 7 | B30: 305316872620 | C30: 44964 | D30: KGN-23020277 | F30: 16/02/23 | G30: 1 | I30: MSDU1699994 | J30: =(G30*$C$255)+(G30*$C$256)+(H30*$D$255+H30*$D$256)+(G30*$C$258+H30*$D$258) -> 1300000 | K30: =SUM(G30:I30)*250000 -> 250000 | L30: 300000 | N30: =+SUM(J30:M30) -> 1850000 | O30: 339LN2300145 | R30: 1104 | BM30: XANH | CP30: X
A31: =+A30+1 -> 8 | B31: 305316656100 | C31: 44965 | D31: KGN-23020308 | F31: 16/02/23 | H31: 1 | I31: CSNU6720543 | J31: =(G31*$C$255)+(G31*$C$256)+(H31*$D$255+H31*$D$256)+(G31*$C$258+H31*$D$258) -> 2000000 | K31: =SUM(G31:I31)*250000 -> 250000 | L31: 300000 | N31: =+SUM(J31:M31) -> 2550000 | O31: 2713562690 | R31: 36 | BM31: XANH | CP31: X
A32: =+A31+1 -> 9 | B32: 305316623310 | C32: 44965 | D32: KGN-23020307 | F32: 16/02/23 | H32: 1 | I32: WHSU6054232 | J32: =(G32*$C$255)+(G32*$C$256)+(H32*$D$255+H32*$D$256)+(G32*$C$258+H32*$D$258) -> 2000000 | K32: =SUM(G32:I32)*250000 -> 250000 | L32: 300000 | N32: =+SUM(J32:M32) -> 2550000 | O32: 039DX02313 | R32: 36 | BM32: XANH | CP32: X
A33: =+A32+1 -> 10 | B33: 105260265720 | C33: 44967 | D33: KGN-23020345 | F33: 16/02/23 | G33: 2 | I33: NYKU3790150 NYKU3868942 | J33: =(G33*$C$255)+(G33*$C$256)+(H33*$D$255+H33*$D$256)+(G33*$C$258+H33*$D$258) -> 2600000 | K33: =SUM(G33:I33)*250000 -> 500000 | N33: =+SUM(J33:M33) -> 3100000 | O33: ONEYPKGC65985600 | R33: 2 | BM33: ĐỎ | CP33: N
A34: =+A33+1 -> 11 | B34: 305323385530 | C34: 44967 | D34: KGN-23020568 | F34: 16/02/23 | H34: 3 | I34: TRHU4779135 TEMU7296918 NYKU5270667 | J34: =(G34*$C$255)+(G34*$C$256)+(H34*$D$255+H34*$D$256)+(G34*$C$258+H34*$D$258) -> 6000000 | K34: =SUM(G34:I34)*250000 -> 750000 | L34: 300000 | N34: =+SUM(J34:M34) -> 7050000 | O34: SGND07030700 | R34: 5500 | BM34: XANH | CP34: X
A35: =+A34+1 -> 12 | B35: 305323727940/E62 305323756900/H21 | C35: 44967 | D35: KGN-23020569 | F35: 16/02/23 | H35: 1 | I35: WHSU6347272 | J35: =(G35*$C$255)+(G35*$C$256)+(H35*$D$255+H35*$D$256)+(G35*$C$258+H35*$D$258) -> 2000000 | K35: =SUM(G35:I35)*250000 -> 250000 | L35: 300000 | N35: =+SUM(J35:M35) -> 2550000 | O35: 039DX02313 | R35: 36 | BM35: XANH | CP35: X
A36: =+A35+1 -> 13 | B36: 305326861510 | C36: 44970 | D36: KGN-23020570 | F36: 16/02/23 | G36: 1 | I36: YMLU3438714 | J36: =(G36*$C$255)+(G36*$C$256)+(H36*$D$255+H36*$D$256)+(G36*$C$258+H36*$D$258) -> 1300000 | K36: =SUM(G36:I36)*250000 -> 250000 | L36: 300000 | N36: =+SUM(J36:M36) -> 1850000 | O36: YMLUI490462827 | R36: 600 | BM36: XANH | CP36: X
A37: =+A36+1 -> 14 | B37: 305327614230 | C37: 44970 | D37: KGN-23020571 | F37: 16/02/23 | H37: 2 | I37: YMMU6314259 YMMU6578415 | J37: =(G37*$C$255)+(G37*$C$256)+(H37*$D$255+H37*$D$256)+(G37*$C$258+H37*$D$258) -> 4000000 | K37: =SUM(G37:I37)*250000 -> 500000 | L37: 300000 | N37: =+SUM(J37:M37) -> 4800000 | O37: YMLUI490462648 | R37: 68 | BM37: XANH | CP37: X
A38: =+A37+1 -> 15 | B38: 105260336160 | C38: 44971 | D38: KGN-23020346 | F38: 16/02/23 | G38: 2 | I38: FCIU6408242 FBIU0199502 | J38: =(G38*$C$255)+(G38*$C$256)+(H38*$D$255+H38*$D$256)+(G38*$C$258+H38*$D$258) -> 2600000 | K38: =SUM(G38:I38)*250000 -> 500000 | N38: =+SUM(J38:M38) -> 3100000 | O38: TLLYHCJH23025101 | R38: 1200 | BM38: VÀNG | CP38: N
A39: =+A38+1 -> 16 | B39: 305330306760 | C39: 14/02/2023 | D39: KGN-23020786 | F39: 24/02/23 | H39: 1 | I39: WHSU6578332 | J39: =(G39*$C$255)+(G39*$C$256)+(H39*$D$255+H39*$D$256)+(G39*$C$258+H39*$D$258) -> 2000000 | L39: 300000 | N39: =+SUM(J39:M39) -> 2300000 | O39: 039DX06289 | R39: 36 | BM39: XANH | CP39: X
A40: =+A39+1 -> 17 | B40: 305331839060 | C40: 15/02/2023 | D40: KGN-23020741 | F40: 24/02/23 | H40: 1 | I40: WHSU5161410 | J40: =(G40*$C$255)+(G40*$C$256)+(H40*$D$255+H40*$D$256)+(G40*$C$258+H40*$D$258) -> 2000000 | L40: 300000 | N40: =+SUM(J40:M40) -> 2300000 | O40: 039DX06289 | R40: 36 | BM40: XANH | CP40: X
A41: =+A40+1 -> 18 | B41: 305332601950/E62 305332614810/B11 | C41: 15/02/2023 | D41: KGN-23020738 | F41: 24/02/23 | H41: 1 | I41: WHSU6661914 | J41: =(G41*$C$255)+(G41*$C$256)+(H41*$D$255+H41*$D$256)+(G41*$C$258+H41*$D$258) -> 2000000 | L41: 300000 | N41: =+SUM(J41:M41) -> 2300000 | O41: 039DX06289 | R41: 34 | BM41: XANH | CP41: X
...

Sheet FOLIOT
B1: THEO DÕI HÀNG HÓA TẠM ỨNG, THANH TOÁN, ĐIỀU XE 2023 - FOLIOT
C2: Chi phí làm hàng
A3: SỐ ISO | B3: STT | C3: TKHQ | D3: NGÀY TKHQ | E3: TẠO JOB | F3: SELLING + OBH PENDING | G3: Ngày tạm ứmg | H3: X/N | I3: MỨC | J3: 20' | K3: 40' | L3: LCL | M3: LUỒNG | N3: Nâng/hạ/ CSHT | O3: Chi phí làm hàng | P3: LCC/ CO | Q3: Estimate tạm ứng | R3: Số kiện | S3: G.W (KGS) | T3: Tên hàng | U3: Số Bill/ Booking | V3: Ngày ETA/ Cut off | W3: CẢNG | X3: Dest | Y3: Số cont/ seal | Z3: Ngày giao/Xếp hàng | AA3: PHÍ NÂNG | AB3: PHÍ HẠ | AC3: PHÍ CHỨNG TỪ (TM) | AD3: PHÍ CHỨNG TỪ (ST CK) | AE3: Phí khai hquan | AF3: Phí vận chuyển | AG3: PHÍ KHÁC | AH3: TỔNG CHI HỘ (CASH) | AI3: TỔNG CHI HỘ (ST CK) | AJ3: GHI CHÚ PHÁT SINH | AK3: PHÍ DỊCH VỤ GN | AL3: DT BẢNG KÊ (GỒM VAT) | AM3: GIAO BẢNG KÊ | AN3: CƯỢC CONT | AO3: TẠM THU HÃNG TÀU/ SỬA CHỮA CONT | AP3: CHUYỂN CƯỢC | AQ3: GHI CHÚ | AR3: PHÍ CƯỢC
B4: 1 | C4: 305287582630 | D4: 14/01/2023 | E4: KGN-23010735 | F4: Ms. Thẩm | H4: X | K4: 1 | U4: ZIMUHCM80317138 | Y4: GAOU6109936 | AG4: =+(1200000+(18-10)*40000) -> 1520000 | AH4: =+AA4+AB4+AC4 -> 0 | AI4: =+AD4 -> 0 | AK4: =(AE4+AF4+AG4)*1.1 -> 1672000 | AL4: =+AK4+AI4+AH4 -> 1672000 | AT4: 1672000
B5: 2 | C5: 305291802930 | D5: 16/01/2023 | E5: KGN-23010807 | F5: Ms. Thẩm | H5: X | K5: 1 | U5: 2712210591 | Y5: TCNU3880944 | AA5: =1227273*1.1 -> 1350000.3 | AB5: =959091*1.1 -> 1055000.1 | AE5: 900000 | AF5: 3580000 | AH5: =+AA5+AB5+AC5 -> 2405000.4 | AI5: =+AD5 -> 0 | AK5: =(AE5+AF5+AG5)*1.1 -> 4928000 | AL5: =+AK5+AI5+AH5 -> 7333000.4 | AM5: =+AA5+AB5 -> 2405000.4 | AT5: 4928000
B6: 3 | C6: 305320724500 | D6: 44966 | E6: KGN-23020573 | G6: 16/02/2023 | H6: X | K6: 1 | U6: ZIMUHCM80319515 | Y6: JZPU8023588 | AA6: =836364*1.1 -> 920000.4 | AB6: =645000*1.1 -> 709500 | AE6: 900000 | AF6: 3580000 | AG6: =+(1200000+(21-10)*40000) -> 1640000 | AH6: =+AA6+AB6+AC6 -> 1629500.4 | AI6: =+AD6 -> 0 | AK6: =(AE6+AF6+AG6)*1.1 -> 6732000 | AL6: =+AK6+AI6+AH6 -> 8361500.4 | AM6: =+AA6+AB6 -> 1629500.4 | AT6: 6732000
B7: 4 | C7: 305320811630 | D7: 44966 | E7: KGN-23020574 | G7: 16/02/2023 | H7: X | J7: 1 | U7: ZIMUHCM80319516 | Y7: ZIMU1379156 | AA7: =790909*1.1 -> 869999.9 | AB7: =365000*1.1 -> 401500 | AE7: 900000 | AF7: 3380000 | AG7: 1200000 | AH7: =+AA7+AB7+AC7 -> 1271499.9 | AI7: =+AD7 -> 0 | AK7: =(AE7+AF7+AG7)*1.1 -> 6028000 | AL7: =+AK7+AI7+AH7 -> 7299499.9 | AM7: =+AA7+AB7 -> 1271499.9 | AT7: 6028000
A8: THÁNG 03/2023 | AH8: =SUM(AH4:AH7) -> 5306000.7 | AI8: =SUM(AI2:AI7) -> 0 | AK8: =SUM(AK4:AK7) -> 19360000 | AL8: =+AH8+AI8+AK8 -> 24666001
B9: 1 | C9: 305372133640 305372110060 | D9: 44988 | E9: KGN-23031096 | G9: 18/03/23 | H9: X | K9: 1 | M9: VÀNG | U9: 11349535 | Y9: HLBU2080083 | AA9: =840000*1.1 -> 924000 | AB9: =954545*1.1 -> 1049999.5 | AE9: =900000+300000 -> 1200000 | AF9: 3580000 | AH9: =+AA9+AB9+AC9 -> 1973999.5 | AI9: =+AD9 -> 0 | AJ9: 2 TK | AK9: =(AE9+AF9+AG9)*1.1 -> 5258000 | AL9: =+AK9+AI9+AH9 -> 7231999.5 | AM9: =+AA9+AB9 -> 1973999.5
B10: 2 | C10: 305376039750 305376026120 | D10: 44991 | E10: KGN-23031097 | G10: 18/03/23 | H10: X | K10: 1 | M10: XANH | U10: 11349535 | Y10: HLXU8471190 | AA10: =840000*1.1 -> 924000 | AB10: =954545*1.1 -> 1049999.5 | AE10: =900000+300000 -> 1200000 | AF10: 3580000 | AH10: =+AA10+AB10+AC10 -> 1973999.5 | AI10: =+AD10 -> 0 | AJ10: 2 TK | AK10: =(AE10+AF10+AG10)*1.1 -> 5258000 | AL10: =+AK10+AI10+AH10 -> 7231999.5 | AM10: =+AA10+AB10 -> 1973999.5
B11: 3 | C11: 305378247330 | D11: 44992 | E11: KGN-23031098 | G11: 18/03/23 | H11: X | K11: 1 | M11: XANH | U11: 8035233140 | Y11: BSIU9355605 | AA11: =1227273*1.1 -> 1350000.3 | AB11: =954545*1.1 -> 1049999.5 | AE11: 900000 | AF11: 3580000 | AH11: =+AA11+AB11+AC11 -> 2399999.8 | AI11: =+AD11 -> 0 | AK11: =(AE11+AF11+AG11)*1.1 -> 4928000 | AL11: =+AK11+AI11+AH11 -> 7327999.8 | AM11: =+AA11+AB11 -> 2399999.8
B12: 4 | C12: 305381304450 | D12: 44993 | E12: KGN-23031099 | G12: 18/03/23 | H12: X | K12: 1 | M12: VÀNG | U12: AHA0259892 | Y12: CMAU8210121 | AA12: =1227273*1.1 -> 1350000.3 | AB12: =954545*1.1 -> 1049999.5 | AE12: 900000 | AF12: 3580000 | AG12: =+(1200000+(14-10)*40000) -> 1360000 | AH12: =+AA12+AB12+AC12 -> 2399999.8 | AI12: =+AD12 -> 0 | AJ12: C/O AANZ | AK12: =(AE12+AF12+AG12)*1.1 -> 6424000 | AL12: =+AK12+AI12+AH12 -> 8823999.8 | AM12: =+AA12+AB12 -> 2399999.8
B13: 5 | C13: 105325974830 | D13: 13/03/2023 | E13: KGN-23031285 | G13: Không ứng | H13: N | M13: ĐỎ | U13: 132300019676513 | AE13: 900000 | AG13: 1500000 | AH13: =+AA13+AB13+AC13 -> 0 | AI13: =+AD13 -> 0 | AJ13: CHI MIỄN KIỂM, KHAI TK K VC | AK13: =(AE13+AF13+AG13)*1.1 -> 2640000 | AL13: =+AK13+AI13+AH13 -> 2640000
B14: 6 | C14: 105324562930 | D14: 13/03/2023 | E14: KGN-23031286 | G14: Không ứng | H14: N | M14: VÀNG | U14: M2418751041 | AE14: 900000 | AH14: =+AA14+AB14+AC14 -> 0 | AI14: =+AD14 -> 0 | AJ14: KHAI TK K VC | AK14: =(AE14+AF14+AG14)*1.1 -> 990000 | AL14: =+AK14+AI14+AH14 -> 990000
A15: THÁNG 04/2023 | AH15: =SUM(AH9:AH14) -> 8747998.6 | AI15: =SUM(AI9:AI14) -> 0 | AK15: =SUM(AK9:AK14) -> 25498000 | AL15: =+AH15+AI15+AK15 -> 34245999
B16: 1 | C16: 105377855700 | D16: 07/04/2023 | E16: KGN-23040598 | G16: 13/04/23 | H16: N | M16: ĐỎ | U16: 132300020351328 | AE16: 900000 | AH16: =+AA16+AB16+AC16 -> 0 | AI16: =+AD16 -> 0 | AJ16: KHAI TK K VC | AK16: =(AE16+AF16+AG16)*1.1 -> 990000 | AL16: =+AK16+AI16+AH16 -> 990000 | AR16: 100000
B17: 2 | C17: 105382774450 | D17: 08/04/2023 | E17: KGN-23040527 | G17: 13/04/23 | H17: N | L17: AIR | M17: XANH | U17: HMTL028371 | AE17: 900000 | AH17: =+AA17+AB17+AC17 -> 0 | AI17: =+AD17 -> 0 | AJ17: KHAI TK K VC | AK17: =(AE17+AF17+AG17)*1.1 -> 990000 | AL17: =+AK17+AI17+AH17 -> 990000 | AR17: 100000
B18: 3 | C18: 305433920320 | D18: 31/03/2023 | E18: KGN-23040649 | G18: 13/04/23 | H18: X | L18: AIR | M18: XANH | AE18: 900000 | AH18: =+AA18+AB18+AC18 -> 0 | AI18: =+AD18 -> 0 | AJ18: KHAI TK K VC | AK18: =(AE18+AF18+AG18)*1.1 -> 990000 | AL18: =+AK18+AI18+AH18 -> 990000 | AR18: 100000
B19: 4 | C19: 305440475930 305440459500 | D19: 04/04/2023 | E19: KGN-23040171 | G19: 13/04/23 | H19: X | K19: 1 | M19: XANH | U19: YMLUE490365834 | Y19: TGBU5547383 | AA19: 1450000 | AB19: 709500 | AE19: =900000+300000 -> 1200000 | AF19: 3580000 | AH19: =+AA19+AB19+AC19 -> 2159500 | AI19: =+AD19 -> 0 | AK19: =(AE19+AF19+AG19)*1.1 -> 5258000 | AL19: =+AK19+AI19+AH19 -> 7417500 | AM19: =+AA19+AB19 -> 2159500 | AR19: 200000
B20: 5 | C20: 305453199610 | D20: 10/04/2023 | E20: KGN-23040503 | G20: 13/04/23 | H20: X | K20: 1 | M20: XANH | U20: 235300348459 | Y20: EGHU8345260 | AA20: 1350000 | AB20: 1050000 | AE20: 900000 | AF20: 3580000 | AH20: =+AA20+AB20+AC20 -> 2400000 | AI20: =+AD20 -> 0 | AK20: =(AE20+AF20+AG20)*1.1 -> 4928000 | AL20: =+AK20+AI20+AH20 -> 7328000 | AM20: =+AA20+AB20 -> 2400000 | AR20: 200000
B21: 6 | C21: 305455469340 | D21: 11/04/2023 | E21: KGN-23040597 | G21: 13/04/23 | H21: X | K21: 1 | M21: XANH | U21: YMLUE490365835 | Y21: YMMU6115658 | AA21: 1450000 | AB21: 1055000 | AE21: 900000 | AF21: 3580000 | AH21: =+AA21+AB21+AC21 -> 2505000 | AI21: =+AD21 -> 0 | AK21: =(AE21+AF21+AG21)*1.1 -> 4928000 | AL21: =+AK21+AI21+AH21 -> 7433000 | AM21: =+AA21+AB21 -> 2505000 | AR21: 200000
B22: 7 | C22: 305458536630 | D22: 45028 | E22: KGN-23040650 | G22: 25/04/23 | H22: X | K22: 1 | M22: XANH | U22: YMLUE490365835 | Y22: TCNU1984580 | AA22: 1450000 | AB22: 2110000 | AE22: 900000 | AF22: 3580000 | AH22: =+AA22+AB22+AC22 -> 3560000 | AI22: =+AD22 -> 0 | AK22: =(AE22+AF22+AG22)*1.1 -> 4928000 | AL22: =+AK22+AI22+AH22 -> 8488000 | AM22: =+AA22+AB22 -> 3560000 | AR22: 200000
B23: 8 | C23: 305458698440 305458713360 | D23: 45028 | E23: KGN-23040651 | G23: 25/04/23 | H23: X | K23: 1 | M23: VÀNG | U23: YMLUE490365835 | Y23: TEMU7681811 | AA23: 1450000 | AE23: =900000+300000 -> 1200000 | AF23: 3580000 | AH23: =+AA23+AB23+AC23 -> 1450000 | AI23: =+AD23 -> 0 | AK23: =(AE23+AF23+AG23)*1.1 -> 5258000 | AL23: =+AK23+AI23+AH23 -> 6708000 | AM23: =+AA23 -> 1450000 | AR23: 200000
B24: 9 | C24: 305464268340 | D24: 14/04/2023 | E24: KGN-23040877 | G24: 25/04/23 | H24: X | K24: 1 | M24: XANH | U24: 2716792970 | Y24: TEMU6468930 | AA24: 1200000 | AB24: 4220000 | AE24: 900000 | AF24: 3580000 | AH24: =+AA24+AB24+AC24 -> 5420000 | AI24: =+AD24 -> 0 | AK24: =(AE24+AF24+AG24)*1.1 -> 4928000 | AL24: =+AK24+AI24+AH24 -> 10348000 | AM24: =+AA24+AB24 -> 5420000 | AR24: 200000
B25: 10 | C25: 305464358310 | D25: 14/04/2023 | E25: KGN-23040876 | G25: 25/04/23 | H25: X | K25: 1 | M25: XANH | U25: 2716792970 | Y25: OOCU8763340 | AA25: 1200000 | AE25: 900000 | AF25: 3580000 | AH25: =+AA25+AB25+AC25 -> 1200000 | AI25: =+AD25 -> 0 | AK25: =(AE25+AF25+AG25)*1.1 -> 4928000 | AL25: =+AK25+AI25+AH25 -> 6128000 | AM25: =+AA25+AB25 -> 1200000 | AR25: 200000
B26: 11 | C26: 305466217030 | D26: 15/04/2023 | E26: KGN-23040875 | G26: 25/04/23 | H26: X | K26: 1 | M26: XANH | U26: 2716792970 | Y26: CBHU9168954 | AA26: 1200000 | AE26: 900000 | AF26: 3580000 | AH26: =+AA26+AB26+AC26 -> 1200000 | AI26: =+AD26 -> 0 | AK26: =(AE26+AF26+AG26)*1.1 -> 4928000 | AL26: =+AK26+AI26+AH26 -> 6128000 | AM26: =+AA26+AB26 -> 1200000 | AR26: 200000
B27: 12 | C27: 305469653810 | D27: 17/04/2023 | E27: KGN-23040968 | G27: 25/04/23 | H27: X | K27: 1 | M27: XANH | U27: 2716792970 | Y27: OOCU6527962 | AA27: 1200000 | AE27: 900000 | AF27: 3580000 | AH27: =+AA27+AB27+AC27 -> 1200000 | AI27: =+AD27 -> 0 | AK27: =(AE27+AF27+AG27)*1.1 -> 4928000 | AL27: =+AK27+AI27+AH27 -> 6128000 | AM27: =+AA27+AB27 -> 1200000 | AR27: 200000
B28: 13 | C28: 305469700820 | D28: 17/04/2023 | E28: KGN-23040972 | G28: 25/04/23 | H28: X | K28: 1 | M28: XANH | U28: YMLUW490429137 | Y28: BMOU6325290 | AA28: 1450000 | AB28: 1050000 | AE28: 900000 | AF28: 3580000 | AH28: =+AA28+AB28+AC28 -> 2500000 | AI28: =+AD28 -> 0 | AK28: =(AE28+AF28+AG28)*1.1 -> 4928000 | AL28: =+AK28+AI28+AH28 -> 7428000 | AM28: =+AA28+AB28 -> 2500000 | AR28: 200000
B29: 14 | C29: 305472349950 305472372240 | D29: 45034 | E29: KGN-23040997 | G29: 25/04/23 | H29: X | K29: 1 | M29: VÀNG | U29: SGND48129700 | Y29: DRYU4107155 | AA29: 920000 | AB29: 709500 | AE29: =900000+300000 -> 1200000 | AF29: 3580000 | AG29: 1200000 | AH29: =+AA29+AB29+AC29 -> 1629500 | AI29: =+AD29 -> 0 | AJ29: C/O AANZ | AK29: =(AE29+AF29+AG29)*1.1 -> 6578000 | AL29: =+AK29+AI29+AH29 -> 8207500 | AM29: =+AA29+AB29 -> 1629500 | AR29: 200000
B30: 15 | C30: 305481031721 305481073940 | D30: 21/04/2023 | E30: KGN-23041463 | G30: 25/04/23 | H30: x | K30: 1 | M30: XANH/VÀNG | U30: 2717182770 | Y30: CSLU6141550 | AA30: 1450000 | AB30: 2110000 | AE30: =900000+300000 -> 1200000 | AF30: 3580000 | AH30: =+AA30+AB30+AC30 -> 3560000 | AI30: =+AD30 -> 0 | AK30: =(AE30+AF30+AG30)*1.1 -> 5258000 | AL30: =+AK30+AI30+AH30 -> 8818000 | AM30: =+AA30+AB30 -> 3560000 | AR30: 200000
B31: 16 | C31: 305481601300 305481624400 | D31: 21/04/2023 | E31: KGN-23041464 | G31: 25/04/23 | H31: X | K31: 1 | M31: XANH/VÀNG | U31: 2717182770 | Y31: BSIU9364000 | AA31: 1450000 | AE31: =900000+300000 -> 1200000 | AF31: 3580000 | AH31: =+AA31+AB31+AC31 -> 1450000 | AI31: =+AD31 -> 0 | AK31: =(AE31+AF31+AG31)*1.1 -> 5258000 | AL31: =+AK31+AI31+AH31 -> 6708000 | AM31: =+AA31+AB31 -> 1450000 | AR31: 200000
B32: 17 | C32: 305486621550 305486636950 | D32: 24/04/2023 | E32: KGN-23041575 | G32: Không ứng | H32: X | K32: 1 | M32: XANH/VÀNG | U32: YMLUE490366006 | Y32: BMOU5719956 | AA32: 920000 | AB32: 709500 | AE32: =900000+300000 -> 1200000 | AF32: 3580000 | AH32: =+AA32+AB32+AC32 -> 1629500 | AI32: =+AD32 -> 0 | AK32: =(AE32+AF32+AG32)*1.1 -> 5258000 | AL32: =+AK32+AI32+AH32 -> 6887500 | AM32: =+AA32+AB32 -> 1629500 | AR32: 200000
B33: 18 | C33: 305486913230 305486802850 | D33: 24/04/2023 | E33: KGN-23041574 | G33: Không ứng | H33: X | K33: 1 | M33: XANH/VÀNG | U33: SGND46860700 | Y33: NYKU0847571 | AA33: 1450000 | AB33: 1050000 | AE33: =900000+300000 -> 1200000 | AF33: 3580000 | AH33: =+AA33+AB33+AC33 -> 2500000 | AI33: =+AD33 -> 0 | AK33: =(AE33+AF33+AG33)*1.1 -> 5258000 | AL33: =+AK33+AI33+AH33 -> 7758000 | AM33: =+AA33+AB33 -> 2500000 | AR33: 200000
B34: 19 | C34: 305488907200 305488952700 | D34: 25/04/2023 | E34: KGN-23041576 | G34: Không ứng | H34: x | K34: 1 | M34: XANH | U34: ONEYSGND52089700 | Y34: CAIU9503097 | AA34: 920000 | AB34: 1055000 | AE34: =900000+300000 -> 1200000 | AF34: 3580000 | AH34: =+AA34+AB34+AC34 -> 1975000 | AI34: =+AD34 -> 0 | AK34: =(AE34+AF34+AG34)*1.1 -> 5258000 | AL34: =+AK34+AI34+AH34 -> 7233000 | AM34: =+AA34+AB34 -> 1975000 | AR34: 200000
A35: THÁNG 05/2023 | AH35: =SUM(AH18:AH34) -> 36338500 | AI35: =SUM(AI18:AI34) -> 0 | AK35: =SUM(AK18:AK34) -> 83798000 | AL35: =SUM(AL18:AL34) -> 120136500

Sheet SUNAGRO
A1: THEO DÕI HÀNG HÓA TẠM ỨNG, THANH TOÁN, ĐIỀU XE 2023 - SUNAGRO
B2: MST:
A3: STT | B3: TKHQ | C3: NGÀY TKHQ | D3: TẠO JOB | E3: SELLING + OBH PENDING | F3: X/N | G3: 20' | H3: 40' | I3: LCL | J3: LUỒNG | K3: Ngày tạm ứmg | L3: Nâng/hạ/ CSHT | M3: Chi phí làm hàng | N3: LCC/ CO | O3: Estimate tạm ứng | P3: Số kiện | Q3: G.W (KGS) | R3: Tên hàng | S3: Số Bill/ Booking | T3: Ngày ETA/ Cut off | U3: CẢNG | V3: Dest | W3: Số cont/ seal | X3: Ngày giao/Xếp hàng | Y3: PHÍ NÂNG | Z3: PHÍ HẠ | AA3: Phí KDTV | AB3: Phí CSHT | AC3: PHÍ DEM | AD3: PHÍ DET | AE3: PHÍ CHỨNG TỪ (TM) | AF3: PHÍ CHỨNG TỪ (ST CK) | AG3: Phí vận chuyển | AH3: Phí CO | AI3: PHÍ KHÁC | AJ3: TỔNG CHI HỘ (CASH) | AK3: TỔNG CHI HỘ (ST CK) | AL3: GHI CHÚ PHÁT SINH | AM3: PHÍ DỊCH VỤ GN | AN3: DT BẢNG KÊ (GỒM VAT) | AO3: GIAO BẢNG KÊ | AP3: CƯỢC CONT | AQ3: TẠM THU HÃNG TÀU/ SỬA CHỮA CONT | AR3: CHUYỂN CƯỢC | AS3: GHI CHÚ | AT3: PHÍ CƯỢC | AU3: CHI HỘ OBH
A4: THÁNG 03/2023
B5: 305381479120 | C5: 44993 | D5: KGN-23031526 | F5: X | H5: 1 | J5: Vàng | K5: 27/03/2023 | L5: 0 | M5: =SUM(G5:I5)*500000 -> 500000 | N5: 300000 | O5: =+SUM(L5:N5) -> 800000 | S5: 225592668 | W5: MRSU3932524 | Y5: 1350000 | Z5: 709500 | AA5: 99000 | AB5: 500000 | AG5: 4650000 | AH5: 600000 | AI5: 600000 | AJ5: =+Y5+Z5+AA5+AB5+AE5+AC5+AD5 -> 2658500 | AK5: =+AF5 -> 0 | AL5: C/O E, PHYTO 026691 | AM5: =(AG5+AH5+AI5)*1.1 -> 6435000 | AN5: =+AM5+AK5+AJ5 -> 9093500 | AO5: =+Z5+Y5 -> 2059500
B6: 305403931510 | C6: 20/03/2023 | D6: KGN-23031527 | F6: X | H6: 1 | J6: ĐỎ | K6: 27/03/2023 | L6: 0 | M6: =SUM(G6:I6)*500000 -> 500000 | N6: 300000 | O6: =+SUM(L6:N6) -> 800000 | S6: BSGNC23005629 | W6: TXGU5412544 | Y6: 1350000 | Z6: 709500 | AA6: 99000 | AB6: 500000 | AG6: 4650000 | AH6: 600000 | AI6: 600000 | AJ6: =+Y6+Z6+AA6+AB6+AE6+AC6+AD6 -> 2658500 | AK6: =+AF6 -> 0 | AL6: C/O E, PHYTO 031554 | AM6: =(AG6+AH6+AI6)*1.1 -> 6435000 | AN6: =+AM6+AK6+AJ6 -> 9093500 | AO6: =+Z6+Y6 -> 2059500
B7: 305420239040 | C7: 27/03/2023 | D7: KGN-23031528 | F7: X | H7: 1 | J7: ĐỎ | K7: 27/03/2023 | L7: 0 | M7: =SUM(G7:I7)*500000 -> 500000 | N7: 300000 | O7: =+SUM(L7:N7) -> 800000 | S7: 226179041 | W7: MRSU3128706 | Y7: 1300000 | Z7: 709500 | AA7: 99000 | AB7: 500000 | AG7: 4650000 | AH7: 600000 | AI7: 600000 | AJ7: =+Y7+Z7+AA7+AB7+AE7+AC7+AD7 -> 2608500 | AK7: =+AF7 -> 0 | AL7: C/O E, PHYTO 033449 | AM7: =(AG7+AH7+AI7)*1.1 -> 6435000 | AN7: =+AM7+AK7+AJ7 -> 9043500 | AO7: =+Z7+Y7 -> 2009500
A8: THÁNG 07/2023
B9: 105551969940 | C9: 45117 | D9: KGN-23070623 | F9: N | I9: 1 | J9: Vàng | P9: 2 | Q9: 810 KGS/ 2.35 CBM | S9: SE23060066 | W9: BMOU6035346 | Y9: =152928+27805 -> 180733 | AG9: =1000000+1350000 -> 2350000 | AJ9: =+Y9+Z9+AA9+AB9+AE9+AC9+AD9 -> 180733 | AK9: =+AF9 -> 0 | AM9: =(AG9+AH9+AI9)*1.08 -> 2538000 | AN9: =+AM9+AK9+AJ9 -> 2718733 | AU9: KGN-PR-2307507
B10: 105570983561 | C10: 45117 | D10: KGN-23070624 | F10: N | H10: 1 | J10: ĐỎ | S10: OOLU2720166200 | W10: OOCU6999022 | Y10: 1150200 | Z10: 1430000 | AB10: 500000 | AC10: =213210+106605+106605 -> 426420 | AG10: 4650000 | AJ10: =+Y10+Z10+AA10+AB10+AE10+AC10+AD10 -> 3506620 | AK10: =+AF10 -> 0 | AM10: =(AG10+AH10+AI10)*1.08 -> 5022000 | AN10: =+AM10+AK10+AJ10 -> 8528620
B11: 105588821700 | C11: 45125 | D11: KGN-23071091 | F11: N | I11: 1 | J11: Vàng | P11: 130 | Q11: 3207.8 KGS/ 6 CBM | S11: AMIGL230273796A | W11: BMOU6930536 | Y11: 189098 | AG11: =1000000+2550000 -> 3550000 | AJ11: =+Y11+Z11+AA11+AB11+AE11+AC11+AD11 -> 189098 | AK11: =+AF11 -> 0 | AM11: =(AG11+AH11+AI11)*1.08 -> 3834000 | AN11: =+AM11+AK11+AJ11 -> 4023098
B12: PHÍ SỬA TK AMA | D12: KGN-23071455 | AI12: =400000*11 -> 4400000 | AJ12: =+Y12+Z12+AA12+AB12+AE12+AC12+AD12 -> 0 | AK12: =+AF12 -> 0 | AM12: =(AG12+AH12+AI12)*1.08 -> 4752000 | AN12: =+AM12+AK12+AJ12 -> 4752000
AJ13: =+Y13+Z13+AA13+AB13+AE13+AC13+AD13 -> 0 | AK13: =+AF13 -> 0 | AM13: =(AG13+AH13+AI13)*1.08 -> 0 | AN13: =+AM13+AK13+AJ13 -> 0
AJ14: =+Y14+Z14+AA14+AB14+AE14+AC14+AD14 -> 0 | AK14: =+AF14 -> 0 | AM14: =(AG14+AH14+AI14)*1.08 -> 0 | AN14: =+AM14+AK14+AJ14 -> 0
AJ15: =+Y15+Z15+AA15+AB15+AE15+AC15+AD15 -> 0 | AK15: =+AF15 -> 0 | AM15: =(AG15+AH15+AI15)*1.08 -> 0 | AN15: =+AM15+AK15+AJ15 -> 0
AJ16: =+Y16+Z16+AA16+AB16+AE16+AC16+AD16 -> 0 | AK16: =+AF16 -> 0 | AM16: =(AG16+AH16+AI16)*1.08 -> 0 | AN16: =+AM16+AK16+AJ16 -> 0
AJ17: =+Y17+Z17+AA17+AB17+AE17+AC17+AD17 -> 0 | AK17: =+AF17 -> 0 | AM17: =(AG17+AH17+AI17)*1.08 -> 0 | AN17: =+AM17+AK17+AJ17 -> 0
AJ18: =+Y18+Z18+AA18+AB18+AE18+AC18+AD18 -> 0 | AK18: =+AF18 -> 0 | AM18: =(AG18+AH18+AI18)*1.08 -> 0 | AN18: =+AM18+AK18+AJ18 -> 0
AJ19: =+Y19+Z19+AA19+AB19+AE19+AC19+AD19 -> 0 | AK19: =+AF19 -> 0 | AM19: =(AG19+AH19+AI19)*1.08 -> 0 | AN19: =+AM19+AK19+AJ19 -> 0

Sheet ZASI
A2: THEO DÕI HÀNG HÓA TẠM ỨNG, THANH TOÁN, ĐIỀU XE - ZASI
C3: MST: 3703240385 | D3: Địa chỉ : Lô G1, G2 (khu B2) đường D9, Khu công Nghiệp Rạch Bắp, Phường Tây Nam, Tp Hồ Chí Minh
A4: STT | B4: NGÀY ĐÓNG/GIAO HÀNG | C4: Số TK | D4: Ngày ĐK | E4: Tạo Job | F4: NCC LINE | G4: X/N | H4: 20' | I4: 40' | J4: LCL | K4: LUỒNG | L4: Vận đơn/ BOOKING | M4: SỐ CONT/SEAL | N4: SỐ HĐ | O4: CUT OFF ETA/ETD | P4: DEM/DET | Q4: SỐ XE | R4: CẢNG | S4: KIỂM HÓA | T4: PHÍ CO | U4: PHÍ TK THÊM | V4: LẤY BILL GỐC | W4: PHỤ PHÍ NÂNG | X4: PHÍ NÂNG | Y4: PHÍ HẠ | Z4: PHÍ CHỨNG TỪ (TM) | AA4: PHÍ CSHT | AB4: PHÍ DEM/DET | AC4: PHÍ SỮA CHỮA CONT | AD4: TỔNG CHI HỘ (CASH) | AE4: GHI CHÚ PHÁT SINH | AF4: PHÍ DỊCH VỤ GN | AG4: DT BẢNG KÊ (GỒM VAT) | AH4: GIAO BẢNG KÊ | AI4: Phụ phí thu hàng nặng
A5: THÁNG 5/2025 | AI5: 450000
A6: 1 | B6: 09/05/2025 | C6: 107141079951 | D6: 29/04/2025 | E6: KGN-25042236 | G6: N | H6: 1 | K6: VÀNG | L6: NSASGNG204947 | M6: SITU2828223/SITF590026 | N6: JS-250410-1 | O6: 30/04/2025 | P6: DEM: 13/05/2025 DET: 3 | R6: CÁT LÁI | X6: 497000 | Y6: 999000 | Z6: =5670000+1150000 -> 6820000 | AA6: 250000 | AD6: =+SUM(W6:AC6) -> 8566000 | AE6: KHAI TK CÁT LÁI | AF6: =((H6*4600000)+(I6*4600000))*1.08+(S6*500000*1.08) -> 4968000 | AG6: =+AD6+AF6 -> 13534000
A7: =+A6+1 -> 2 | B7: 15/05/2025 | C7: 107162617701 | D7: 08/05/2025 | E7: KGN-25050221 | G7: N | H7: 1 | K7: ĐỎ | L7: NSASGNG206194 | M7: SITU2641823/SITF564098 | N7: JS-250410-2B | O7: 08/05/2025 | P7: DEM: 21/05/2025 DET: 3 | R7: CÁT LÁI | S7: 1 | X7: 1194000 | Y7: 980000 | Z7: =5670000+1150000 -> 6820000 | AA7: 250000 | AD7: =+SUM(W7:AC7) -> 9244000 | AE7: KHAI TK CÁT LÁI THAM VẤN GIÁ 3TR CHI KIỂM HÓA (Đã trả) | AF7: =((H7*4600000)+(I7*4600000))*1.08+(S7*500000*1.08) -> 5508000 | AG7: =+AD7+AF7 -> 14752000
A8: =+A7+1 -> 3 | B8: 23/05/2025 | C8: 107183292050 | D8: 15/05/2025 | E8: KGN-25051032 | G8: N | H8: 1 | K8: VÀNG | L8: NSASGNG206478A | M8: UETU2333229/SITF563275 | N8: JS-250410-2A | O8: 15/05/2025 | P8: DEM: 27/05/2025 | R8: CÁT LÁI | X8: 1018000 | Y8: 1000000 | Z8: =5670000+1150000 -> 6820000 | AA8: 250000 | AD8: =+SUM(W8:AC8) -> 9088000 | AE8: KHAI TK CÁT LÁI | AF8: =((H8*4600000)+(I8*4600000))*1.08+(S8*500000*1.08) -> 4968000 | AG8: =+AD8+AF8 -> 14056000
A9: =+A8+1 -> 4 | B9: 24/05/2025 | C9: 107191284911 | D9: 19/05/2025 | E9: KGN-25051147 | G9: N | H9: 1 | K9: ĐỎ | L9: NSASGNG207685 | M9: TGBU2542773/SITF564216 | N9: JS-250410-3 | O9: 17/05/2025 | P9: DEM: 30/05/2025 | R9: CÁT LÁI | S9: 1 | X9: 1337000 | Y9: =265000+ 980000 -> 1245000 | Z9: =5670000+1150000 -> 6820000 | AA9: 250000 | AD9: =+SUM(W9:AC9) -> 9652000 | AE9: KHAI TK CÁT LÁI THAM VẤN GIÁ | AF9: =((H9*4600000)+(I9*4600000))*1.08+(S9*500000*1.08) -> 5508000 | AG9: =+AD9+AF9 -> 15160000
A10: =+A9+1 -> 5 | C10: 107200172110 | D10: 21/05/2025 | E10: KGN-25051464 | G10: N | H10: 1 | K10: VÀNG | L10: NSASGNG208508 | M10: BEAU2877275/SITF561876 | N10: JS-250429-1 | O10: 24/05/2025 | P10: DEM: 06/06/2025 | R10: CÁT LÁI | X10: 727000 | Y10: 999000 | Z10: =5670000+1150000 -> 6820000 | AA10: 250000 | AD10: =+SUM(W10:AC10) -> 8796000 | AE10: KHAI TK CÁT LÁI | AF10: =((H10*4600000)+(I10*4600000))*1.08+(S10*500000*1.08) -> 4968000 | AG10: =+AD12+AF10 -> 5008000
A11: THÁNG 6/2025 | AI11: 450000
C12: 10671172961 10677471642 | D12: 09/11/2024 03/12/2024 | W12: 40000 | AD12: =+SUM(W12:AC12) -> 40000 | AE12: BỔ SUNG CHI HỘ LPHQ | AF12: =((H12*4600000)+(I12*4600000))*1.08+(S12*500000*1.08) -> 0
A13: 1 | C13: 107246741450 | D13: 07/06/2025 | E13: KGN-25060191 | G13: N | H13: 2 | K13: VÀNG | L13: NSASGNG211976 | M13: BEAU2700124 UETU2775004 | N13: JS-250429-2 | O13: 05/06/2025 | P13: DEM: 18/06/2025 | Q13: 50H29647 50H05655 | R13: PHƯỚC AN -> CÁT LÁI | X13: 1900000 | Y13: 2000000 | Z13: 12490000 | AA13: 500000 | AD13: =+SUM(W13:AC13) -> 16890000 | AE13: KHAI TK CÁT LÁI THAM VẤN GIÁ | AF13: =((H13*(3600000+900000)+(I13*4600000))*1.08+(S13*500000*1.08)) -> 9720000 | AG13: =+AD13+AF13 -> 26610000
A14: =+A13+1 -> 2 | C14: 107281597400 | D14: 23/06/2025 | E14: KGN-25060854 | G14: N | H14: 2 | K14: VÀNG | L14: NSASGNG213155 | M14: TIIU2283115 SITU2591614 | N14: JS-250429-3 | O14: 19/06/2025 | P14: 02/07/2025 | Q14: 51C23338 50H29647 | R14: PHƯỚC AN -> CÁT LÁI | X14: 1524000 | Y14: 2000000 | Z14: 12490000 | AA14: 500000 | AD14: =+SUM(W14:AC14) -> 16514000 | AE14: KHAI TK CÁT LÁI | AF14: =((H14*(3600000+900000)+(I14*4600000))*1.08+(S14*500000*1.08)) -> 9720000 | AG14: =+AD14+AF14 -> 26234000
A15: =+A14+1 -> 3 | AD15: =+SUM(W15:AC15) -> 0 | AF15: =((H15*4600000)+(I15*4600000))*1.08+(S15*500000*1.08) -> 0 | AG15: =+AD15+AF15 -> 0
A16: =+A15+1 -> 4 | AD16: =+SUM(W16:AC16) -> 0
A17: =+A16+1 -> 5
A18: =+A17+1 -> 6
A19: =+A18+1 -> 7
A20: =+A19+1 -> 8
A21: =+A20+1 -> 9
A22: =+A21+1 -> 10
A23: =+A22+1 -> 11
A24: =+A23+1 -> 12
A25: =+A24+1 -> 13
A26: =+A25+1 -> 14
A27: =+A26+1 -> 15
A28: =+A27+1 -> 16
... A127: =+A126+1 -> 115

Sheet SONG LONG
A2: THEO DÕI HÀNG HÓA TẠM ỨNG, THANH TOÁN, ĐIỀU XE 2023 - SONG LONG
C3: MST: 3702373463 | D3: CÔNG TY TNHH SẢN XUấT THƯƠNG MẠI NHỰA SONG LONG VIệT NAM | L3: DC: Lô A - 14E-CN, Khu công nghiệp Bàu Bàng, Xã Bàu Bàng, Thành phố Hồ Chí Minh, Việt Nam
A4: STT | B4: NGÀY GIAO HÀNG | C4: Số TK | D4: Ngày ĐK | E4: Tạo Job | F4: XUẤT/NHẬP | G4: 20' | H4: 40' | I4: LCL / | J4: CONT NO. | K4: Phân luồng | L4: CHI TIẾT | M4: ETA | N4: TÊN HÀNG | O4: Vận đơn/ BOOKING | P4: SỐ XE | Q4: PHỤ PHÍ NÂNG | R4: PHÍ NÂNG | S4: PHÍ HẠ | T4: PHÍ CHỨNG TỪ (TM) | U4: PHÍ CHỨNG TỪ (ST CK) | V4: PHÍ CSHT | W4: PHÍ DEM/DET/CƯỢC | X4: TỔNG CHI HỘ (CASH) | Y4: TỔNG CHI HỘ (ST CK) | Z4: GHI CHÚ PHÁT SINH | AA4: PHÍ DỊCH VỤ GN | AB4: DT BẢNG KÊ (GỒM VAT) | AC4: GIAO BẢNG KÊ | AD4: GHI CHÚ
A5: 1 | C5: 105246037150 | D5: 44959 | E5: KGN-23011165 | F5: N | I5: LCL | L5: 44963 | O5: GXSAG23014749 | R5: 49920 | U5: 5471664 | X5: =+B5+R5+S5+T5+Q5+W5 -> 49920 | Y5: =+U5 -> 5471664 | Z5: 2 KIỆN/ 2080 KGS / 3.4 CBM | AA5: =2290000*1.1 -> 2519000 | AB5: =+AA5+Y5+X5 -> 8040584 | AE5: 2519000
A6: 2 | C6: 105267870960 | D6: 14/02/2023 | E6: KGN-23020782 | F6: N | G6: 5 | J6: DFSU3093090 SNBU2278474 SNBU2304830 SNBU2343374 SNCU2962407 | K6: ĐỎ | L6: 24/02/23 | O6: SNLDXMVL000136 | R6: 3932500 | S6: =1760000+1760000+880000 -> 4400000 | X6: =+B6+R6+S6+T6+Q6+W6 -> 8332500 | Y6: =+U6 -> 0 | AA6: =((G6*5160000)+(H6*5560000))*1.1 -> 28380000 | AB6: =+AA6+Y6+X6 -> 36712500 | AC6: =+R6+S6 -> 8332500 | AE6: 28380000
A7: 3 | C7: 105282102110 | D7: 21/02/2023 | E7: KGN-23021001 | F7: N | I7: LCL | L7: 24/02/23 | O7: GXSAG23024061 | R7: 36000 | T7: 3331625 | X7: =+B7+R7+S7+T7+Q7+W7 -> 3367625 | Y7: =+U7 -> 0 | Z7: 1 KIỆN/ 190 KGS / 0.37 CBM | AA7: =2090000*1.1 -> 2299000 | AB7: =+AA7+Y7+X7 -> 5666625 | AE7: 2299000
A8: 4 | C8: PHÍ XIN C/O: 31300568, 31300594 | D8: 20/02/2023 | E8: KGN-23030589 | F8: N | T8: 200000 | X8: =+B8+R8+S8+T8+Q8+W8 -> 200000 | Y8: =+U8 -> 0 | Z8: 2 C/O | AA8: =(800000*2)*1.1 -> 1760000 | AB8: =+AA8+Y8+X8 -> 1960000 | AD8: làm GCN mẫu X cho HĐ 0000005 | AE8: 1760000
A9: THÁNG 03/2023 | X9: =SUM(X5:X8) -> 11950045 | Y9: =SUM(Y5:Y8) -> 5471664 | AA9: =SUM(AA5:AA8) -> 34958000 | AB9: =+X9+Y9+AA9 -> 52379709
A10: 1 | C10: 105327699960 | D10: 14/03/2023 | E10: KGN-23021175 | F10: N | I10: LCL | K10: VÀNG | L10: 24/02/23 | O10: NOSNB23CL40073I | R10: =1399440+114241 -> 1513681 | U10: 5266581 | X10: =+B10+R10+S10+T10+Q10+W10 -> 1513681 | Y10: =+U10 -> 5266581 | Z10: 3 KIỆN/ 2380 KGS / 0.38 CBM | AA10: =2090000*1.1 -> 2299000 | AB10: =+AA10+Y10+X10 -> 9079262
A11: 2 | C11: 105317575640 | D11: 14/03/2023 | E11: KGN-23030404 | F11: N | I11: LCL | K11: VÀNG | L11: 18/03/23 | O11: COAU8035412290E | R11: =49920+74880 -> 124800 | U11: 3686443 | X11: =+B11+R11+S11+T11+Q11+W11 -> 124800 | Y11: =+U11 -> 3686443 | Z11: 2 KIỆN/ 2080 KGS / 3.73 CBM | AA11: =2290000*1.1 -> 2519000 | AB11: =+AA11+Y11+X11 -> 6330243
A12: 3 | C12: PHÍ XIN C/O T03.2023 | T12: 900000 | X12: =+B12+R12+S12+T12+Q12+W12 -> 900000 | Y12: =+U12 -> 0 | Z12: 9 C/O | AA12: =(800000*9)*1.1 -> 7920000 | AB12: =+AA12+Y12+X12 -> 8820000
A13: THÁNG 04/2023 | X13: =SUM(X10:X12) -> 2538481 | Y13: =SUM(Y10:Y12) -> 8953024 | AA13: =SUM(AA10:AA12) -> 12738000 | AB13: =+X13+Y13+AA13 -> 24229505
A14: 1 | C14: 105355638140 | D14: 27/03/2023 | E14: KGN-23040123 | F14: N | G14: 5 | I14: DRYU2794345 FCIU4977825 TLLU2608070 UETU2256740 UETU2274152 | K14: VÀNG | L14: 05/04/23 | O14: COAU8036156890 | R14: 3300000 | W14: 1193000 | X14: =+B14+R14+S14+T14+Q14+W14 -> 4493000 | Y14: =+U14 -> 0 | AA14: =((G14*5160000)+(H14*5560000))*1.1 -> 28380000 | AB14: =+AA14+Y14+X14 -> 32873000
A15: 2 | C15: 105386507810 | D15: 11/04/2023 | E15: KGN-23040501 | I15: LCL | K15: ĐỎ | L15: 13/04/23 | O15: NOSNB23CL40592E | R15: 105840 | U15: 3875529 | X15: =+B15+R15+S15+T15+Q15+W15 -> 105840 | Y15: =+U15 -> 3875529 | Z15: 3 KIỆN/ 1260 KGS / 1.51 CBM | AA15: =2090000*1.1 -> 2299000 | AB15: =+AA15+Y15+X15 -> 6280369
A16: 3 | C16: PHÍ XIN C/O T04.2023 | E16: KGN-23041124 | T16: =100000+100000 -> 200000 | X16: =+B16+R16+S16+T16+Q16+W16 -> 200000 | Y16: =+U16 -> 0 | Z16: 2 C/O, CHỨNG THỰC INV VCCI | AA16: =(800000*2)*1.1 -> 1760000 | AB16: =+AA16+Y16+X16 -> 1960000
A17: THÁNG 05/2023 | X17: =SUM(X14:X16) -> 4798840 | Y17: =SUM(Y14:Y16) -> 3875529 | AA17: =SUM(AA14:AA16) -> 32439000 | AB17: =+X17+Y17+AA17 -> 41113369
A18: 1 | C18: 105413665560 | D18: 24/04/2023. | E18: KGN-23041466 | F18: N | G18: 10 | J18: TGBU2104020 FCIU4815188 CSLU1884779 TGBU2317453 OOLU0594872 CSLU2391015 UETU2661721 CSNU1993376 TEMU5432086 CBHU4190554 | L18: 25/04/23 | O18: COAU8037166610 | R18: =5720000+440000 -> 6160000 | S18: =900000+900000+900000+900000+900000 -> 4500000 | W18: =295250+590500 -> 885750 | X18: =+B18+R18+S18+T18+Q18+W18 -> 11545750 | Y18: =+U18 -> 0 | AA18: =((G18*5160000)+(H18*5560000))*1.1 -> 56760000 | AB18: =+AA18+Y18+X18 -> 68305750 | AC18: =+S18 -> 4500000
A19: =+A18+1 -> 2 | C19: PHÍ XIN C/O T05.2023 | D19: 16/05/2023 | E19: KGN-23051250 | T19: 100000 | X19: =+B19+R19+S19+T19+Q19+W19 -> 100000 | Y19: =+U19 -> 0 | Z19: 1 C/O, CHỨNG THỰC INV VCCI | AA19: =(800000*1)*1.1 -> 880000 | AB19: =+AA19+Y19+X19 -> 980000
A20: THÁNG 06/2023 | X20: =SUM(X18:X19) -> 11645750 | Y20: =SUM(Y18:Y19) -> 0 | AA20: =SUM(AA18:AA19) -> 57640000 | AB20: =+X20+Y20+AA20 -> 69285750
A21: 1 | C21: 105413665560 | D21: 24/04/2023. | E21: KGN-23041466 | F21: N | G21: 10 | J21: TGBU2104020 FCIU4815188 CSLU1884779 TGBU2317453 OOLU0594872 CSLU2391015 UETU2661721 CSNU1993376 TEMU5432086 CBHU4190554 | L21: 25/04/23 | O21: COAU8037166610 | S21: =900000+900000+900000+900000+900000 -> 4500000 | X21: =+B21+R21+S21+T21+Q21+W21 -> 4500000 | Y21: =+U21 -> 0 | AA21: 0 | AB21: =+AA21+Y21+X21 -> 4500000 | AC21: BỔ SUNG CHI HỘ | AD21: KGN-PR-2306183
A22: 2 | C22: 105502742000 | D22: 06/06/2023 | E22: KGN-23060353 | F22: N | G22: 10 | J22: CSLU1797329 SLDU2001919 OOLU2928731 OOLU1390359 TEMU3458712 FBIU0384877 BSIU2885244 FTAU1573774 CBHU4434650 OOLU0542014 | K22: VÀNG | O22: COAU7884807200 | R22: =379500+6600000 -> 6979500 | S22: =900000+800000+800000+800000+800000+800000+800000+800000+800000+800000 -> 8100000 | T22: =446870+295125 -> 741995 | W22: 2361000 | X22: =+B22+R22+S22+T22+Q22+W22 -> 18182495 | Y22: =+U22+W22 -> 2361000 | AA22: =((G22*5160000)+(H22*5560000))*1.1 -> 56760000 | AB22: =+AA22+Y22+X22 -> 77303495
A23: 3 | C23: 105527782400 | D23: 19/06/2023 | E23: KGN-23061252 | F23: N | G23: LCL | I23: LCL | K23: VÀNG | O23: OOLU2140741820G | U23: 3798190 | X23: =+B23+R23+S23+T23+Q23+W23 -> 0 | Y23: =+U23 -> 3798190 | AA23: =2090000*1.1 -> 2299000 | AB23: =+AA23+Y23+X23 -> 6097190
A24: 4 | C24: PHÍ XIN C/O T06.2023 | D24: 45085 | E24: KGN-23061065 | T24: 200000 | X24: =+B24+R24+S24+T24+Q24+W24 -> 200000 | Y24: =+U24 -> 0 | AA24: =(800000*2)*1.1 -> 1760000 | AB24: =+AA24+Y24+X24 -> 1960000
A25: THÁNG 07/2023 | X25: =SUM(X21:X24) -> 22882495 | Y25: =SUM(Y21:Y24) -> 6159190 | AA25: =SUM(AA21:AA24) -> 60819000 | AB25: =+X25+Y25+AA25 -> 89860685
A26: 1 | B26: KGN-PR-2307589 | C26: 105527782400 | D26: 19/06/2023 | E26: KGN-23061252 | F26: N | G26: LCL | I26: LCL | O26: OOLU2140741820G | R26: 108000 | X26: =R26+S26+T26+Q26+W26 -> 108000 | Y26: =+U26 -> 0 | AA26: 0 | AB26: =+AA26+Y26+X26 -> 108000 | AC26: BỔ SUNG CHI HỘ
A27: 2 | C27: 105533383760 | D27: 21/06/2023 | E27: KGN-23061596 | F27: N | G27: LCL | I27: LCL | K27: VÀNG | L27: 1 PK/ 720 KGS/ 0.76 CBM | O27: GOSUNGB20086958R | R27: 24000 | T27: 3592215 | X27: =R27+S27+T27+Q27+W27 -> 3616215 | Y27: =+U27 -> 0 | AA27: =2090000*1.08 -> 2257200 | AB27: =+AA27+Y27+X27 -> 5873415 | AD27: KGN-PR-2307404
A28: =+A27+1 -> 3 | C28: 105546953740 | D28: 28/06/2023 | E28: KGN-23062232 | F28: N | G28: LCL | I28: LCL | K28: VÀNG | L28: 2 PK/ 3100 KGS / 0.9 CBM | O28: COAU7244446280L | R28: 186000 | X28: =R28+S28+T28+Q28+W28 -> 186000 | Y28: =+U28 -> 0 | AA28: =2090000*1.08 -> 2257200 | AB28: =+AA28+Y28+X28 -> 2443200
A29: =+A28+1 -> 4 | C29: 105569787960 | D29: 45206 | E29: KGN-23070944 | F29: N | G29: 10 | J29: DFSU2984027 FCIU5859241 TGBU3001198 OOLU1923566 TLLU3013970 CSLU2315530 TEMU2692990 TGHU1938041 CSLU1421481 OOLU0567882 | K29: VÀNG | O29: COAU7884860960 | Q29: 1674000 | R29: 3942000 | S29: =900000+900000+900000+900000+900000+900000+900000+900000+900000+900000 -> 9000000 | X29: =R29+S29+T29+Q29+W29 -> 14616000 | Y29: =+U29 -> 0 | AA29: =((G29*5160000)+(H29*5560000))*1.08 -> 55728000 | AB29: =+AA29+Y29+X29 -> 70344000
A30: =+A29+1 -> 5 | C30: 105578665030 | D30: 13/07/2023 | E30: KGN-23070696 | F30: N | G30: LCL | I30: LCL | K30: VÀNG | L30: 1 PK / 290 KGS / 2 CBM | O30: OOLU2721381400E | R30: 82472 | U30: 5104944 | X30: =R30+S30+T30+Q30+W30 -> 82472 | Y30: =+U30 -> 5104944 | AA30: =2090000*1.08 -> 2257200 | AB30: =+AA30+Y30+X30 -> 7444616
A31: =+A30+1 -> 6 | C31: PHÍ XIN C/O T07.2023 | D31: 18/07/2023 | E31: KGN-23071046 | O31: 31303205 | T31: 100000 | X31: =R31+S31+T31+Q31+W31 -> 100000 | Y31: =+U31 -> 0 | AA31: =(800000)*1.08 -> 864000 | AB31: =+AA31+Y31+X31 -> 964000
A32: THÁNG 08/2023 | X32: =SUM(X26:X31) -> 18708687 | Y32: =SUM(Y26:Y31) -> 5104944 | AA32: =SUM(AA26:AA31) -> 63363600 | AB32: =+X32+Y32+AA32 -> 87177231
A33: 1 | C33: 105608687810 | D33: 26/07/2023 | E33: KGN-23071425 | F33: N | G33: LCL | I33: LCL | K33: VÀNG | L33: 2 PK/ 2100 KGS / 3.4 CBM | O33: GXSAG23075802 | U33: 6586058 | X33: =R33+S33+T33+Q33+W33 -> 0 | Y33: =+U33 -> 6586058 | AA33: =3090000*1.08 -> 3337200 | AB33: =+AA33+Y33+X33 -> 9923258 | AD33: KGN-PR-2308390 KGN-PR-23080475 (263,158 VND)
A34: =+A33+1 -> 2 | C34: 105607363300 | D34: 27/07/2023 | E34: KGN-23071495 | F34: N | G34: 10 | J34: CULU1909910 CULU1926883 CULU1926918 CULU1930918 GESU1257929 TEMU0548710 TEMU0549742 TLLU2939587 TRHU3123230 UETU2276432 | K34: VÀNG | O34: CULVXMN2301884 | Q34: =1134000+108000 -> 1242000 | R34: 5886000 | S34: =1800000+1800000+1800000+1800000+900000+900000 -> 9000000 | W34: 263158 | X34: =R34+S34+T34+Q34+W34 -> 16391158 | Y34: =+U34 -> 0 | AA34: =((G34*5160000)+(H34*5560000))*1.08 -> 55728000 | AB34: =+AA34+Y34+X34 -> 72119158 | AC34: BỔ SUNG PHÍ SỬA HD
A35: =+A34+1 -> 3 | C35: 105629140740 | D35: 45145 | E35: KGN-23080117 | F35: N | G35: LCL | I35: LCL | K35: VÀNG | L35: 6PK/ 961 KGS / 0.51 CBM | O35: NBHCM23053886 | U35: 3839712 | X35: =R35+S35+T35+Q35+W35 -> 0 | Y35: =+U35 -> 3839712 | AA35: =2090000*1.08 -> 2257200 | AB35: =+AA35+Y35+X35 -> 6096912
A36: =+A35+1 -> 4 | C36: 105629106002 | D36: 45141 | E36: KGN-23080187 | F36: n | G36: LCL | I36: LCL | K36: VÀNG | L36: 1pk /1,400 KGS/0.8 CBM | O36: NOSNB23CL41485B | Q36: 478342 | T36: 3768638 | X36: =R36+S36+T36+Q36+W36 -> 4246980 | Y36: =+U36 -> 0 | AA36: =2290000*1.08 -> 2473200 | AB36: =+AA36+Y36+X36 -> 6720180
A37: =+A36+1 -> 5 | C37: 105639536220 | D37: 45147 | E37: KGN-23080277 | F37: N | G37: LCL | I37: LCL | K37: X | L37: 2 PK/1500 KGS/0.39 CBM | O37: GOSUNGB20087344H | U37: 4377718 | X37: =R37+S37+T37+Q37+W37 -> 0 | Y37: =+U37 -> 4377718 | AA37: =2290000*1.08 -> 2473200 | AB37: =+AA37+Y37+X37 -> 6850918
A38: =+A37+1 -> 6 | C38: 105640277850 | D38: 45147 | E38: KGN-23080278 | F38: N | G38: LCL | I38: LCL | K38: VÀNG | L38: 1PK /480 KGS/0.5 CBM | O38: GOSUNGB20087344C | Q38: 23563 | U38: 3575794 | X38: =R38+S38+T38+Q38+W38 -> 23563 | Y38: =+U38 -> 3575794 | AA38: =2090000*1.08 -> 2257200 | AB38: =+AA38+Y38+X38 -> 5856557
A39: =+A38+1 -> 7 | C39: 105658896010 | D39: 17/08/2023 | E39: KGN-23080927 | F39: N | G39: LCL | I39: LCL | K39: VÀNG | L39: 1PK/ 300 KGS/ 0.08 CBM | O39: NOSNB23CL41661I | U39: 3454942 | X39: =R39+S39+T39+Q39+W39 -> 0 | Y39: =+U39 -> 3454942 | AA39: =2090000*1.08 -> 2257200 | AB39: =+AA39+Y39+X39 -> 5712142 | AD39: KGN-PR-23080475
A40: =+A39+1 -> 8 | C40: 105668713510 | D40: 22/08/2023 | E40: KGN-23081342 | F40: N | G40: LCL | I40: LCL | K40: VÀNG | L40: 1PK/ 550 KGS/ 0.57 CBM | O40: COAU8042516610L | Q40: 11782 | T40: 3454942 | X40: =R40+S40+T40+Q40+W40 -> 3466724 | Y40: =+U40 -> 0 | AA40: =2090000*1.08 -> 2257200 | AB40: =+AA40+Y40+X40 -> 5723924
A41: THÁNG 09/2023 | X41: =SUM(X33:X40) -> 24128425 | Y41: =SUM(Y33:Y40) -> 21834224 | AA41: =SUM(AA33:AA40) -> 73040400 | AB41: =+X41+Y41+AA41 -> 119003049
...

Sheet SONG LONG- XTC
A2: THEO DÕI HÀNG XUẤT TẠI CHỖ - SONG LONG
C3: MST: 3702373463
A4: STT | B4: NGÀY GIAO HÀNG | C4: Số TK | D4: Ngày ĐK | E4: Tạo Job | F4: XUẤT/NHẬP | G4: 20' | H4: 40' | I4: KHÁCH HÀNG | J4: PNK | K4: INV NO | L4: SỐ KIỆN | M4: Phân luồng | N4: TÊN HÀNG | O4: Vận đơn/ BOOKING | P4: PHỤ PHÍ NÂNG | Q4: PHÍ NÂNG | R4: PHÍ HẠ | S4: PHÍ CHỨNG TỪ (TM) | T4: PHÍ CHỨNG TỪ (ST CK) | U4: PHÍ DEM/DET | V4: TỔNG CHI HỘ (CASH) | W4: TỔNG CHI HỘ (ST CK) | X4: GHI CHÚ PHÁT SINH | Y4: PHÍ DỊCH VỤ GN | Z4: DT BẢNG KÊ (GỒM VAT) | AA4: GIAO BẢNG KÊ | AB4: GHI CHÚ
A5: 1 | B5: 01/07/2024 | C5: 306543480960 | D5: 01/07/2024 | E5: KGN-24071343 | F5: Xuất | I5: CONG TY TNHH CUORI VIETNAM | J5: 00000056 | K5: SL-CU.009/2024 | L5: 436 | M5: Xanh | V5: =Q5+R5+S5+P5+U5 -> 0 | W5: =+T5 -> 0 | Y5: =600000*1.08 -> 648000 | Z5: =+Y5+W5+V5 -> 648000
A6: =+A5+1 -> 2 | B6: 01/07/2024 | C6: 306545165050 | D6: 01/07/2024 | E6: KGN-24071343 | F6: Xuất | I6: CONG TY TNHH VACPRO VIETNAM | J6: 00000057 | K6: SL-VA.019/2024 | L6: 418 | M6: Xanh | V6: =Q6+R6+S6+P6+U6 -> 0 | W6: =+T6 -> 0 | Y6: =600000*1.08 -> 648000 | Z6: =+Y6+W6+V6 -> 648000
A7: =+A6+1 -> 3 | B7: 04/07/2024 | C7: 306553811930 | D7: 06/07/2024 | E7: KGN-24071343 | F7: Xuất | I7: CÔNG TY TNHH LEADER ELECTRIC APPLIANCE | J7: 00000058 | K7: SL-LD.018/2024 | L7: 1306 | M7: Xanh | V7: =Q7+R7+S7+P7+U7 -> 0 | W7: =+T7 -> 0 | Y7: =600000*1.08 -> 648000 | Z7: =+Y7+W7+V7 -> 648000
A8: =+A7+1 -> 4 | B8: 11/07/2024 | C8: 306565840950 | D8: 11/07/2024 | E8: KGN-24071343 | F8: Xuất | I8: CONG TY TNHH VACPRO VIETNAM | J8: 00000059 | K8: SL-VA.020/2024 | L8: 482 | M8: Xanh | V8: =Q8+R8+S8+P8+U8 -> 0 | W8: =+T8 -> 0 | Y8: =600000*1.08 -> 648000 | Z8: =+Y8+W8+V8 -> 648000
A9: =+A8+1 -> 5 | B9: 12/07/2024 | C9: 306574008220 | D9: 12/07/2024 | E9: KGN-24071343 | F9: Xuất | I9: CONG TY TNHH CUORI VIETNAM | J9: 00000060 | K9: SL-CU.010/2024 | L9: 139 | M9: Xanh | V9: =Q9+R9+S9+P9+U9 -> 0 | W9: =+T9 -> 0 | Y9: =600000*1.08 -> 648000 | Z9: =+Y9+W9+V9 -> 648000
A10: =+A9+1 -> 6 | B10: 12/07/2024 | C10: 306568543060 | D10: 13/07/2024 | E10: KGN-24071343 | F10: Xuất | I10: CÔNG TY TNHH LEADER ELECTRIC APPLIANCE | J10: 00000061 | K10: SL-LD.019/2024 | L10: 1021 | M10: Xanh | V10: =Q10+R10+S10+P10+U10 -> 0 | W10: =+T10 -> 0 | Y10: =600000*1.08 -> 648000 | Z10: =+Y10+W10+V10 -> 648000
A11: =+A10+1 -> 7 | B11: 15/07/2024 | C11: 306580604430 | D11: 16/07/2024 | E11: KGN-24071343 | F11: Xuất | I11: CONG TY TNHH VACPRO VIETNAM | J11: 00000062 | K11: SL-VA.021/2024 | L11: 931 | M11: Xanh | V11: =Q11+R11+S11+P11+U11 -> 0 | W11: =+T11 -> 0 | Y11: =600000*1.08 -> 648000 | Z11: =+Y11+W11+V11 -> 648000
A12: =+A11+1 -> 8 | B12: 18/07/2024 | C12: 306592569530 | D12: 20/07/2024 | E12: KGN-24071343 | F12: Xuất | I12: CÔNG TY TNHH LEADER ELECTRIC APPLIANCE | J12: 00000063 | K12: SL-LD.020/2024 | L12: 737 | M12: Xanh | V12: =Q12+R12+S12+P12+U12 -> 0 | W12: =+T12 -> 0 | Y12: =600000*1.08 -> 648000 | Z12: =+Y12+W12+V12 -> 648000
A13: =+A12+1 -> 9 | B13: 20/07/2024 | C13: 306594925620 | D13: 22/07/2024 | E13: KGN-24071343 | F13: Xuất | I13: CONG TY TNHH VACPRO VIETNAM | J13: 00000064 | K13: SL-VA.022/2024 | L13: 273 | M13: Xanh | V13: =Q13+R13+S13+P13+U13 -> 0 | W13: =+T13 -> 0 | Y13: =600000*1.08 -> 648000 | Z13: =+Y13+W13+V13 -> 648000
A14: THÁNG 08/2024 | Z14: =SUM(Z5:Z13) -> 5832000
A15: 1 | B15: 25/07/2024 | C15: 306605516840 | D15: 25/07/2024 | E15: KGN-24081340 | F15: Xuất | I15: CONG TY TNHH VACPRO VIETNAM | J15: 00000065 | K15: SL-VA.023/2024 | L15: 116 | M15: Xanh | V15: =Q15+R15+S15+P15+U15 -> 0 | W15: =+T15 -> 0 | Y15: =600000*1.08 -> 648000 | Z15: =+Y15+W15+V15 -> 648000
A16: =+A15+1 -> 2 | B16: 31/07/2024 | C16: 306624655650 | D16: 45506 | E16: KGN-24081340 | F16: Xuất | I16: CONG TY TNHH VACPRO VIETNAM | J16: 00000068 | K16: SL-VA.024/2024 | L16: 246 | M16: Xanh | V16: =Q16+R16+S16+P16+U16 -> 0 | W16: =+T16 -> 0 | Y16: =600000*1.08 -> 648000 | Z16: =+Y16+W16+V16 -> 648000
A17: =+A16+1 -> 3 | B17: 31/07/2024 | C17: 306624514400 | D17: 45505 | E17: KGN-24081340 | F17: Xuất | I17: CONG TY TNHH CUORI VIETNAM | J17: 00000066 | K17: SL-CU.011/2024 | L17: 399 | M17: Xanh | V17: =Q17+R17+S17+P17+U17 -> 0 | W17: =+T17 -> 0 | Y17: =600000*1.08 -> 648000 | Z17: =+Y17+W17+V17 -> 648000
A18: =+A17+1 -> 4 | B18: 05/08/2024 | C18: 306634616320 | D18: 06/08/2024 | E18: KGN-24081340 | F18: Xuất | I18: CONG TY TNHH VACPRO VIETNAM | J18: 00000069 | K18: SL-VA.025/2024 | L18: 379 | M18: Xanh | V18: =Q18+R18+S18+P18+U18 -> 0 | W18: =+T18 -> 0 | Y18: =600000*1.08 -> 648000 | Z18: =+Y18+W18+V18 -> 648000
A19: =+A18+1 -> 5 | B19: 06/08/2024 | C19: 306639318550 | D19: 08/08/2024 | E19: KGN-24081340 | F19: Xuất | I19: CÔNG TY TNHH LEADER ELECTRIC APPLIANCE | J19: 00000070 | K19: SL-LD.021.2024 | L19: 1020 | M19: Xanh | V19: =Q19+R19+S19+P19+U19 -> 0 | W19: =+T19 -> 0 | Y19: =600000*1.08 -> 648000 | Z19: =+Y19+W19+V19 -> 648000
A20: =+A19+1 -> 6 | B20: 07/08/2024 | C20: 306642012300 | D20: 09/08/2024 | E20: KGN-24081340 | F20: Xuất | I20: CONG TY TNHH DECHANG VIETNAM | J20: 00000071 | K20: SL-DE.009 2024 | L20: 488 | M20: Xanh | V20: =Q20+R20+S20+P20+U20 -> 0 | W20: =+T20 -> 0 | Y20: =600000*1.08 -> 648000 | Z20: =+Y20+W20+V20 -> 648000
A21: =+A20+1 -> 7 | B21: 08/08/2024 | C21: 306648700060 | D21: 12/08/2024 | E21: KGN-24081340 | F21: Xuất | I21: CÔNG TY TNHH LEADER ELECTRIC APPLIANCE | J21: 00000072 | K21: SL-LD.022.2024 | L21: 1129 | M21: Xanh | V21: =Q21+R21+S21+P21+U21 -> 0 | W21: =+T21 -> 0 | Y21: =600000*1.08 -> 648000 | Z21: =+Y21+W21+V21 -> 648000
A22: =+A21+1 -> 8 | B22: 13/08/2024 | C22: 306656551960 | D22: 14/08/2024 | E22: KGN-24081340 | F22: Xuất | I22: CONG TY TNHH VACPRO VIETNAM | J22: 00000073 | K22: SL-VA.026.2024 | L22: 243 | M22: Xanh | V22: =Q22+R22+S22+P22+U22 -> 0 | W22: =+T22 -> 0 | Y22: =600000*1.08 -> 648000 | Z22: =+Y22+W22+V22 -> 648000
A23: =+A22+1 -> 9 | B23: 17/08/2024 | C23: 306667953010 | D23: 17/08/2024 | E23: KGN-24081340 | F23: Xuất | I23: CONG TY TNHH CUORI VIETNAM | J23: 00000074 | K23: SL-CU.012/2024 | L23: 171 | M23: Xanh | V23: =Q23+R23+S23+P23+U23 -> 0 | W23: =+T23 -> 0 | Y23: =600000*1.08 -> 648000 | Z23: =+Y23+W23+V23 -> 648000
A24: =+A23+1 -> 10 | B24: 19/08/2024 | C24: 306668669550 | D24: 19/08/2024 | E24: KGN-24081340 | F24: Xuất | I24: CONG TY TNHH VACPRO VIETNAM | J24: 00000075 | K24: SL-VA.027.2024 | L24: 665 | M24: Xanh | V24: =Q24+R24+S24+P24+U24 -> 0 | W24: =+T24 -> 0 | Y24: =600000*1.08 -> 648000 | Z24: =+Y24+W24+V24 -> 648000
A25: =+A24+1 -> 11 | B25: 20/08/2024 | C25: 306665950160 | D25: 20/08/2024 | E25: KGN-24081340 | F25: Xuất | I25: CÔNG TY TNHH LEADER ELECTRIC APPLIANCE | J25: 00000076 | K25: SL-LD.023.2024 | L25: 639 | M25: Xanh | V25: =Q25+R25+S25+P25+U25 -> 0 | W25: =+T25 -> 0 | Y25: =600000*1.08 -> 648000 | Z25: =+Y25+W25+V25 -> 648000
A26: =+A25+1 -> 12 | B26: 21/08/2024 | C26: 306675092860 | D26: 21/08/2024 | E26: KGN-24081340 | F26: Xuất | I26: CONG TY TNHH DECHANG VIETNAM | J26: 00000077 | K26: SL-DE.0102024 | L26: 122 | M26: Xanh | V26: =Q26+R26+S26+P26+U26 -> 0 | W26: =+T26 -> 0 | Y26: =600000*1.08 -> 648000 | Z26: =+Y26+W26+V26 -> 648000
A27: THÁNG 09/2024 | Z27: =SUM(Z18:Z26) -> 5832000
A28: 1 | B28: 22/08/2024 | C28: 306680992350 | D28: 23/08/2024 | E28: KGN-24091207 | F28: Xuất | I28: CONG TY TNHH LEADER ELECTRIC APPLIANCE | J28: 00000078 | K28: SL-LD.024.2024 | L28: 482 | M28: Xanh | V28: =Q28+R28+S28+P28+U28 -> 0 | W28: =+T28 -> 0 | Y28: =600000*1.08 -> 648000 | Z28: =+Y28+W28+V28 -> 648000
A29: 2 | B29: 23/08/2024 | C29: 306684638650 | D29: 29/08/2024 | E29: KGN-24091207 | F29: Xuất | I29: CONG TY TNHH VACPRO VIETNAM | J29: 00000079 | K29: SL-VA.028.2024 | L29: 172 | M29: Xanh | V29: =Q29+R29+S29+P29+U29 -> 0 | W29: =+T29 -> 0 | Y29: =600000*1.08 -> 648000 | Z29: =+Y29+W29+V29 -> 648000
A30: =+A29+1 -> 3 | B30: 30/08/2024 | C30: 306707268250 | D30: 31/08/2024 | E30: KGN-24091207 | F30: Xuất | I30: CONG TY TNHH CUORI VIETNAM | J30: 00000080 | K30: SL-CU.013/2024 | L30: 300 | M30: Xanh | V30: =Q30+R30+S30+P30+U30 -> 0 | W30: =+T30 -> 0 | Y30: =600000*1.08 -> 648000 | Z30: =+Y30+W30+V30 -> 648000
A31: =+A30+1 -> 4 | B31: 30/08/2024 | C31: 306707420410 | D31: 04/09/2024 | E31: KGN-24091207 | F31: Xuất | I31: CONG TY TNHH VACPRO VIETNAM | J31: 00000081 | K31: SL-VA.029.2024 | L31: 486 | M31: Xanh | V31: =Q31+R31+S31+P31+U31 -> 0 | W31: =+T31 -> 0 | Y31: =600000*1.08 -> 648000 | Z31: =+Y31+W31+V31 -> 648000
A32: =+A31+1 -> 5 | B32: 06/09/2024 | C32: 306719309540 | D32: 09/09/2024 | E32: KGN-24091207 | F32: Xuất | I32: CONG TY TNHH VACPRO VIETNAM | J32: 00000082 | K32: SL-VA.030.2024 | L32: 691 | M32: Xanh | V32: =Q32+R32+S32+P32+U32 -> 0 | W32: =+T32 -> 0 | Y32: =600000*1.08 -> 648000 | Z32: =+Y32+W32+V32 -> 648000
A33: =+A32+1 -> 6 | B33: 10/09/2024 | C33: 306726678000 | D33: 11/09/2024 | E33: KGN-24091207 | F33: Xuất | I33: CONG TY TNHH LEADER ELECTRIC APPLIANCE | J33: 00000083 | K33: SL-LD.025.2024 | L33: 1810 | M33: Xanh | V33: =Q33+R33+S33+P33+U33 -> 0 | W33: =+T33 -> 0 | Y33: =600000*1.08 -> 648000 | Z33: =+Y33+W33+V33 -> 648000
A34: =+A33+1 -> 7 | B34: 16/09/2024 | C34: 306733992630 | D34: 16/09/2024 | E34: KGN-24091207 | F34: Xuất | I34: CONG TY TNHH LEADER ELECTRIC APPLIANCE | J34: 00000084 | K34: SL-VA.031.2024 | L34: 486 | M34: Xanh | V34: =Q34+R34+S34+P34+U34 -> 0 | W34: =+T34 -> 0 | Y34: =600000*1.08 -> 648000 | Z34: =+Y34+W34+V34 -> 648000
A35: 8 | B35: 17/09/2024 | C35: 306746391730 | D35: 18/09/2024 | E35: KGN-24091207 | F35: Xuất | I35: CONG TY TNHH VACPRO VIETNAM | J35: 00000085 | K35: SL-VA.032.2024 | L35: 714 | M35: Xanh | V35: =Q35+R35+S35+P35+U35 -> 0 | W35: =+T35 -> 0 | Y35: =600000*1.08 -> 648000 | Z35: =+Y35+W35+V35 -> 648000
A36: 9 | B36: 16/09/2024 | C36: 306742014630 | D36: 20/09/2024 | E36: KGN-24091207 | F36: Xuất | I36: CONG TY TNHH LEADER ELECTRIC APPLIANCE | J36: 00000086 | K36: SL-LD.026.2024 | L36: 1784 | M36: Xanh | V36: =Q36+R36+S36+P36+U36 -> 0 | W36: =+T36 -> 0 | Y36: =600000*1.08 -> 648000 | Z36: =+Y36+W36+V36 -> 648000
A37: 10 | B37: 19/09/2024 | C37: 306752675040 | D37: 20/09/2024 | E37: KGN-24091207 | F37: Xuất | I37: CONG TY TNHH LEADER ELECTRIC APPLIANCE | J37: 00000088 | K37: SL-LD.027.2024 | L37: 1204 | M37: Xanh | V37: =Q37+R37+S37+P37+U37 -> 0 | W37: =+T37 -> 0 | Y37: =600000*1.08 -> 648000 | Z37: =+Y37+W37+V37 -> 648000
A38: =+A37+1 -> 11 | B38: 19/09/2024 | C38: 306752727100 | D38: 20/09/2024 | E38: KGN-24091207 | F38: Xuất | I38: CONG TY TNHH DECHANG VIETNAM | J38: 00000089 | K38: SL-DE.0112024 | L38: 99 | M38: Xanh | N38: HỦY TK 306752727100 | V38: =Q38+R38+S38+P38+U38 -> 0 | W38: =+T38 -> 0 | Y38: =600000*1.08 -> 648000 | Z38: =+Y38+W38+V38 -> 648000
A39: =+A38+1 -> 12 | B39: 23/09/2024 | C39: 306758762240 | D39: 23/09/2024 | E39: KGN-24091207 | F39: Xuất | I39: CONG TY TNHH DECHANG VIETNAM | J39: 00000089 | K39: SL-DE.0112024 | L39: 170 | M39: Xanh | V39: =Q39+R39+S39+P39+U39 -> 0 | W39: =+T39 -> 0 | Y39: =600000*1.08 -> 648000 | Z39: =+Y39+W39+V39 -> 648000
A40: THÁNG 10/2024 | Y40: =SUM(Y28:Y39) -> 7776000 | Z40: =SUM(Z28:Z38) -> 7128000
A41: 1 | B41: 30/09/2024 | C41: 306781693100 | D41: 02/10/2024 | E41: KGN-24101364 | F41: Xuất | I41: CONG TY TNHH CUORI VIETNAM | J41: 00000090 | K41: SL-CU.014/2024 | L41: 494 | M41: Xanh | V41: =Q41+R41+S41+P41+U41 -> 0 | W41: =+T41 -> 0 | Y41: =600000*1.08 -> 648000 | Z41: =+Y41+W41+V41 -> 648000
...

Sheet ĐẠI HÀO
A2: THEO DÕI HÀNG HÓA TẠM ỨNG, THANH TOÁN, ĐIỀU XE 2023 - ĐẠI HÀO
B3: MST: | K3: Chi phí làm hàng
